Workbook

Sheet 言語切替
A1: 言語切替 / 语言切换 / Chuyển ngôn ngữ
A3: 表示言語 | B3: Tiếng Việt
A6: 言語コード / 语言代码 / Mã ngôn ngữ (TRANSLATE用・変更禁止)
A7: 日本語 | B7: ja
A8: 中文 | B8: zh-Hans
A9: Tiếng Việt | B9: vi
A11: 自動翻訳はM365+ネット要。TRANSLATEが#NAME?なら手動でCopilotに貼付翻訳。 / 需M365+网络，若#NAME?请用Copilot手动翻译 / Cần M365 + mạng, nếu #NAME? thì dùng Copilot dịch tay.

Sheet 00_運用ルール
A1: =INDEX(_ゴミ箱_Backup!$B$2:$D$32,MATCH("TITLE",_ゴミ箱_Backup!$A$2:$A$32,0),MATCH(言語切替!$B$3,_ゴミ箱_Backup!$B$1:$D$1,0)) -> #N/A
A2: =INDEX(_ゴミ箱_Backup!$B$2:$D$32,MATCH("PURPOSE",_ゴミ箱_Backup!$A$2:$A$32,0),MATCH(言語切替!$B$3,_ゴミ箱_Backup!$B$1:$D$1,0)) -> #N/A
A4: =INDEX(_ゴミ箱_Backup!$B$2:$D$32,MATCH("PRINCIPLE_HEADER",_ゴミ箱_Backup!$A$2:$A$32,0),MATCH(言語切替!$B$3,_ゴミ箱_Backup!$B$1:$D$1,0)) -> #N/A | J4: =INDEX(_ゴミ箱_Backup!$B$2:$D$32,MATCH("COL_SHEET",_ゴミ箱_Backup!$A$2:$A$32,0),MATCH(言語切替!$B$3,_ゴミ箱_Backup!$B$1:$D$1,0)) -> #N/A | K4: =INDEX(_ゴミ箱_Backup!$B$2:$D$32,MATCH("COL_USAGE",_ゴミ箱_Backup!$A$2:$A$32,0),MATCH(言語切替!$B$3,_ゴミ箱_Backup!$B$1:$D$1,0)) -> #N/A
A5: =INDEX(_ゴミ箱_Backup!$B$2:$D$32,MATCH("P1",_ゴミ箱_Backup!$A$2:$A$32,0),MATCH(言語切替!$B$3,_ゴミ箱_Backup!$B$1:$D$1,0)) -> #N/A | J5: 01_全体サマリー | K5: =INDEX(_ゴミ箱_Backup!$B$2:$D$32,MATCH("U1",_ゴミ箱_Backup!$A$2:$A$32,0),MATCH(言語切替!$B$3,_ゴミ箱_Backup!$B$1:$D$1,0)) -> #N/A
A6: =INDEX(_ゴミ箱_Backup!$B$2:$D$32,MATCH("P2",_ゴミ箱_Backup!$A$2:$A$32,0),MATCH(言語切替!$B$3,_ゴミ箱_Backup!$B$1:$D$1,0)) -> #N/A | J6: 02_マスタ | K6: =INDEX(_ゴミ箱_Backup!$B$2:$D$32,MATCH("U2",_ゴミ箱_Backup!$A$2:$A$32,0),MATCH(言語切替!$B$3,_ゴミ箱_Backup!$B$1:$D$1,0)) -> #N/A
A7: =INDEX(_ゴミ箱_Backup!$B$2:$D$32,MATCH("P3",_ゴミ箱_Backup!$A$2:$A$32,0),MATCH(言語切替!$B$3,_ゴミ箱_Backup!$B$1:$D$1,0)) -> #N/A | J7: 03_WBS | K7: =INDEX(_ゴミ箱_Backup!$B$2:$D$32,MATCH("U3",_ゴミ箱_Backup!$A$2:$A$32,0),MATCH(言語切替!$B$3,_ゴミ箱_Backup!$B$1:$D$1,0)) -> #N/A
A8: =INDEX(_ゴミ箱_Backup!$B$2:$D$32,MATCH("P4",_ゴミ箱_Backup!$A$2:$A$32,0),MATCH(言語切替!$B$3,_ゴミ箱_Backup!$B$1:$D$1,0)) -> #N/A | J8: 04_課題ToDo | K8: =INDEX(_ゴミ箱_Backup!$B$2:$D$32,MATCH("U4",_ゴミ箱_Backup!$A$2:$A$32,0),MATCH(言語切替!$B$3,_ゴミ箱_Backup!$B$1:$D$1,0)) -> #N/A
J9: 05_決定事項 | K9: =INDEX(_ゴミ箱_Backup!$B$2:$D$32,MATCH("U5",_ゴミ箱_Backup!$A$2:$A$32,0),MATCH(言語切替!$B$3,_ゴミ箱_Backup!$B$1:$D$1,0)) -> #N/A
A10: =INDEX(_ゴミ箱_Backup!$B$2:$D$32,MATCH("RESP_HEADER",_ゴミ箱_Backup!$A$2:$A$32,0),MATCH(言語切替!$B$3,_ゴミ箱_Backup!$B$1:$D$1,0)) -> #N/A | J10: 06_KPI | K10: =INDEX(_ゴミ箱_Backup!$B$2:$D$32,MATCH("U6",_ゴミ箱_Backup!$A$2:$A$32,0),MATCH(言語切替!$B$3,_ゴミ箱_Backup!$B$1:$D$1,0)) -> #N/A
A11: =INDEX(_ゴミ箱_Backup!$B$2:$D$32,MATCH("R1",_ゴミ箱_Backup!$A$2:$A$32,0),MATCH(言語切替!$B$3,_ゴミ箱_Backup!$B$1:$D$1,0)) -> #N/A | J11: 07_更新履歴 | K11: =INDEX(_ゴミ箱_Backup!$B$2:$D$32,MATCH("U7",_ゴミ箱_Backup!$A$2:$A$32,0),MATCH(言語切替!$B$3,_ゴミ箱_Backup!$B$1:$D$1,0)) -> #N/A
A12: =INDEX(_ゴミ箱_Backup!$B$2:$D$32,MATCH("R2",_ゴミ箱_Backup!$A$2:$A$32,0),MATCH(言語切替!$B$3,_ゴミ箱_Backup!$B$1:$D$1,0)) -> #N/A
A13: =INDEX(_ゴミ箱_Backup!$B$2:$D$32,MATCH("R3",_ゴミ箱_Backup!$A$2:$A$32,0),MATCH(言語切替!$B$3,_ゴミ箱_Backup!$B$1:$D$1,0)) -> #N/A
A14: =INDEX(_ゴミ箱_Backup!$B$2:$D$32,MATCH("R4",_ゴミ箱_Backup!$A$2:$A$32,0),MATCH(言語切替!$B$3,_ゴミ箱_Backup!$B$1:$D$1,0)) -> #N/A
A16: =INDEX(_ゴミ箱_Backup!$B$2:$D$32,MATCH("CYCLE_HEADER",_ゴミ箱_Backup!$A$2:$A$32,0),MATCH(言語切替!$B$3,_ゴミ箱_Backup!$B$1:$D$1,0)) -> #N/A
A17: =INDEX(_ゴミ箱_Backup!$B$2:$D$32,MATCH("C1",_ゴミ箱_Backup!$A$2:$A$32,0),MATCH(言語切替!$B$3,_ゴミ箱_Backup!$B$1:$D$1,0)) -> #N/A
A18: =INDEX(_ゴミ箱_Backup!$B$2:$D$32,MATCH("C2",_ゴミ箱_Backup!$A$2:$A$32,0),MATCH(言語切替!$B$3,_ゴミ箱_Backup!$B$1:$D$1,0)) -> #N/A
A19: =INDEX(_ゴミ箱_Backup!$B$2:$D$32,MATCH("C3",_ゴミ箱_Backup!$A$2:$A$32,0),MATCH(言語切替!$B$3,_ゴミ箱_Backup!$B$1:$D$1,0)) -> #N/A
A20: =INDEX(_ゴミ箱_Backup!$B$2:$D$32,MATCH("C4",_ゴミ箱_Backup!$A$2:$A$32,0),MATCH(言語切替!$B$3,_ゴミ箱_Backup!$B$1:$D$1,0)) -> #N/A
A22: =INDEX(_ゴミ箱_Backup!$B$2:$D$32,MATCH("ESC_HEADER",_ゴミ箱_Backup!$A$2:$A$32,0),MATCH(言語切替!$B$3,_ゴミ箱_Backup!$B$1:$D$1,0)) -> #N/A
A23: =INDEX(_ゴミ箱_Backup!$B$2:$D$32,MATCH("E1",_ゴミ箱_Backup!$A$2:$A$32,0),MATCH(言語切替!$B$3,_ゴミ箱_Backup!$B$1:$D$1,0)) -> #N/A
A24: =INDEX(_ゴミ箱_Backup!$B$2:$D$32,MATCH("E2",_ゴミ箱_Backup!$A$2:$A$32,0),MATCH(言語切替!$B$3,_ゴミ箱_Backup!$B$1:$D$1,0)) -> #N/A
A25: =INDEX(_ゴミ箱_Backup!$B$2:$D$32,MATCH("E3",_ゴミ箱_Backup!$A$2:$A$32,0),MATCH(言語切替!$B$3,_ゴミ箱_Backup!$B$1:$D$1,0)) -> #N/A
A26: =INDEX(_ゴミ箱_Backup!$B$2:$D$32,MATCH("E4",_ゴミ箱_Backup!$A$2:$A$32,0),MATCH(言語切替!$B$3,_ゴミ箱_Backup!$B$1:$D$1,0)) -> #N/A
A27: =INDEX(_ゴミ箱_Backup!$B$2:$D$300,MATCH("PARA_TITLE",_ゴミ箱_Backup!$A$2:$A$300,0),MATCH(言語切替!$B$3,_ゴミ箱_Backup!$B$1:$D$1,0)) -> #N/A
A28: =INDEX(_ゴミ箱_Backup!$B$2:$D$300,MATCH("PARA_DESC",_ゴミ箱_Backup!$A$2:$A$300,0),MATCH(言語切替!$B$3,_ゴミ箱_Backup!$B$1:$D$1,0)) -> #N/A
A29: =INDEX(_ゴミ箱_Backup!$B$2:$D$300,MATCH("PARA_HOWTO",_ゴミ箱_Backup!$A$2:$A$300,0),MATCH(言語切替!$B$3,_ゴミ箱_Backup!$B$1:$D$1,0)) -> #N/A
A30: =INDEX(_ゴミ箱_Backup!$B$2:$D$300,MATCH("BACKUP_TITLE",_ゴミ箱_Backup!$A$2:$A$300,0),MATCH(言語切替!$B$3,_ゴミ箱_Backup!$B$1:$D$1,0)) -> #N/A
A31: =INDEX(_ゴミ箱_Backup!$B$2:$D$300,MATCH("BACKUP_DESC",_ゴミ箱_Backup!$A$2:$A$300,0),MATCH(言語切替!$B$3,_ゴミ箱_Backup!$B$1:$D$1,0)) -> #N/A

Sheet 01_全体サマリー
A1: =INDEX(_ゴミ箱_Backup!$B$33:$D$45,MATCH("DASH_TITLE",_ゴミ箱_Backup!$A$33:$A$45,0),MATCH(言語切替!$B$3,_ゴミ箱_Backup!$B$1:$D$1,0)) -> #N/A
A2: =INDEX(_ゴミ箱_Backup!$B$33:$D$45,MATCH("DASH_DESC",_ゴミ箱_Backup!$A$33:$A$45,0),MATCH(言語切替!$B$3,_ゴミ箱_Backup!$B$1:$D$1,0)) -> #N/A
B4: =INDEX(_ゴミ箱_Backup!$B$33:$D$45,MATCH("DASH_OPEN_WBS",_ゴミ箱_Backup!$A$33:$A$45,0),MATCH(言語切替!$B$3,_ゴミ箱_Backup!$B$1:$D$1,0)) -> #N/A | D4: =INDEX(_ゴミ箱_Backup!$B$33:$D$45,MATCH("DASH_DELAY_WBS",_ゴミ箱_Backup!$A$33:$A$45,0),MATCH(言語切替!$B$3,_ゴミ箱_Backup!$B$1:$D$1,0)) -> #N/A | F4: =INDEX(_ゴミ箱_Backup!$B$33:$D$45,MATCH("DASH_OPEN_ISSUES",_ゴミ箱_Backup!$A$33:$A$45,0),MATCH(言語切替!$B$3,_ゴミ箱_Backup!$B$1:$D$1,0)) -> #N/A | H4: =INDEX(_ゴミ箱_Backup!$B$33:$D$45,MATCH("DASH_HIGH_OVERDUE",_ゴミ箱_Backup!$A$33:$A$45,0),MATCH(言語切替!$B$3,_ゴミ箱_Backup!$B$1:$D$1,0)) -> #N/A | J4: =INDEX(_ゴミ箱_Backup!$B$33:$D$45,MATCH("DASH_KPI_MISS",_ゴミ箱_Backup!$A$33:$A$45,0),MATCH(言語切替!$B$3,_ゴミ箱_Backup!$B$1:$D$1,0)) -> #N/A
B5: =COUNTIFS('03_WBS'!$A$5:$A$204,"<>",'03_WBS'!$L$5:$L$204,"<>"&INDEX(_ゴミ箱_Backup!$B$75:$D$75,1,MATCH(言語切替!$B$3,_ゴミ箱_Backup!$B$1:$D$1,0))) -> 3 | D5: =COUNTIF('03_WBS'!$N$5:$N$204,INDEX(_ゴミ箱_Backup!$B$92:$D$92,1,MATCH(言語切替!$B$3,_ゴミ箱_Backup!$B$1:$D$1,0))) -> 3 | F5: =COUNTIFS('04_課題ToDo'!$A$5:$A$304,"<>",'04_課題ToDo'!$M$5:$M$304,"<>"&INDEX(_ゴミ箱_Backup!$B$75:$D$75,1,MATCH(言語切替!$B$3,_ゴミ箱_Backup!$B$1:$D$1,0)),'04_課題ToDo'!$M$5:$M$304,"<>"&INDEX(_ゴミ箱_Backup!$B$77:$D$77,1,MATCH(言語切替!$B$3,_ゴミ箱_Backup!$B$1:$D$1,0))) -> 4 | H5: =COUNTIFS('04_課題ToDo'!$A$5:$A$304,"<>",'04_課題ToDo'!$S$5:$S$304,"High")+COUNTIFS('04_課題ToDo'!$A$5:$A$304,"<>",'04_課題ToDo'!$S$5:$S$304,INDEX(_ゴミ箱_Backup!$B$117:$D$247,MATCH("ALERT_OVERDUE",_ゴミ箱_Backup!$A$117:$A$247,0),MATCH(言語切替!$B$3,_ゴミ箱_Backup!$B$1:$D$1,0))) -> 4 | J5: =COUNTIFS('06_KPI'!$A$5:$A$204,"<>",'06_KPI'!$O$5:$O$204,INDEX(_ゴミ箱_Backup!$B$94:$D$94,1,MATCH(言語切替!$B$3,_ゴミ箱_Backup!$B$1:$D$1,0))) -> 4
A9: =INDEX(_ゴミ箱_Backup!$B$33:$D$45,MATCH("DASH_WG",_ゴミ箱_Backup!$A$33:$A$45,0),MATCH(言語切替!$B$3,_ゴミ箱_Backup!$B$1:$D$1,0)) -> #N/A | B9: =INDEX(_ゴミ箱_Backup!$B$33:$D$45,MATCH("DASH_OPEN_WBS",_ゴミ箱_Backup!$A$33:$A$45,0),MATCH(言語切替!$B$3,_ゴミ箱_Backup!$B$1:$D$1,0)) -> #N/A | C9: =INDEX(_ゴミ箱_Backup!$B$33:$D$45,MATCH("DASH_DELAY_WBS",_ゴミ箱_Backup!$A$33:$A$45,0),MATCH(言語切替!$B$3,_ゴミ箱_Backup!$B$1:$D$1,0)) -> #N/A | D9: =INDEX(_ゴミ箱_Backup!$B$33:$D$45,MATCH("DASH_OPEN_ISSUES_SHORT",_ゴミ箱_Backup!$A$33:$A$45,0),MATCH(言語切替!$B$3,_ゴミ箱_Backup!$B$1:$D$1,0)) -> #N/A | E9: =INDEX(_ゴミ箱_Backup!$B$33:$D$45,MATCH("DASH_HIGH_OVERDUE_SHORT",_ゴミ箱_Backup!$A$33:$A$45,0),MATCH(言語切替!$B$3,_ゴミ箱_Backup!$B$1:$D$1,0)) -> #N/A | F9: =INDEX(_ゴミ箱_Backup!$B$33:$D$45,MATCH("DASH_WAITING",_ゴミ箱_Backup!$A$33:$A$45,0),MATCH(言語切替!$B$3,_ゴミ箱_Backup!$B$1:$D$1,0)) -> #N/A | G9: =INDEX(_ゴミ箱_Backup!$B$33:$D$45,MATCH("DASH_KPI_MISS",_ゴミ箱_Backup!$A$33:$A$45,0),MATCH(言語切替!$B$3,_ゴミ箱_Backup!$B$1:$D$1,0)) -> #N/A
A10: ='02_マスタ'!$A$5 -> #N/A | B10: =COUNTIFS('03_WBS'!$B$5:$B$204,$A10,'03_WBS'!$L$5:$L$204,"<>"&INDEX(_ゴミ箱_Backup!$B$75:$D$75,1,MATCH(言語切替!$B$3,_ゴミ箱_Backup!$B$1:$D$1,0))) -> 1 | C10: =COUNTIFS('03_WBS'!$B$5:$B$204,$A10,'03_WBS'!$N$5:$N$204,INDEX(_ゴミ箱_Backup!$B$92:$D$92,1,MATCH(言語切替!$B$3,_ゴミ箱_Backup!$B$1:$D$1,0))) -> 1 | D10: =COUNTIFS('04_課題ToDo'!$C$5:$C$304,$A10,'04_課題ToDo'!$M$5:$M$304,"<>"&INDEX(_ゴミ箱_Backup!$B$75:$D$75,1,MATCH(言語切替!$B$3,_ゴミ箱_Backup!$B$1:$D$1,0)),'04_課題ToDo'!$M$5:$M$304,"<>"&INDEX(_ゴミ箱_Backup!$B$77:$D$77,1,MATCH(言語切替!$B$3,_ゴミ箱_Backup!$B$1:$D$1,0))) -> 4 | E10: =COUNTIFS('04_課題ToDo'!$C$5:$C$304,$A10,'04_課題ToDo'!$S$5:$S$304,"High")+COUNTIFS('04_課題ToDo'!$C$5:$C$304,$A10,'04_課題ToDo'!$S$5:$S$304,INDEX(_ゴミ箱_Backup!$B$117:$D$247,MATCH("ALERT_OVERDUE",_ゴミ箱_Backup!$A$117:$A$247,0),MATCH(言語切替!$B$3,_ゴミ箱_Backup!$B$1:$D$1,0))) -> 4 | F10: =COUNTIFS('04_課題ToDo'!$C$5:$C$304,$A10,'04_課題ToDo'!$M$5:$M$304,INDEX(_ゴミ箱_Backup!$B$72:$D$72,1,MATCH(言語切替!$B$3,_ゴミ箱_Backup!$B$1:$D$1,0)))+COUNTIFS('04_課題ToDo'!$C$5:$C$304,$A10,'04_課題ToDo'!$M$5:$M$304,INDEX(_ゴミ箱_Backup!$B$73:$D$73,1,MATCH(言語切替!$B$3,_ゴミ箱_Backup!$B$1:$D$1,0))) -> 8 | G10: =COUNTIFS('06_KPI'!$B$5:$B$204,$A10,'06_KPI'!$O$5:$O$204,INDEX(_ゴミ箱_Backup!$B$94:$D$94,1,MATCH(言語切替!$B$3,_ゴミ箱_Backup!$B$1:$D$1,0))) -> 4
A11: WG-1 | B11: =COUNTIFS('03_WBS'!$B$5:$B$204,$A11,'03_WBS'!$L$5:$L$204,"<>"&INDEX(_ゴミ箱_Backup!$B$75:$D$75,1,MATCH(言語切替!$B$3,_ゴミ箱_Backup!$B$1:$D$1,0))) -> 1 | C11: =COUNTIFS('03_WBS'!$B$5:$B$204,$A11,'03_WBS'!$N$5:$N$204,INDEX(_ゴミ箱_Backup!$B$92:$D$92,1,MATCH(言語切替!$B$3,_ゴミ箱_Backup!$B$1:$D$1,0))) -> 1 | D11: =COUNTIFS('04_課題ToDo'!$C$5:$C$304,$A11,'04_課題ToDo'!$M$5:$M$304,"<>"&INDEX(_ゴミ箱_Backup!$B$75:$D$75,1,MATCH(言語切替!$B$3,_ゴミ箱_Backup!$B$1:$D$1,0)),'04_課題ToDo'!$M$5:$M$304,"<>"&INDEX(_ゴミ箱_Backup!$B$77:$D$77,1,MATCH(言語切替!$B$3,_ゴミ箱_Backup!$B$1:$D$1,0))) -> 0 | E11: =COUNTIFS('04_課題ToDo'!$C$5:$C$304,$A11,'04_課題ToDo'!$S$5:$S$304,"High")+COUNTIFS('04_課題ToDo'!$C$5:$C$304,$A11,'04_課題ToDo'!$S$5:$S$304,INDEX(_ゴミ箱_Backup!$B$117:$D$247,MATCH("ALERT_OVERDUE",_ゴミ箱_Backup!$A$117:$A$247,0),MATCH(言語切替!$B$3,_ゴミ箱_Backup!$B$1:$D$1,0))) -> 0 | F11: =COUNTIFS('04_課題ToDo'!$C$5:$C$304,$A11,'04_課題ToDo'!$M$5:$M$304,INDEX(_ゴミ箱_Backup!$B$72:$D$72,1,MATCH(言語切替!$B$3,_ゴミ箱_Backup!$B$1:$D$1,0)))+COUNTIFS('04_課題ToDo'!$C$5:$C$304,$A11,'04_課題ToDo'!$M$5:$M$304,INDEX(_ゴミ箱_Backup!$B$73:$D$73,1,MATCH(言語切替!$B$3,_ゴミ箱_Backup!$B$1:$D$1,0))) -> 0 | G11: =COUNTIFS('06_KPI'!$B$5:$B$204,$A11,'06_KPI'!$O$5:$O$204,INDEX(_ゴミ箱_Backup!$B$94:$D$94,1,MATCH(言語切替!$B$3,_ゴミ箱_Backup!$B$1:$D$1,0))) -> 0
A12: WG-2 | B12: =COUNTIFS('03_WBS'!$B$5:$B$204,$A12,'03_WBS'!$L$5:$L$204,"<>"&INDEX(_ゴミ箱_Backup!$B$75:$D$75,1,MATCH(言語切替!$B$3,_ゴミ箱_Backup!$B$1:$D$1,0))) -> 0 | C12: =COUNTIFS('03_WBS'!$B$5:$B$204,$A12,'03_WBS'!$N$5:$N$204,INDEX(_ゴミ箱_Backup!$B$92:$D$92,1,MATCH(言語切替!$B$3,_ゴミ箱_Backup!$B$1:$D$1,0))) -> 0 | D12: =COUNTIFS('04_課題ToDo'!$C$5:$C$304,$A12,'04_課題ToDo'!$M$5:$M$304,"<>"&INDEX(_ゴミ箱_Backup!$B$75:$D$75,1,MATCH(言語切替!$B$3,_ゴミ箱_Backup!$B$1:$D$1,0)),'04_課題ToDo'!$M$5:$M$304,"<>"&INDEX(_ゴミ箱_Backup!$B$77:$D$77,1,MATCH(言語切替!$B$3,_ゴミ箱_Backup!$B$1:$D$1,0))) -> 0 | E12: =COUNTIFS('04_課題ToDo'!$C$5:$C$304,$A12,'04_課題ToDo'!$S$5:$S$304,"High")+COUNTIFS('04_課題ToDo'!$C$5:$C$304,$A12,'04_課題ToDo'!$S$5:$S$304,INDEX(_ゴミ箱_Backup!$B$117:$D$247,MATCH("ALERT_OVERDUE",_ゴミ箱_Backup!$A$117:$A$247,0),MATCH(言語切替!$B$3,_ゴミ箱_Backup!$B$1:$D$1,0))) -> 0 | F12: =COUNTIFS('04_課題ToDo'!$C$5:$C$304,$A12,'04_課題ToDo'!$M$5:$M$304,INDEX(_ゴミ箱_Backup!$B$72:$D$72,1,MATCH(言語切替!$B$3,_ゴミ箱_Backup!$B$1:$D$1,0)))+COUNTIFS('04_課題ToDo'!$C$5:$C$304,$A12,'04_課題ToDo'!$M$5:$M$304,INDEX(_ゴミ箱_Backup!$B$73:$D$73,1,MATCH(言語切替!$B$3,_ゴミ箱_Backup!$B$1:$D$1,0))) -> 0 | G12: =COUNTIFS('06_KPI'!$B$5:$B$204,$A12,'06_KPI'!$O$5:$O$204,INDEX(_ゴミ箱_Backup!$B$94:$D$94,1,MATCH(言語切替!$B$3,_ゴミ箱_Backup!$B$1:$D$1,0))) -> 0
A13: WG-3 | B13: =COUNTIFS('03_WBS'!$B$5:$B$204,$A13,'03_WBS'!$L$5:$L$204,"<>"&INDEX(_ゴミ箱_Backup!$B$75:$D$75,1,MATCH(言語切替!$B$3,_ゴミ箱_Backup!$B$1:$D$1,0))) -> 0 | C13: =COUNTIFS('03_WBS'!$B$5:$B$204,$A13,'03_WBS'!$N$5:$N$204,INDEX(_ゴミ箱_Backup!$B$92:$D$92,1,MATCH(言語切替!$B$3,_ゴミ箱_Backup!$B$1:$D$1,0))) -> 0 | D13: =COUNTIFS('04_課題ToDo'!$C$5:$C$304,$A13,'04_課題ToDo'!$M$5:$M$304,"<>"&INDEX(_ゴミ箱_Backup!$B$75:$D$75,1,MATCH(言語切替!$B$3,_ゴミ箱_Backup!$B$1:$D$1,0)),'04_課題ToDo'!$M$5:$M$304,"<>"&INDEX(_ゴミ箱_Backup!$B$77:$D$77,1,MATCH(言語切替!$B$3,_ゴミ箱_Backup!$B$1:$D$1,0))) -> 0 | E13: =COUNTIFS('04_課題ToDo'!$C$5:$C$304,$A13,'04_課題ToDo'!$S$5:$S$304,"High")+COUNTIFS('04_課題ToDo'!$C$5:$C$304,$A13,'04_課題ToDo'!$S$5:$S$304,INDEX(_ゴミ箱_Backup!$B$117:$D$247,MATCH("ALERT_OVERDUE",_ゴミ箱_Backup!$A$117:$A$247,0),MATCH(言語切替!$B$3,_ゴミ箱_Backup!$B$1:$D$1,0))) -> 0 | F13: =COUNTIFS('04_課題ToDo'!$C$5:$C$304,$A13,'04_課題ToDo'!$M$5:$M$304,INDEX(_ゴミ箱_Backup!$B$72:$D$72,1,MATCH(言語切替!$B$3,_ゴミ箱_Backup!$B$1:$D$1,0)))+COUNTIFS('04_課題ToDo'!$C$5:$C$304,$A13,'04_課題ToDo'!$M$5:$M$304,INDEX(_ゴミ箱_Backup!$B$73:$D$73,1,MATCH(言語切替!$B$3,_ゴミ箱_Backup!$B$1:$D$1,0))) -> 0 | G13: =COUNTIFS('06_KPI'!$B$5:$B$204,$A13,'06_KPI'!$O$5:$O$204,INDEX(_ゴミ箱_Backup!$B$94:$D$94,1,MATCH(言語切替!$B$3,_ゴミ箱_Backup!$B$1:$D$1,0))) -> 0
A14: WG-4 | B14: =COUNTIFS('03_WBS'!$B$5:$B$204,$A14,'03_WBS'!$L$5:$L$204,"<>"&INDEX(_ゴミ箱_Backup!$B$75:$D$75,1,MATCH(言語切替!$B$3,_ゴミ箱_Backup!$B$1:$D$1,0))) -> 0 | C14: =COUNTIFS('03_WBS'!$B$5:$B$204,$A14,'03_WBS'!$N$5:$N$204,INDEX(_ゴミ箱_Backup!$B$92:$D$92,1,MATCH(言語切替!$B$3,_ゴミ箱_Backup!$B$1:$D$1,0))) -> 0 | D14: =COUNTIFS('04_課題ToDo'!$C$5:$C$304,$A14,'04_課題ToDo'!$M$5:$M$304,"<>"&INDEX(_ゴミ箱_Backup!$B$75:$D$75,1,MATCH(言語切替!$B$3,_ゴミ箱_Backup!$B$1:$D$1,0)),'04_課題ToDo'!$M$5:$M$304,"<>"&INDEX(_ゴミ箱_Backup!$B$77:$D$77,1,MATCH(言語切替!$B$3,_ゴミ箱_Backup!$B$1:$D$1,0))) -> 0 | E14: =COUNTIFS('04_課題ToDo'!$C$5:$C$304,$A14,'04_課題ToDo'!$S$5:$S$304,"High")+COUNTIFS('04_課題ToDo'!$C$5:$C$304,$A14,'04_課題ToDo'!$S$5:$S$304,INDEX(_ゴミ箱_Backup!$B$117:$D$247,MATCH("ALERT_OVERDUE",_ゴミ箱_Backup!$A$117:$A$247,0),MATCH(言語切替!$B$3,_ゴミ箱_Backup!$B$1:$D$1,0))) -> 0 | F14: =COUNTIFS('04_課題ToDo'!$C$5:$C$304,$A14,'04_課題ToDo'!$M$5:$M$304,INDEX(_ゴミ箱_Backup!$B$72:$D$72,1,MATCH(言語切替!$B$3,_ゴミ箱_Backup!$B$1:$D$1,0)))+COUNTIFS('04_課題ToDo'!$C$5:$C$304,$A14,'04_課題ToDo'!$M$5:$M$304,INDEX(_ゴミ箱_Backup!$B$73:$D$73,1,MATCH(言語切替!$B$3,_ゴミ箱_Backup!$B$1:$D$1,0))) -> 0 | G14: =COUNTIFS('06_KPI'!$B$5:$B$204,$A14,'06_KPI'!$O$5:$O$204,INDEX(_ゴミ箱_Backup!$B$94:$D$94,1,MATCH(言語切替!$B$3,_ゴミ箱_Backup!$B$1:$D$1,0))) -> 0
A15: WG-5 | B15: =COUNTIFS('03_WBS'!$B$5:$B$204,$A15,'03_WBS'!$L$5:$L$204,"<>"&INDEX(_ゴミ箱_Backup!$B$75:$D$75,1,MATCH(言語切替!$B$3,_ゴミ箱_Backup!$B$1:$D$1,0))) -> 0 | C15: =COUNTIFS('03_WBS'!$B$5:$B$204,$A15,'03_WBS'!$N$5:$N$204,INDEX(_ゴミ箱_Backup!$B$92:$D$92,1,MATCH(言語切替!$B$3,_ゴミ箱_Backup!$B$1:$D$1,0))) -> 0 | D15: =COUNTIFS('04_課題ToDo'!$C$5:$C$304,$A15,'04_課題ToDo'!$M$5:$M$304,"<>"&INDEX(_ゴミ箱_Backup!$B$75:$D$75,1,MATCH(言語切替!$B$3,_ゴミ箱_Backup!$B$1:$D$1,0)),'04_課題ToDo'!$M$5:$M$304,"<>"&INDEX(_ゴミ箱_Backup!$B$77:$D$77,1,MATCH(言語切替!$B$3,_ゴミ箱_Backup!$B$1:$D$1,0))) -> 0 | E15: =COUNTIFS('04_課題ToDo'!$C$5:$C$304,$A15,'04_課題ToDo'!$S$5:$S$304,"High")+COUNTIFS('04_課題ToDo'!$C$5:$C$304,$A15,'04_課題ToDo'!$S$5:$S$304,INDEX(_ゴミ箱_Backup!$B$117:$D$247,MATCH("ALERT_OVERDUE",_ゴミ箱_Backup!$A$117:$A$247,0),MATCH(言語切替!$B$3,_ゴミ箱_Backup!$B$1:$D$1,0))) -> 0 | F15: =COUNTIFS('04_課題ToDo'!$C$5:$C$304,$A15,'04_課題ToDo'!$M$5:$M$304,INDEX(_ゴミ箱_Backup!$B$72:$D$72,1,MATCH(言語切替!$B$3,_ゴミ箱_Backup!$B$1:$D$1,0)))+COUNTIFS('04_課題ToDo'!$C$5:$C$304,$A15,'04_課題ToDo'!$M$5:$M$304,INDEX(_ゴミ箱_Backup!$B$73:$D$73,1,MATCH(言語切替!$B$3,_ゴミ箱_Backup!$B$1:$D$1,0))) -> 0 | G15: =COUNTIFS('06_KPI'!$B$5:$B$204,$A15,'06_KPI'!$O$5:$O$204,INDEX(_ゴミ箱_Backup!$B$94:$D$94,1,MATCH(言語切替!$B$3,_ゴミ箱_Backup!$B$1:$D$1,0))) -> 0
A16: WG-6 | B16: =COUNTIFS('03_WBS'!$B$5:$B$204,$A16,'03_WBS'!$L$5:$L$204,"<>"&INDEX(_ゴミ箱_Backup!$B$75:$D$75,1,MATCH(言語切替!$B$3,_ゴミ箱_Backup!$B$1:$D$1,0))) -> 0 | C16: =COUNTIFS('03_WBS'!$B$5:$B$204,$A16,'03_WBS'!$N$5:$N$204,INDEX(_ゴミ箱_Backup!$B$92:$D$92,1,MATCH(言語切替!$B$3,_ゴミ箱_Backup!$B$1:$D$1,0))) -> 0 | D16: =COUNTIFS('04_課題ToDo'!$C$5:$C$304,$A16,'04_課題ToDo'!$M$5:$M$304,"<>"&INDEX(_ゴミ箱_Backup!$B$75:$D$75,1,MATCH(言語切替!$B$3,_ゴミ箱_Backup!$B$1:$D$1,0)),'04_課題ToDo'!$M$5:$M$304,"<>"&INDEX(_ゴミ箱_Backup!$B$77:$D$77,1,MATCH(言語切替!$B$3,_ゴミ箱_Backup!$B$1:$D$1,0))) -> 0 | E16: =COUNTIFS('04_課題ToDo'!$C$5:$C$304,$A16,'04_課題ToDo'!$S$5:$S$304,"High")+COUNTIFS('04_課題ToDo'!$C$5:$C$304,$A16,'04_課題ToDo'!$S$5:$S$304,INDEX(_ゴミ箱_Backup!$B$117:$D$247,MATCH("ALERT_OVERDUE",_ゴミ箱_Backup!$A$117:$A$247,0),MATCH(言語切替!$B$3,_ゴミ箱_Backup!$B$1:$D$1,0))) -> 0 | F16: =COUNTIFS('04_課題ToDo'!$C$5:$C$304,$A16,'04_課題ToDo'!$M$5:$M$304,INDEX(_ゴミ箱_Backup!$B$72:$D$72,1,MATCH(言語切替!$B$3,_ゴミ箱_Backup!$B$1:$D$1,0)))+COUNTIFS('04_課題ToDo'!$C$5:$C$304,$A16,'04_課題ToDo'!$M$5:$M$304,INDEX(_ゴミ箱_Backup!$B$73:$D$73,1,MATCH(言語切替!$B$3,_ゴミ箱_Backup!$B$1:$D$1,0))) -> 0 | G16: =COUNTIFS('06_KPI'!$B$5:$B$204,$A16,'06_KPI'!$O$5:$O$204,INDEX(_ゴミ箱_Backup!$B$94:$D$94,1,MATCH(言語切替!$B$3,_ゴミ箱_Backup!$B$1:$D$1,0))) -> 0
A17: WG-7 | B17: =COUNTIFS('03_WBS'!$B$5:$B$204,$A17,'03_WBS'!$L$5:$L$204,"<>"&INDEX(_ゴミ箱_Backup!$B$75:$D$75,1,MATCH(言語切替!$B$3,_ゴミ箱_Backup!$B$1:$D$1,0))) -> 0 | C17: =COUNTIFS('03_WBS'!$B$5:$B$204,$A17,'03_WBS'!$N$5:$N$204,INDEX(_ゴミ箱_Backup!$B$92:$D$92,1,MATCH(言語切替!$B$3,_ゴミ箱_Backup!$B$1:$D$1,0))) -> 0 | D17: =COUNTIFS('04_課題ToDo'!$C$5:$C$304,$A17,'04_課題ToDo'!$M$5:$M$304,"<>"&INDEX(_ゴミ箱_Backup!$B$75:$D$75,1,MATCH(言語切替!$B$3,_ゴミ箱_Backup!$B$1:$D$1,0)),'04_課題ToDo'!$M$5:$M$304,"<>"&INDEX(_ゴミ箱_Backup!$B$77:$D$77,1,MATCH(言語切替!$B$3,_ゴミ箱_Backup!$B$1:$D$1,0))) -> 0 | E17: =COUNTIFS('04_課題ToDo'!$C$5:$C$304,$A17,'04_課題ToDo'!$S$5:$S$304,"High")+COUNTIFS('04_課題ToDo'!$C$5:$C$304,$A17,'04_課題ToDo'!$S$5:$S$304,INDEX(_ゴミ箱_Backup!$B$117:$D$247,MATCH("ALERT_OVERDUE",_ゴミ箱_Backup!$A$117:$A$247,0),MATCH(言語切替!$B$3,_ゴミ箱_Backup!$B$1:$D$1,0))) -> 0 | F17: =COUNTIFS('04_課題ToDo'!$C$5:$C$304,$A17,'04_課題ToDo'!$M$5:$M$304,INDEX(_ゴミ箱_Backup!$B$72:$D$72,1,MATCH(言語切替!$B$3,_ゴミ箱_Backup!$B$1:$D$1,0)))+COUNTIFS('04_課題ToDo'!$C$5:$C$304,$A17,'04_課題ToDo'!$M$5:$M$304,INDEX(_ゴミ箱_Backup!$B$73:$D$73,1,MATCH(言語切替!$B$3,_ゴミ箱_Backup!$B$1:$D$1,0))) -> 0 | G17: =COUNTIFS('06_KPI'!$B$5:$B$204,$A17,'06_KPI'!$O$5:$O$204,INDEX(_ゴミ箱_Backup!$B$94:$D$94,1,MATCH(言語切替!$B$3,_ゴミ箱_Backup!$B$1:$D$1,0))) -> 0
A18: WG-8 | B18: =COUNTIFS('03_WBS'!$B$5:$B$204,$A18,'03_WBS'!$L$5:$L$204,"<>"&INDEX(_ゴミ箱_Backup!$B$75:$D$75,1,MATCH(言語切替!$B$3,_ゴミ箱_Backup!$B$1:$D$1,0))) -> 1 | C18: =COUNTIFS('03_WBS'!$B$5:$B$204,$A18,'03_WBS'!$N$5:$N$204,INDEX(_ゴミ箱_Backup!$B$92:$D$92,1,MATCH(言語切替!$B$3,_ゴミ箱_Backup!$B$1:$D$1,0))) -> 1 | D18: =COUNTIFS('04_課題ToDo'!$C$5:$C$304,$A18,'04_課題ToDo'!$M$5:$M$304,"<>"&INDEX(_ゴミ箱_Backup!$B$75:$D$75,1,MATCH(言語切替!$B$3,_ゴミ箱_Backup!$B$1:$D$1,0)),'04_課題ToDo'!$M$5:$M$304,"<>"&INDEX(_ゴミ箱_Backup!$B$77:$D$77,1,MATCH(言語切替!$B$3,_ゴミ箱_Backup!$B$1:$D$1,0))) -> 0 | E18: =COUNTIFS('04_課題ToDo'!$C$5:$C$304,$A18,'04_課題ToDo'!$S$5:$S$304,"High")+COUNTIFS('04_課題ToDo'!$C$5:$C$304,$A18,'04_課題ToDo'!$S$5:$S$304,INDEX(_ゴミ箱_Backup!$B$117:$D$247,MATCH("ALERT_OVERDUE",_ゴミ箱_Backup!$A$117:$A$247,0),MATCH(言語切替!$B$3,_ゴミ箱_Backup!$B$1:$D$1,0))) -> 0 | F18: =COUNTIFS('04_課題ToDo'!$C$5:$C$304,$A18,'04_課題ToDo'!$M$5:$M$304,INDEX(_ゴミ箱_Backup!$B$72:$D$72,1,MATCH(言語切替!$B$3,_ゴミ箱_Backup!$B$1:$D$1,0)))+COUNTIFS('04_課題ToDo'!$C$5:$C$304,$A18,'04_課題ToDo'!$M$5:$M$304,INDEX(_ゴミ箱_Backup!$B$73:$D$73,1,MATCH(言語切替!$B$3,_ゴミ箱_Backup!$B$1:$D$1,0))) -> 0 | G18: =COUNTIFS('06_KPI'!$B$5:$B$204,$A18,'06_KPI'!$O$5:$O$204,INDEX(_ゴミ箱_Backup!$B$94:$D$94,1,MATCH(言語切替!$B$3,_ゴミ箱_Backup!$B$1:$D$1,0))) -> 0
A19: WG-9 | B19: =COUNTIFS('03_WBS'!$B$5:$B$204,$A19,'03_WBS'!$L$5:$L$204,"<>"&INDEX(_ゴミ箱_Backup!$B$75:$D$75,1,MATCH(言語切替!$B$3,_ゴミ箱_Backup!$B$1:$D$1,0))) -> 0 | C19: =COUNTIFS('03_WBS'!$B$5:$B$204,$A19,'03_WBS'!$N$5:$N$204,INDEX(_ゴミ箱_Backup!$B$92:$D$92,1,MATCH(言語切替!$B$3,_ゴミ箱_Backup!$B$1:$D$1,0))) -> 0 | D19: =COUNTIFS('04_課題ToDo'!$C$5:$C$304,$A19,'04_課題ToDo'!$M$5:$M$304,"<>"&INDEX(_ゴミ箱_Backup!$B$75:$D$75,1,MATCH(言語切替!$B$3,_ゴミ箱_Backup!$B$1:$D$1,0)),'04_課題ToDo'!$M$5:$M$304,"<>"&INDEX(_ゴミ箱_Backup!$B$77:$D$77,1,MATCH(言語切替!$B$3,_ゴミ箱_Backup!$B$1:$D$1,0))) -> 0 | E19: =COUNTIFS('04_課題ToDo'!$C$5:$C$304,$A19,'04_課題ToDo'!$S$5:$S$304,"High")+COUNTIFS('04_課題ToDo'!$C$5:$C$304,$A19,'04_課題ToDo'!$S$5:$S$304,INDEX(_ゴミ箱_Backup!$B$117:$D$247,MATCH("ALERT_OVERDUE",_ゴミ箱_Backup!$A$117:$A$247,0),MATCH(言語切替!$B$3,_ゴミ箱_Backup!$B$1:$D$1,0))) -> 0 | F19: =COUNTIFS('04_課題ToDo'!$C$5:$C$304,$A19,'04_課題ToDo'!$M$5:$M$304,INDEX(_ゴミ箱_Backup!$B$72:$D$72,1,MATCH(言語切替!$B$3,_ゴミ箱_Backup!$B$1:$D$1,0)))+COUNTIFS('04_課題ToDo'!$C$5:$C$304,$A19,'04_課題ToDo'!$M$5:$M$304,INDEX(_ゴミ箱_Backup!$B$73:$D$73,1,MATCH(言語切替!$B$3,_ゴミ箱_Backup!$B$1:$D$1,0))) -> 0 | G19: =COUNTIFS('06_KPI'!$B$5:$B$204,$A19,'06_KPI'!$O$5:$O$204,INDEX(_ゴミ箱_Backup!$B$94:$D$94,1,MATCH(言語切替!$B$3,_ゴミ箱_Backup!$B$1:$D$1,0))) -> 0

Sheet 02_マスタ
A1: =INDEX(_ゴミ箱_Backup!$B$47:$D$98,MATCH("M_TITLE",_ゴミ箱_Backup!$A$47:$A$98,0),MATCH(言語切替!$B$3,_ゴミ箱_Backup!$B$1:$D$1,0)) -> #N/A
A2: =INDEX(_ゴミ箱_Backup!$B$47:$D$98,MATCH("M_DESC",_ゴミ箱_Backup!$A$47:$A$98,0),MATCH(言語切替!$B$3,_ゴミ箱_Backup!$B$1:$D$1,0)) -> #N/A
A4: =INDEX(_ゴミ箱_Backup!$B$47:$D$98,MATCH("M_WG",_ゴミ箱_Backup!$A$47:$A$98,0),MATCH(言語切替!$B$3,_ゴミ箱_Backup!$B$1:$D$1,0)) -> #N/A | C4: =INDEX(_ゴミ箱_Backup!$B$47:$D$98,MATCH("M_SITE",_ゴミ箱_Backup!$A$47:$A$98,0),MATCH(言語切替!$B$3,_ゴミ箱_Backup!$B$1:$D$1,0)) -> #N/A | E4: =INDEX(_ゴミ箱_Backup!$B$47:$D$98,MATCH("M_STATUS",_ゴミ箱_Backup!$A$47:$A$98,0),MATCH(言語切替!$B$3,_ゴミ箱_Backup!$B$1:$D$1,0)) -> #N/A | G4: =INDEX(_ゴミ箱_Backup!$B$47:$D$98,MATCH("M_PRIORITY",_ゴミ箱_Backup!$A$47:$A$98,0),MATCH(言語切替!$B$3,_ゴミ箱_Backup!$B$1:$D$1,0)) -> #N/A | I4: =INDEX(_ゴミ箱_Backup!$B$47:$D$98,MATCH("M_TYPE",_ゴミ箱_Backup!$A$47:$A$98,0),MATCH(言語切替!$B$3,_ゴミ箱_Backup!$B$1:$D$1,0)) -> #N/A | K4: =INDEX(_ゴミ箱_Backup!$B$47:$D$98,MATCH("M_KPI_LEVEL",_ゴミ箱_Backup!$A$47:$A$98,0),MATCH(言語切替!$B$3,_ゴミ箱_Backup!$B$1:$D$1,0)) -> #N/A | M4: =INDEX(_ゴミ箱_Backup!$B$47:$D$98,MATCH("M_JUDGMENT",_ゴミ箱_Backup!$A$47:$A$98,0),MATCH(言語切替!$B$3,_ゴミ箱_Backup!$B$1:$D$1,0)) -> #N/A
A5: =INDEX(_ゴミ箱_Backup!$B$47:$D$98,MATCH("M_ALL",_ゴミ箱_Backup!$A$47:$A$98,0),MATCH(言語切替!$B$3,_ゴミ箱_Backup!$B$1:$D$1,0)) -> #N/A | C5: =INDEX(_ゴミ箱_Backup!$B$47:$D$98,MATCH("M_COMMON",_ゴミ箱_Backup!$A$47:$A$98,0),MATCH(言語切替!$B$3,_ゴミ箱_Backup!$B$1:$D$1,0)) -> #N/A | E5: =INDEX(_ゴミ箱_Backup!$B$47:$D$98,MATCH("M_NOT_STARTED",_ゴミ箱_Backup!$A$47:$A$98,0),MATCH(言語切替!$B$3,_ゴミ箱_Backup!$B$1:$D$1,0)) -> #N/A | G5: =INDEX(_ゴミ箱_Backup!$B$47:$D$98,MATCH("M_HIGH",_ゴミ箱_Backup!$A$47:$A$98,0),MATCH(言語切替!$B$3,_ゴミ箱_Backup!$B$1:$D$1,0)) -> #N/A | I5: =INDEX(_ゴミ箱_Backup!$B$47:$D$98,MATCH("M_ISSUE",_ゴミ箱_Backup!$A$47:$A$98,0),MATCH(言語切替!$B$3,_ゴミ箱_Backup!$B$1:$D$1,0)) -> #N/A | K5: =INDEX(_ゴミ箱_Backup!$B$47:$D$98,MATCH("M_FOUNDATION",_ゴミ箱_Backup!$A$47:$A$98,0),MATCH(言語切替!$B$3,_ゴミ箱_Backup!$B$1:$D$1,0)) -> #N/A | M5: =INDEX(_ゴミ箱_Backup!$B$47:$D$98,MATCH("M_UNSET",_ゴミ箱_Backup!$A$47:$A$98,0),MATCH(言語切替!$B$3,_ゴミ箱_Backup!$B$1:$D$1,0)) -> #N/A
A6: =INDEX(_ゴミ箱_Backup!$B$47:$D$98,MATCH("M_WG1",_ゴミ箱_Backup!$A$47:$A$98,0),MATCH(言語切替!$B$3,_ゴミ箱_Backup!$B$1:$D$1,0)) -> #N/A | C6: =INDEX(_ゴミ箱_Backup!$B$47:$D$98,MATCH("M_KDC",_ゴミ箱_Backup!$A$47:$A$98,0),MATCH(言語切替!$B$3,_ゴミ箱_Backup!$B$1:$D$1,0)) -> #N/A | E6: =INDEX(_ゴミ箱_Backup!$B$47:$D$98,MATCH("M_IN_PROGRESS",_ゴミ箱_Backup!$A$47:$A$98,0),MATCH(言語切替!$B$3,_ゴミ箱_Backup!$B$1:$D$1,0)) -> #N/A | G6: =INDEX(_ゴミ箱_Backup!$B$47:$D$98,MATCH("M_MIDDLE",_ゴミ箱_Backup!$A$47:$A$98,0),MATCH(言語切替!$B$3,_ゴミ箱_Backup!$B$1:$D$1,0)) -> #N/A | I6: =INDEX(_ゴミ箱_Backup!$B$47:$D$98,MATCH("M_TODO",_ゴミ箱_Backup!$A$47:$A$98,0),MATCH(言語切替!$B$3,_ゴミ箱_Backup!$B$1:$D$1,0)) -> #N/A | K6: =INDEX(_ゴミ箱_Backup!$B$47:$D$98,MATCH("M_ADOPTION",_ゴミ箱_Backup!$A$47:$A$98,0),MATCH(言語切替!$B$3,_ゴミ箱_Backup!$B$1:$D$1,0)) -> #N/A | M6: =INDEX(_ゴミ箱_Backup!$B$47:$D$98,MATCH("M_ON_TRACK",_ゴミ箱_Backup!$A$47:$A$98,0),MATCH(言語切替!$B$3,_ゴミ箱_Backup!$B$1:$D$1,0)) -> #N/A
A7: =INDEX(_ゴミ箱_Backup!$B$47:$D$98,MATCH("M_WG2",_ゴミ箱_Backup!$A$47:$A$98,0),MATCH(言語切替!$B$3,_ゴミ箱_Backup!$B$1:$D$1,0)) -> #N/A | C7: =INDEX(_ゴミ箱_Backup!$B$47:$D$98,MATCH("M_KDTCN",_ゴミ箱_Backup!$A$47:$A$98,0),MATCH(言語切替!$B$3,_ゴミ箱_Backup!$B$1:$D$1,0)) -> #N/A | E7: =INDEX(_ゴミ箱_Backup!$B$47:$D$98,MATCH("M_WAIT_DECISION",_ゴミ箱_Backup!$A$47:$A$98,0),MATCH(言語切替!$B$3,_ゴミ箱_Backup!$B$1:$D$1,0)) -> #N/A | G7: =INDEX(_ゴミ箱_Backup!$B$47:$D$98,MATCH("M_LOW",_ゴミ箱_Backup!$A$47:$A$98,0),MATCH(言語切替!$B$3,_ゴミ箱_Backup!$B$1:$D$1,0)) -> #N/A | I7: =INDEX(_ゴミ箱_Backup!$B$47:$D$98,MATCH("M_DECISION",_ゴミ箱_Backup!$A$47:$A$98,0),MATCH(言語切替!$B$3,_ゴミ箱_Backup!$B$1:$D$1,0)) -> #N/A | K7: =INDEX(_ゴミ箱_Backup!$B$47:$D$98,MATCH("M_BUSINESS",_ゴミ箱_Backup!$A$47:$A$98,0),MATCH(言語切替!$B$3,_ゴミ箱_Backup!$B$1:$D$1,0)) -> #N/A | M7: =INDEX(_ゴミ箱_Backup!$B$47:$D$98,MATCH("M_CAUTION",_ゴミ箱_Backup!$A$47:$A$98,0),MATCH(言語切替!$B$3,_ゴミ箱_Backup!$B$1:$D$1,0)) -> #N/A
A8: =INDEX(_ゴミ箱_Backup!$B$47:$D$98,MATCH("M_WG3",_ゴミ箱_Backup!$A$47:$A$98,0),MATCH(言語切替!$B$3,_ゴミ箱_Backup!$B$1:$D$1,0)) -> #N/A | C8: =INDEX(_ゴミ箱_Backup!$B$47:$D$98,MATCH("M_KDTVN",_ゴミ箱_Backup!$A$47:$A$98,0),MATCH(言語切替!$B$3,_ゴミ箱_Backup!$B$1:$D$1,0)) -> #N/A | E8: =INDEX(_ゴミ箱_Backup!$B$47:$D$98,MATCH("M_WAIT_WG",_ゴミ箱_Backup!$A$47:$A$98,0),MATCH(言語切替!$B$3,_ゴミ箱_Backup!$B$1:$D$1,0)) -> #N/A | I8: =INDEX(_ゴミ箱_Backup!$B$47:$D$98,MATCH("M_RISK",_ゴミ箱_Backup!$A$47:$A$98,0),MATCH(言語切替!$B$3,_ゴミ箱_Backup!$B$1:$D$1,0)) -> #N/A | K8: =INDEX(_ゴミ箱_Backup!$B$47:$D$98,MATCH("M_INVESTMENT",_ゴミ箱_Backup!$A$47:$A$98,0),MATCH(言語切替!$B$3,_ゴミ箱_Backup!$B$1:$D$1,0)) -> #N/A | M8: =INDEX(_ゴミ箱_Backup!$B$47:$D$98,MATCH("M_DELAY",_ゴミ箱_Backup!$A$47:$A$98,0),MATCH(言語切替!$B$3,_ゴミ箱_Backup!$B$1:$D$1,0)) -> #N/A
A9: =INDEX(_ゴミ箱_Backup!$B$47:$D$98,MATCH("M_WG4",_ゴミ箱_Backup!$A$47:$A$98,0),MATCH(言語切替!$B$3,_ゴミ箱_Backup!$B$1:$D$1,0)) -> #N/A | E9: =INDEX(_ゴミ箱_Backup!$B$47:$D$98,MATCH("M_WAIT_COMPLETE",_ゴミ箱_Backup!$A$47:$A$98,0),MATCH(言語切替!$B$3,_ゴミ箱_Backup!$B$1:$D$1,0)) -> #N/A | M9: =INDEX(_ゴミ箱_Backup!$B$47:$D$98,MATCH("M_ACHIEVED",_ゴミ箱_Backup!$A$47:$A$98,0),MATCH(言語切替!$B$3,_ゴミ箱_Backup!$B$1:$D$1,0)) -> #N/A
A10: =INDEX(_ゴミ箱_Backup!$B$47:$D$98,MATCH("M_WG5",_ゴミ箱_Backup!$A$47:$A$98,0),MATCH(言語切替!$B$3,_ゴミ箱_Backup!$B$1:$D$1,0)) -> #N/A | E10: =INDEX(_ゴミ箱_Backup!$B$47:$D$98,MATCH("M_COMPLETE",_ゴミ箱_Backup!$A$47:$A$98,0),MATCH(言語切替!$B$3,_ゴミ箱_Backup!$B$1:$D$1,0)) -> #N/A | M10: =INDEX(_ゴミ箱_Backup!$B$47:$D$98,MATCH("M_NOT_ACHIEVED",_ゴミ箱_Backup!$A$47:$A$98,0),MATCH(言語切替!$B$3,_ゴミ箱_Backup!$B$1:$D$1,0)) -> #N/A
A11: =INDEX(_ゴミ箱_Backup!$B$47:$D$98,MATCH("M_WG6",_ゴミ箱_Backup!$A$47:$A$98,0),MATCH(言語切替!$B$3,_ゴミ箱_Backup!$B$1:$D$1,0)) -> #N/A | E11: =INDEX(_ゴミ箱_Backup!$B$47:$D$98,MATCH("M_HOLD",_ゴミ箱_Backup!$A$47:$A$98,0),MATCH(言語切替!$B$3,_ゴミ箱_Backup!$B$1:$D$1,0)) -> #N/A
A12: =INDEX(_ゴミ箱_Backup!$B$47:$D$98,MATCH("M_WG7",_ゴミ箱_Backup!$A$47:$A$98,0),MATCH(言語切替!$B$3,_ゴミ箱_Backup!$B$1:$D$1,0)) -> #N/A | E12: =INDEX(_ゴミ箱_Backup!$B$47:$D$98,MATCH("M_WITHDRAWN",_ゴミ箱_Backup!$A$47:$A$98,0),MATCH(言語切替!$B$3,_ゴミ箱_Backup!$B$1:$D$1,0)) -> #N/A
A13: =INDEX(_ゴミ箱_Backup!$B$47:$D$98,MATCH("M_WG8",_ゴミ箱_Backup!$A$47:$A$98,0),MATCH(言語切替!$B$3,_ゴミ箱_Backup!$B$1:$D$1,0)) -> #N/A
A14: =INDEX(_ゴミ箱_Backup!$B$47:$D$98,MATCH("M_WG9",_ゴミ箱_Backup!$A$47:$A$98,0),MATCH(言語切替!$B$3,_ゴミ箱_Backup!$B$1:$D$1,0)) -> #N/A
A18: =INDEX(_ゴミ箱_Backup!$B$47:$D$98,MATCH("M_PRIORITY_GUIDE",_ゴミ箱_Backup!$A$47:$A$98,0),MATCH(言語切替!$B$3,_ゴミ箱_Backup!$B$1:$D$1,0)) -> #N/A
A19: =INDEX(_ゴミ箱_Backup!$B$47:$D$98,MATCH("M_HIGH_DESC",_ゴミ箱_Backup!$A$47:$A$98,0),MATCH(言語切替!$B$3,_ゴミ箱_Backup!$B$1:$D$1,0)) -> #N/A
A20: =INDEX(_ゴミ箱_Backup!$B$47:$D$98,MATCH("M_MIDDLE_DESC",_ゴミ箱_Backup!$A$47:$A$98,0),MATCH(言語切替!$B$3,_ゴミ箱_Backup!$B$1:$D$1,0)) -> #N/A
A21: =INDEX(_ゴミ箱_Backup!$B$47:$D$98,MATCH("M_LOW_DESC",_ゴミ箱_Backup!$A$47:$A$98,0),MATCH(言語切替!$B$3,_ゴミ箱_Backup!$B$1:$D$1,0)) -> #N/A

Sheet 03_WBS
A1: =INDEX(_ゴミ箱_Backup!$B$99:$D$116,MATCH("WBS_TITLE",_ゴミ箱_Backup!$A$99:$A$116,0),MATCH(言語切替!$B$3,_ゴミ箱_Backup!$B$1:$D$1,0)) -> #N/A
A2: =INDEX(_ゴミ箱_Backup!$B$99:$D$116,MATCH("WBS_DESC",_ゴミ箱_Backup!$A$99:$A$116,0),MATCH(言語切替!$B$3,_ゴミ箱_Backup!$B$1:$D$1,0)) -> #N/A
A3: =INDEX([1]_翻訳マスタ!$B$2:$D$300,MATCH("PARA_HOWTO",[1]_翻訳マスタ!$A$2:$A$300,0),MATCH(言語切替!$B$3,[1]_翻訳マスタ!$B$1:$D$1,0)) -> #N/A
A4: =INDEX(_ゴミ箱_Backup!$B$99:$D$116,MATCH("WBS_ID",_ゴミ箱_Backup!$A$99:$A$116,0),MATCH(言語切替!$B$3,_ゴミ箱_Backup!$B$1:$D$1,0)) -> #N/A | B4: =INDEX(_ゴミ箱_Backup!$B$99:$D$116,MATCH("WBS_WG",_ゴミ箱_Backup!$A$99:$A$116,0),MATCH(言語切替!$B$3,_ゴミ箱_Backup!$B$1:$D$1,0)) -> #N/A | C4: =INDEX(_ゴミ箱_Backup!$B$99:$D$116,MATCH("WBS_SITE",_ゴミ箱_Backup!$A$99:$A$116,0),MATCH(言語切替!$B$3,_ゴミ箱_Backup!$B$1:$D$1,0)) -> #N/A | D4: =INDEX(_ゴミ箱_Backup!$B$99:$D$116,MATCH("WBS_CATEGORY",_ゴミ箱_Backup!$A$99:$A$116,0),MATCH(言語切替!$B$3,_ゴミ箱_Backup!$B$1:$D$1,0)) -> #N/A | E4: =INDEX(_ゴミ箱_Backup!$B$99:$D$116,MATCH("WBS_TASK",_ゴミ箱_Backup!$A$99:$A$116,0),MATCH(言語切替!$B$3,_ゴミ箱_Backup!$B$1:$D$1,0)) -> #N/A | F4: =INDEX(_ゴミ箱_Backup!$B$99:$D$116,MATCH("WBS_OWNER",_ゴミ箱_Backup!$A$99:$A$116,0),MATCH(言語切替!$B$3,_ゴミ箱_Backup!$B$1:$D$1,0)) -> #N/A | G4: =INDEX(_ゴミ箱_Backup!$B$99:$D$116,MATCH("WBS_PLAN_START",_ゴミ箱_Backup!$A$99:$A$116,0),MATCH(言語切替!$B$3,_ゴミ箱_Backup!$B$1:$D$1,0)) -> #N/A | H4: =INDEX(_ゴミ箱_Backup!$B$99:$D$116,MATCH("WBS_PLAN_END",_ゴミ箱_Backup!$A$99:$A$116,0),MATCH(言語切替!$B$3,_ゴミ箱_Backup!$B$1:$D$1,0)) -> #N/A | I4: =INDEX(_ゴミ箱_Backup!$B$99:$D$116,MATCH("WBS_ACTUAL_START",_ゴミ箱_Backup!$A$99:$A$116,0),MATCH(言語切替!$B$3,_ゴミ箱_Backup!$B$1:$D$1,0)) -> #N/A | J4: =INDEX(_ゴミ箱_Backup!$B$99:$D$116,MATCH("WBS_ACTUAL_END",_ゴミ箱_Backup!$A$99:$A$116,0),MATCH(言語切替!$B$3,_ゴミ箱_Backup!$B$1:$D$1,0)) -> #N/A | K4: =INDEX(_ゴミ箱_Backup!$B$99:$D$116,MATCH("WBS_PROGRESS",_ゴミ箱_Backup!$A$99:$A$116,0),MATCH(言語切替!$B$3,_ゴミ箱_Backup!$B$1:$D$1,0)) -> #N/A | L4: =INDEX(_ゴミ箱_Backup!$B$99:$D$116,MATCH("WBS_STATUS",_ゴミ箱_Backup!$A$99:$A$116,0),MATCH(言語切替!$B$3,_ゴミ箱_Backup!$B$1:$D$1,0)) -> #N/A | M4: =INDEX(_ゴミ箱_Backup!$B$99:$D$116,MATCH("WBS_DAYS",_ゴミ箱_Backup!$A$99:$A$116,0),MATCH(言語切替!$B$3,_ゴミ箱_Backup!$B$1:$D$1,0)) -> #N/A | N4: =INDEX(_ゴミ箱_Backup!$B$99:$D$116,MATCH("WBS_DELAY",_ゴミ箱_Backup!$A$99:$A$116,0),MATCH(言語切替!$B$3,_ゴミ箱_Backup!$B$1:$D$1,0)) -> #N/A | O4: =INDEX(_ゴミ箱_Backup!$B$99:$D$116,MATCH("WBS_LINK",_ゴミ箱_Backup!$A$99:$A$116,0),MATCH(言語切替!$B$3,_ゴミ箱_Backup!$B$1:$D$1,0)) -> #N/A | P4: =INDEX(_ゴミ箱_Backup!$B$99:$D$116,MATCH("WBS_NOTE",_ゴミ箱_Backup!$A$99:$A$116,0),MATCH(言語切替!$B$3,_ゴミ箱_Backup!$B$1:$D$1,0)) -> #N/A | Q4: =INDEX(_ゴミ箱_Backup!$B$2:$D$300,MATCH("WBS_TASK",_ゴミ箱_Backup!$A$2:$A$300,0),MATCH(言語切替!$B$3,_ゴミ箱_Backup!$B$1:$D$1,0))&INDEX(_ゴミ箱_Backup!$B$2:$D$300,MATCH("NEW_JP_SUFFIX",_ゴミ箱_Backup!$A$2:$A$300,0),MATCH(言語切替!$B$3,_ゴミ箱_Backup!$B$1:$D$1,0)) -> #N/A | R4: =INDEX(_ゴミ箱_Backup!$B$2:$D$300,MATCH("WBS_TASK",_ゴミ箱_Backup!$A$2:$A$300,0),MATCH(言語切替!$B$3,_ゴミ箱_Backup!$B$1:$D$1,0))&INDEX(_ゴミ箱_Backup!$B$2:$D$300,MATCH("NEW_CN_SUFFIX",_ゴミ箱_Backup!$A$2:$A$300,0),MATCH(言語切替!$B$3,_ゴミ箱_Backup!$B$1:$D$1,0)) -> #N/A | S4: =INDEX(_ゴミ箱_Backup!$B$2:$D$300,MATCH("WBS_TASK",_ゴミ箱_Backup!$A$2:$A$300,0),MATCH(言語切替!$B$3,_ゴミ箱_Backup!$B$1:$D$1,0))&INDEX(_ゴミ箱_Backup!$B$2:$D$300,MATCH("NEW_VI_SUFFIX",_ゴミ箱_Backup!$A$2:$A$300,0),MATCH(言語切替!$B$3,_ゴミ箱_Backup!$B$1:$D$1,0)) -> #N/A | T4: =INDEX(_ゴミ箱_Backup!$B$2:$D$300,MATCH("WBS_NOTE",_ゴミ箱_Backup!$A$2:$A$300,0),MATCH(言語切替!$B$3,_ゴミ箱_Backup!$B$1:$D$1,0))&INDEX(_ゴミ箱_Backup!$B$2:$D$300,MATCH("NEW_JP_SUFFIX",_ゴミ箱_Backup!$A$2:$A$300,0),MATCH(言語切替!$B$3,_ゴミ箱_Backup!$B$1:$D$1,0)) -> #N/A | U4: =INDEX(_ゴミ箱_Backup!$B$2:$D$300,MATCH("WBS_NOTE",_ゴミ箱_Backup!$A$2:$A$300,0),MATCH(言語切替!$B$3,_ゴミ箱_Backup!$B$1:$D$1,0))&INDEX(_ゴミ箱_Backup!$B$2:$D$300,MATCH("NEW_CN_SUFFIX",_ゴミ箱_Backup!$A$2:$A$300,0),MATCH(言語切替!$B$3,_ゴミ箱_Backup!$B$1:$D$1,0)) -> #N/A | V4: =INDEX(_ゴミ箱_Backup!$B$2:$D$300,MATCH("WBS_NOTE",_ゴミ箱_Backup!$A$2:$A$300,0),MATCH(言語切替!$B$3,_ゴミ箱_Backup!$B$1:$D$1,0))&INDEX(_ゴミ箱_Backup!$B$2:$D$300,MATCH("NEW_VI_SUFFIX",_ゴミ箱_Backup!$A$2:$A$300,0),MATCH(言語切替!$B$3,_ゴミ箱_Backup!$B$1:$D$1,0)) -> #N/A
A5: WBS-001 | B5: ='02_マスタ'!$A$5 -> #N/A | C5: KDC | D5: =INDEX(_ゴミ箱_Backup!$B$117:$D$247,MATCH("WBS_CAT_STARTUP",_ゴミ箱_Backup!$A$117:$A$247,0),MATCH(言語切替!$B$3,_ゴミ箱_Backup!$B$1:$D$1,0)) -> #N/A | E5: =INDEX(_ゴミ箱_Backup!$B$117:$D$247,MATCH("WBS_TASK_1",_ゴミ箱_Backup!$A$117:$A$247,0),MATCH(言語切替!$B$3,_ゴミ箱_Backup!$B$1:$D$1,0)) -> #N/A | F5: =INDEX(_ゴミ箱_Backup!$B$117:$D$247,MATCH("ROLE_PMO",_ゴミ箱_Backup!$A$117:$A$247,0),MATCH(言語切替!$B$3,_ゴミ箱_Backup!$B$1:$D$1,0)) -> #N/A | G5: 46288 | H5: 46295 | K5: =IF(OR(G5="",H5=""),"",IF(J5<>"",1,IF(I5="",0,MAX(0,MIN(1,(TODAY()-G5)/(H5-G5+1)))))) -> 0 | L5: ='02_マスタ'!$E$6 -> #N/A | M5: =IF(H5="","",H5-TODAY()) -> 1 | N5: =IF(H5="","",IF(J5<>"",INDEX(_ゴミ箱_Backup!$B$75:$D$75,1,MATCH(言語切替!$B$3,_ゴミ箱_Backup!$B$1:$D$1,0)),IF(TODAY()>H5,INDEX(_ゴミ箱_Backup!$B$92:$D$92,1,MATCH(言語切替!$B$3,_ゴミ箱_Backup!$B$1:$D$1,0)),IF(H5-TODAY()<=7,INDEX(_ゴミ箱_Backup!$B$91:$D$91,1,MATCH(言語切替!$B$3,_ゴミ箱_Backup!$B$1:$D$1,0)),INDEX(_ゴミ箱_Backup!$B$90:$D$90,1,MATCH(言語切替!$B$3,_ゴミ箱_Backup!$B$1:$D$1,0)))))) -> #N/A | P5: =INDEX(_ゴミ箱_Backup!$B$117:$D$247,MATCH("COMMON_EXAMPLE",_ゴミ箱_Backup!$A$117:$A$247,0),MATCH(言語切替!$B$3,_ゴミ箱_Backup!$B$1:$D$1,0)) -> #N/A | Q5: =IF(E5="","",IFERROR(_xlfn.TRANSLATE(E5,,"ja"),"")) -> #N/A | R5: =IF(E5="","",IFERROR(_xlfn.TRANSLATE(E5,,"zh-Hans"),"")) -> #N/A | S5: =IF(E5="","",IFERROR(_xlfn.TRANSLATE(E5,,"vi"),"")) -> #N/A | T5: =IF(P5="","",IFERROR(_xlfn.TRANSLATE(P5,,"ja"),"")) -> #N/A | U5: =IF(P5="","",IFERROR(_xlfn.TRANSLATE(P5,,"zh-Hans"),"")) -> #N/A | V5: =IF(P5="","",IFERROR(_xlfn.TRANSLATE(P5,,"vi"),"")) -> #N/A
A6: WBS-002 | B6: WG-1 | C6: KDTVN | D6: =INDEX(_ゴミ箱_Backup!$B$117:$D$247,MATCH("WBS_CAT_ANALYSIS",_ゴミ箱_Backup!$A$117:$A$247,0),MATCH(言語切替!$B$3,_ゴミ箱_Backup!$B$1:$D$1,0)) -> #N/A | E6: =INDEX(_ゴミ箱_Backup!$B$117:$D$247,MATCH("WBS_TASK_2",_ゴミ箱_Backup!$A$117:$A$247,0),MATCH(言語切替!$B$3,_ゴミ箱_Backup!$B$1:$D$1,0)) -> #N/A | F6: WG Leader | G6: 46294 | H6: 46311 | K6: =IF(OR(G6="",H6=""),"",IF(J6<>"",1,IF(I6="",0,MAX(0,MIN(1,(TODAY()-G6)/(H6-G6+1)))))) -> 0 | L6: ='02_マスタ'!$E$5 -> #N/A | M6: =IF(H6="","",H6-TODAY()) -> 17 | N6: =IF(H6="","",IF(J6<>"",INDEX(_ゴミ箱_Backup!$B$75:$D$75,1,MATCH(言語切替!$B$3,_ゴミ箱_Backup!$B$1:$D$1,0)),IF(TODAY()>H6,INDEX(_ゴミ箱_Backup!$B$92:$D$92,1,MATCH(言語切替!$B$3,_ゴミ箱_Backup!$B$1:$D$1,0)),IF(H6-TODAY()<=7,INDEX(_ゴミ箱_Backup!$B$91:$D$91,1,MATCH(言語切替!$B$3,_ゴミ箱_Backup!$B$1:$D$1,0)),INDEX(_ゴミ箱_Backup!$B$90:$D$90,1,MATCH(言語切替!$B$3,_ゴミ箱_Backup!$B$1:$D$1,0)))))) -> #N/A | P6: =INDEX(_ゴミ箱_Backup!$B$117:$D$247,MATCH("COMMON_EXAMPLE",_ゴミ箱_Backup!$A$117:$A$247,0),MATCH(言語切替!$B$3,_ゴミ箱_Backup!$B$1:$D$1,0)) -> #N/A | Q6: =IF(E6="","",IFERROR(_xlfn.TRANSLATE(E6,,"ja"),"")) -> #N/A | R6: =IF(E6="","",IFERROR(_xlfn.TRANSLATE(E6,,"zh-Hans"),"")) -> #N/A | S6: =IF(E6="","",IFERROR(_xlfn.TRANSLATE(E6,,"vi"),"")) -> #N/A | T6: =IF(P6="","",IFERROR(_xlfn.TRANSLATE(P6,,"ja"),"")) -> #N/A | U6: =IF(P6="","",IFERROR(_xlfn.TRANSLATE(P6,,"zh-Hans"),"")) -> #N/A | V6: =IF(P6="","",IFERROR(_xlfn.TRANSLATE(P6,,"vi"),"")) -> #N/A
A7: WBS-003 | B7: WG-8 | C7: ='02_マスタ'!$C$5 -> #N/A | D7: =INDEX(_ゴミ箱_Backup!$B$117:$D$247,MATCH("WBS_CAT_POLICY",_ゴミ箱_Backup!$A$117:$A$247,0),MATCH(言語切替!$B$3,_ゴミ箱_Backup!$B$1:$D$1,0)) -> #N/A | E7: =INDEX(_ゴミ箱_Backup!$B$117:$D$247,MATCH("WBS_TASK_3",_ゴミ箱_Backup!$A$117:$A$247,0),MATCH(言語切替!$B$3,_ゴミ箱_Backup!$B$1:$D$1,0)) -> #N/A | F7: WG Leader | G7: 46296 | H7: 46325 | K7: =IF(OR(G7="",H7=""),"",IF(J7<>"",1,IF(I7="",0,MAX(0,MIN(1,(TODAY()-G7)/(H7-G7+1)))))) -> 0 | L7: ='02_マスタ'!$E$5 -> #N/A | M7: =IF(H7="","",H7-TODAY()) -> 31 | N7: =IF(H7="","",IF(J7<>"",INDEX(_ゴミ箱_Backup!$B$75:$D$75,1,MATCH(言語切替!$B$3,_ゴミ箱_Backup!$B$1:$D$1,0)),IF(TODAY()>H7,INDEX(_ゴミ箱_Backup!$B$92:$D$92,1,MATCH(言語切替!$B$3,_ゴミ箱_Backup!$B$1:$D$1,0)),IF(H7-TODAY()<=7,INDEX(_ゴミ箱_Backup!$B$91:$D$91,1,MATCH(言語切替!$B$3,_ゴミ箱_Backup!$B$1:$D$1,0)),INDEX(_ゴミ箱_Backup!$B$90:$D$90,1,MATCH(言語切替!$B$3,_ゴミ箱_Backup!$B$1:$D$1,0)))))) -> #N/A | P7: =INDEX(_ゴミ箱_Backup!$B$117:$D$247,MATCH("COMMON_EXAMPLE",_ゴミ箱_Backup!$A$117:$A$247,0),MATCH(言語切替!$B$3,_ゴミ箱_Backup!$B$1:$D$1,0)) -> #N/A | Q7: =IF(E7="","",IFERROR(_xlfn.TRANSLATE(E7,,"ja"),"")) -> #N/A | R7: =IF(E7="","",IFERROR(_xlfn.TRANSLATE(E7,,"zh-Hans"),"")) -> #N/A | S7: =IF(E7="","",IFERROR(_xlfn.TRANSLATE(E7,,"vi"),"")) -> #N/A | T7: =IF(P7="","",IFERROR(_xlfn.TRANSLATE(P7,,"ja"),"")) -> #N/A | U7: =IF(P7="","",IFERROR(_xlfn.TRANSLATE(P7,,"zh-Hans"),"")) -> #N/A | V7: =IF(P7="","",IFERROR(_xlfn.TRANSLATE(P7,,"vi"),"")) -> #N/A
K8: =IF(OR(G8="",H8=""),"",IF(J8<>"",1,IF(I8="",0,MAX(0,MIN(1,(TODAY()-G8)/(H8-G8+1)))))) | M8: =IF(H8="","",H8-TODAY()) | N8: =IF(H8="","",IF(J8<>"",INDEX(_ゴミ箱_Backup!$B$75:$D$75,1,MATCH(言語切替!$B$3,_ゴミ箱_Backup!$B$1:$D$1,0)),IF(TODAY()>H8,INDEX(_ゴミ箱_Backup!$B$92:$D$92,1,MATCH(言語切替!$B$3,_ゴミ箱_Backup!$B$1:$D$1,0)),IF(H8-TODAY()<=7,INDEX(_ゴミ箱_Backup!$B$91:$D$91,1,MATCH(言語切替!$B$3,_ゴミ箱_Backup!$B$1:$D$1,0)),INDEX(_ゴミ箱_Backup!$B$90:$D$90,1,MATCH(言語切替!$B$3,_ゴミ箱_Backup!$B$1:$D$1,0)))))) | Q8: =IF(E8="","",IFERROR(_xlfn.TRANSLATE(E8,,"ja"),"")) | R8: =IF(E8="","",IFERROR(_xlfn.TRANSLATE(E8,,"zh-Hans"),"")) | S8: =IF(E8="","",IFERROR(_xlfn.TRANSLATE(E8,,"vi"),"")) | T8: =IF(P8="","",IFERROR(_xlfn.TRANSLATE(P8,,"ja"),"")) | U8: =IF(P8="","",IFERROR(_xlfn.TRANSLATE(P8,,"zh-Hans"),"")) | V8: =IF(P8="","",IFERROR(_xlfn.TRANSLATE(P8,,"vi"),""))
K9: =IF(OR(G9="",H9=""),"",IF(J9<>"",1,IF(I9="",0,MAX(0,MIN(1,(TODAY()-G9)/(H9-G9+1)))))) | M9: =IF(H9="","",H9-TODAY()) | N9: =IF(H9="","",IF(J9<>"",INDEX(_ゴミ箱_Backup!$B$75:$D$75,1,MATCH(言語切替!$B$3,_ゴミ箱_Backup!$B$1:$D$1,0)),IF(TODAY()>H9,INDEX(_ゴミ箱_Backup!$B$92:$D$92,1,MATCH(言語切替!$B$3,_ゴミ箱_Backup!$B$1:$D$1,0)),IF(H9-TODAY()<=7,INDEX(_ゴミ箱_Backup!$B$91:$D$91,1,MATCH(言語切替!$B$3,_ゴミ箱_Backup!$B$1:$D$1,0)),INDEX(_ゴミ箱_Backup!$B$90:$D$90,1,MATCH(言語切替!$B$3,_ゴミ箱_Backup!$B$1:$D$1,0)))))) | Q9: =IF(E9="","",IFERROR(_xlfn.TRANSLATE(E9,,"ja"),"")) | R9: =IF(E9="","",IFERROR(_xlfn.TRANSLATE(E9,,"zh-Hans"),"")) | S9: =IF(E9="","",IFERROR(_xlfn.TRANSLATE(E9,,"vi"),"")) | T9: =IF(P9="","",IFERROR(_xlfn.TRANSLATE(P9,,"ja"),"")) | U9: =IF(P9="","",IFERROR(_xlfn.TRANSLATE(P9,,"zh-Hans"),"")) | V9: =IF(P9="","",IFERROR(_xlfn.TRANSLATE(P9,,"vi"),""))
K10: =IF(OR(G10="",H10=""),"",IF(J10<>"",1,IF(I10="",0,MAX(0,MIN(1,(TODAY()-G10)/(H10-G10+1)))))) | M10: =IF(H10="","",H10-TODAY()) | N10: =IF(H10="","",IF(J10<>"",INDEX(_ゴミ箱_Backup!$B$75:$D$75,1,MATCH(言語切替!$B$3,_ゴミ箱_Backup!$B$1:$D$1,0)),IF(TODAY()>H10,INDEX(_ゴミ箱_Backup!$B$92:$D$92,1,MATCH(言語切替!$B$3,_ゴミ箱_Backup!$B$1:$D$1,0)),IF(H10-TODAY()<=7,INDEX(_ゴミ箱_Backup!$B$91:$D$91,1,MATCH(言語切替!$B$3,_ゴミ箱_Backup!$B$1:$D$1,0)),INDEX(_ゴミ箱_Backup!$B$90:$D$90,1,MATCH(言語切替!$B$3,_ゴミ箱_Backup!$B$1:$D$1,0)))))) | Q10: =IF(E10="","",IFERROR(_xlfn.TRANSLATE(E10,,"ja"),"")) | R10: =IF(E10="","",IFERROR(_xlfn.TRANSLATE(E10,,"zh-Hans"),"")) | S10: =IF(E10="","",IFERROR(_xlfn.TRANSLATE(E10,,"vi"),"")) | T10: =IF(P10="","",IFERROR(_xlfn.TRANSLATE(P10,,"ja"),"")) | U10: =IF(P10="","",IFERROR(_xlfn.TRANSLATE(P10,,"zh-Hans"),"")) | V10: =IF(P10="","",IFERROR(_xlfn.TRANSLATE(P10,,"vi"),""))
K11: =IF(OR(G11="",H11=""),"",IF(J11<>"",1,IF(I11="",0,MAX(0,MIN(1,(TODAY()-G11)/(H11-G11+1)))))) | M11: =IF(H11="","",H11-TODAY()) | N11: =IF(H11="","",IF(J11<>"",INDEX(_ゴミ箱_Backup!$B$75:$D$75,1,MATCH(言語切替!$B$3,_ゴミ箱_Backup!$B$1:$D$1,0)),IF(TODAY()>H11,INDEX(_ゴミ箱_Backup!$B$92:$D$92,1,MATCH(言語切替!$B$3,_ゴミ箱_Backup!$B$1:$D$1,0)),IF(H11-TODAY()<=7,INDEX(_ゴミ箱_Backup!$B$91:$D$91,1,MATCH(言語切替!$B$3,_ゴミ箱_Backup!$B$1:$D$1,0)),INDEX(_ゴミ箱_Backup!$B$90:$D$90,1,MATCH(言語切替!$B$3,_ゴミ箱_Backup!$B$1:$D$1,0)))))) | Q11: =IF(E11="","",IFERROR(_xlfn.TRANSLATE(E11,,"ja"),"")) | R11: =IF(E11="","",IFERROR(_xlfn.TRANSLATE(E11,,"zh-Hans"),"")) | S11: =IF(E11="","",IFERROR(_xlfn.TRANSLATE(E11,,"vi"),"")) | T11: =IF(P11="","",IFERROR(_xlfn.TRANSLATE(P11,,"ja"),"")) | U11: =IF(P11="","",IFERROR(_xlfn.TRANSLATE(P11,,"zh-Hans"),"")) | V11: =IF(P11="","",IFERROR(_xlfn.TRANSLATE(P11,,"vi"),""))
K12: =IF(OR(G12="",H12=""),"",IF(J12<>"",1,IF(I12="",0,MAX(0,MIN(1,(TODAY()-G12)/(H12-G12+1)))))) | M12: =IF(H12="","",H12-TODAY()) | N12: =IF(H12="","",IF(J12<>"",INDEX(_ゴミ箱_Backup!$B$75:$D$75,1,MATCH(言語切替!$B$3,_ゴミ箱_Backup!$B$1:$D$1,0)),IF(TODAY()>H12,INDEX(_ゴミ箱_Backup!$B$92:$D$92,1,MATCH(言語切替!$B$3,_ゴミ箱_Backup!$B$1:$D$1,0)),IF(H12-TODAY()<=7,INDEX(_ゴミ箱_Backup!$B$91:$D$91,1,MATCH(言語切替!$B$3,_ゴミ箱_Backup!$B$1:$D$1,0)),INDEX(_ゴミ箱_Backup!$B$90:$D$90,1,MATCH(言語切替!$B$3,_ゴミ箱_Backup!$B$1:$D$1,0)))))) | Q12: =IF(E12="","",IFERROR(_xlfn.TRANSLATE(E12,,"ja"),"")) | R12: =IF(E12="","",IFERROR(_xlfn.TRANSLATE(E12,,"zh-Hans"),"")) | S12: =IF(E12="","",IFERROR(_xlfn.TRANSLATE(E12,,"vi"),"")) | T12: =IF(P12="","",IFERROR(_xlfn.TRANSLATE(P12,,"ja"),"")) | U12: =IF(P12="","",IFERROR(_xlfn.TRANSLATE(P12,,"zh-Hans"),"")) | V12: =IF(P12="","",IFERROR(_xlfn.TRANSLATE(P12,,"vi"),""))
K13: =IF(OR(G13="",H13=""),"",IF(J13<>"",1,IF(I13="",0,MAX(0,MIN(1,(TODAY()-G13)/(H13-G13+1)))))) | M13: =IF(H13="","",H13-TODAY()) | N13: =IF(H13="","",IF(J13<>"",INDEX(_ゴミ箱_Backup!$B$75:$D$75,1,MATCH(言語切替!$B$3,_ゴミ箱_Backup!$B$1:$D$1,0)),IF(TODAY()>H13,INDEX(_ゴミ箱_Backup!$B$92:$D$92,1,MATCH(言語切替!$B$3,_ゴミ箱_Backup!$B$1:$D$1,0)),IF(H13-TODAY()<=7,INDEX(_ゴミ箱_Backup!$B$91:$D$91,1,MATCH(言語切替!$B$3,_ゴミ箱_Backup!$B$1:$D$1,0)),INDEX(_ゴミ箱_Backup!$B$90:$D$90,1,MATCH(言語切替!$B$3,_ゴミ箱_Backup!$B$1:$D$1,0)))))) | Q13: =IF(E13="","",IFERROR(_xlfn.TRANSLATE(E13,,"ja"),"")) | R13: =IF(E13="","",IFERROR(_xlfn.TRANSLATE(E13,,"zh-Hans"),"")) | S13: =IF(E13="","",IFERROR(_xlfn.TRANSLATE(E13,,"vi"),"")) | T13: =IF(P13="","",IFERROR(_xlfn.TRANSLATE(P13,,"ja"),"")) | U13: =IF(P13="","",IFERROR(_xlfn.TRANSLATE(P13,,"zh-Hans"),"")) | V13: =IF(P13="","",IFERROR(_xlfn.TRANSLATE(P13,,"vi"),""))
K14: =IF(OR(G14="",H14=""),"",IF(J14<>"",1,IF(I14="",0,MAX(0,MIN(1,(TODAY()-G14)/(H14-G14+1)))))) | M14: =IF(H14="","",H14-TODAY()) | N14: =IF(H14="","",IF(J14<>"",INDEX(_ゴミ箱_Backup!$B$75:$D$75,1,MATCH(言語切替!$B$3,_ゴミ箱_Backup!$B$1:$D$1,0)),IF(TODAY()>H14,INDEX(_ゴミ箱_Backup!$B$92:$D$92,1,MATCH(言語切替!$B$3,_ゴミ箱_Backup!$B$1:$D$1,0)),IF(H14-TODAY()<=7,INDEX(_ゴミ箱_Backup!$B$91:$D$91,1,MATCH(言語切替!$B$3,_ゴミ箱_Backup!$B$1:$D$1,0)),INDEX(_ゴミ箱_Backup!$B$90:$D$90,1,MATCH(言語切替!$B$3,_ゴミ箱_Backup!$B$1:$D$1,0)))))) | Q14: =IF(E14="","",IFERROR(_xlfn.TRANSLATE(E14,,"ja"),"")) | R14: =IF(E14="","",IFERROR(_xlfn.TRANSLATE(E14,,"zh-Hans"),"")) | S14: =IF(E14="","",IFERROR(_xlfn.TRANSLATE(E14,,"vi"),"")) | T14: =IF(P14="","",IFERROR(_xlfn.TRANSLATE(P14,,"ja"),"")) | U14: =IF(P14="","",IFERROR(_xlfn.TRANSLATE(P14,,"zh-Hans"),"")) | V14: =IF(P14="","",IFERROR(_xlfn.TRANSLATE(P14,,"vi"),""))
K15: =IF(OR(G15="",H15=""),"",IF(J15<>"",1,IF(I15="",0,MAX(0,MIN(1,(TODAY()-G15)/(H15-G15+1)))))) | M15: =IF(H15="","",H15-TODAY()) | N15: =IF(H15="","",IF(J15<>"",INDEX(_ゴミ箱_Backup!$B$75:$D$75,1,MATCH(言語切替!$B$3,_ゴミ箱_Backup!$B$1:$D$1,0)),IF(TODAY()>H15,INDEX(_ゴミ箱_Backup!$B$92:$D$92,1,MATCH(言語切替!$B$3,_ゴミ箱_Backup!$B$1:$D$1,0)),IF(H15-TODAY()<=7,INDEX(_ゴミ箱_Backup!$B$91:$D$91,1,MATCH(言語切替!$B$3,_ゴミ箱_Backup!$B$1:$D$1,0)),INDEX(_ゴミ箱_Backup!$B$90:$D$90,1,MATCH(言語切替!$B$3,_ゴミ箱_Backup!$B$1:$D$1,0)))))) | Q15: =IF(E15="","",IFERROR(_xlfn.TRANSLATE(E15,,"ja"),"")) | R15: =IF(E15="","",IFERROR(_xlfn.TRANSLATE(E15,,"zh-Hans"),"")) | S15: =IF(E15="","",IFERROR(_xlfn.TRANSLATE(E15,,"vi"),"")) | T15: =IF(P15="","",IFERROR(_xlfn.TRANSLATE(P15,,"ja"),"")) | U15: =IF(P15="","",IFERROR(_xlfn.TRANSLATE(P15,,"zh-Hans"),"")) | V15: =IF(P15="","",IFERROR(_xlfn.TRANSLATE(P15,,"vi"),""))
K16: =IF(OR(G16="",H16=""),"",IF(J16<>"",1,IF(I16="",0,MAX(0,MIN(1,(TODAY()-G16)/(H16-G16+1)))))) | M16: =IF(H16="","",H16-TODAY()) | N16: =IF(H16="","",IF(J16<>"",INDEX(_ゴミ箱_Backup!$B$75:$D$75,1,MATCH(言語切替!$B$3,_ゴミ箱_Backup!$B$1:$D$1,0)),IF(TODAY()>H16,INDEX(_ゴミ箱_Backup!$B$92:$D$92,1,MATCH(言語切替!$B$3,_ゴミ箱_Backup!$B$1:$D$1,0)),IF(H16-TODAY()<=7,INDEX(_ゴミ箱_Backup!$B$91:$D$91,1,MATCH(言語切替!$B$3,_ゴミ箱_Backup!$B$1:$D$1,0)),INDEX(_ゴミ箱_Backup!$B$90:$D$90,1,MATCH(言語切替!$B$3,_ゴミ箱_Backup!$B$1:$D$1,0)))))) | Q16: =IF(E16="","",IFERROR(_xlfn.TRANSLATE(E16,,"ja"),"")) | R16: =IF(E16="","",IFERROR(_xlfn.TRANSLATE(E16,,"zh-Hans"),"")) | S16: =IF(E16="","",IFERROR(_xlfn.TRANSLATE(E16,,"vi"),"")) | T16: =IF(P16="","",IFERROR(_xlfn.TRANSLATE(P16,,"ja"),"")) | U16: =IF(P16="","",IFERROR(_xlfn.TRANSLATE(P16,,"zh-Hans"),"")) | V16: =IF(P16="","",IFERROR(_xlfn.TRANSLATE(P16,,"vi"),""))
K17: =IF(OR(G17="",H17=""),"",IF(J17<>"",1,IF(I17="",0,MAX(0,MIN(1,(TODAY()-G17)/(H17-G17+1)))))) | M17: =IF(H17="","",H17-TODAY()) | N17: =IF(H17="","",IF(J17<>"",INDEX(_ゴミ箱_Backup!$B$75:$D$75,1,MATCH(言語切替!$B$3,_ゴミ箱_Backup!$B$1:$D$1,0)),IF(TODAY()>H17,INDEX(_ゴミ箱_Backup!$B$92:$D$92,1,MATCH(言語切替!$B$3,_ゴミ箱_Backup!$B$1:$D$1,0)),IF(H17-TODAY()<=7,INDEX(_ゴミ箱_Backup!$B$91:$D$91,1,MATCH(言語切替!$B$3,_ゴミ箱_Backup!$B$1:$D$1,0)),INDEX(_ゴミ箱_Backup!$B$90:$D$90,1,MATCH(言語切替!$B$3,_ゴミ箱_Backup!$B$1:$D$1,0)))))) | Q17: =IF(E17="","",IFERROR(_xlfn.TRANSLATE(E17,,"ja"),"")) | R17: =IF(E17="","",IFERROR(_xlfn.TRANSLATE(E17,,"zh-Hans"),"")) | S17: =IF(E17="","",IFERROR(_xlfn.TRANSLATE(E17,,"vi"),"")) | T17: =IF(P17="","",IFERROR(_xlfn.TRANSLATE(P17,,"ja"),"")) | U17: =IF(P17="","",IFERROR(_xlfn.TRANSLATE(P17,,"zh-Hans"),"")) | V17: =IF(P17="","",IFERROR(_xlfn.TRANSLATE(P17,,"vi"),""))
K18: =IF(OR(G18="",H18=""),"",IF(J18<>"",1,IF(I18="",0,MAX(0,MIN(1,(TODAY()-G18)/(H18-G18+1)))))) | M18: =IF(H18="","",H18-TODAY()) | N18: =IF(H18="","",IF(J18<>"",INDEX(_ゴミ箱_Backup!$B$75:$D$75,1,MATCH(言語切替!$B$3,_ゴミ箱_Backup!$B$1:$D$1,0)),IF(TODAY()>H18,INDEX(_ゴミ箱_Backup!$B$92:$D$92,1,MATCH(言語切替!$B$3,_ゴミ箱_Backup!$B$1:$D$1,0)),IF(H18-TODAY()<=7,INDEX(_ゴミ箱_Backup!$B$91:$D$91,1,MATCH(言語切替!$B$3,_ゴミ箱_Backup!$B$1:$D$1,0)),INDEX(_ゴミ箱_Backup!$B$90:$D$90,1,MATCH(言語切替!$B$3,_ゴミ箱_Backup!$B$1:$D$1,0)))))) | Q18: =IF(E18="","",IFERROR(_xlfn.TRANSLATE(E18,,"ja"),"")) | R18: =IF(E18="","",IFERROR(_xlfn.TRANSLATE(E18,,"zh-Hans"),"")) | S18: =IF(E18="","",IFERROR(_xlfn.TRANSLATE(E18,,"vi"),"")) | T18: =IF(P18="","",IFERROR(_xlfn.TRANSLATE(P18,,"ja"),"")) | U18: =IF(P18="","",IFERROR(_xlfn.TRANSLATE(P18,,"zh-Hans"),"")) | V18: =IF(P18="","",IFERROR(_xlfn.TRANSLATE(P18,,"vi"),""))
K19: =IF(OR(G19="",H19=""),"",IF(J19<>"",1,IF(I19="",0,MAX(0,MIN(1,(TODAY()-G19)/(H19-G19+1)))))) | M19: =IF(H19="","",H19-TODAY()) | N19: =IF(H19="","",IF(J19<>"",INDEX(_ゴミ箱_Backup!$B$75:$D$75,1,MATCH(言語切替!$B$3,_ゴミ箱_Backup!$B$1:$D$1,0)),IF(TODAY()>H19,INDEX(_ゴミ箱_Backup!$B$92:$D$92,1,MATCH(言語切替!$B$3,_ゴミ箱_Backup!$B$1:$D$1,0)),IF(H19-TODAY()<=7,INDEX(_ゴミ箱_Backup!$B$91:$D$91,1,MATCH(言語切替!$B$3,_ゴミ箱_Backup!$B$1:$D$1,0)),INDEX(_ゴミ箱_Backup!$B$90:$D$90,1,MATCH(言語切替!$B$3,_ゴミ箱_Backup!$B$1:$D$1,0)))))) | Q19: =IF(E19="","",IFERROR(_xlfn.TRANSLATE(E19,,"ja"),"")) | R19: =IF(E19="","",IFERROR(_xlfn.TRANSLATE(E19,,"zh-Hans"),"")) | S19: =IF(E19="","",IFERROR(_xlfn.TRANSLATE(E19,,"vi"),"")) | T19: =IF(P19="","",IFERROR(_xlfn.TRANSLATE(P19,,"ja"),"")) | U19: =IF(P19="","",IFERROR(_xlfn.TRANSLATE(P19,,"zh-Hans"),"")) | V19: =IF(P19="","",IFERROR(_xlfn.TRANSLATE(P19,,"vi"),""))
... K204: =IF(OR(G204="",H204=""),"",IF(J204<>"",1,IF(I204="",0,MAX(0,MIN(1,(TODAY()-G204)/(H204-G204+1)))))) | M204: =IF(H204="","",H204-TODAY()) | N204: =IF(H204="","",IF(J204<>"",INDEX(_ゴミ箱_Backup!$B$75:$D$75,1,MATCH(言語切替!$B$3,_ゴミ箱_Backup!$B$1:$D$1,0)),IF(TODAY()>H204,INDEX(_ゴミ箱_Backup!$B$92:$D$92,1,MATCH(言語切替!$B$3,_ゴミ箱_Backup!$B$1:$D$1,0)),IF(H204-TODAY()<=7,INDEX(_ゴミ箱_Backup!$B$91:$D$91,1,MATCH(言語切替!$B$3,_ゴミ箱_Backup!$B$1:$D$1,0)),INDEX(_ゴミ箱_Backup!$B$90:$D$90,1,MATCH(言語切替!$B$3,_ゴミ箱_Backup!$B$1:$D$1,0)))))) | Q204: =IF(E204="","",IFERROR(_xlfn.TRANSLATE(E204,,"ja"),"")) | R204: =IF(E204="","",IFERROR(_xlfn.TRANSLATE(E204,,"zh-Hans"),"")) | S204: =IF(E204="","",IFERROR(_xlfn.TRANSLATE(E204,,"vi"),"")) | T204: =IF(P204="","",IFERROR(_xlfn.TRANSLATE(P204,,"ja"),"")) | U204: =IF(P204="","",IFERROR(_xlfn.TRANSLATE(P204,,"zh-Hans"),"")) | V204: =IF(P204="","",IFERROR(_xlfn.TRANSLATE(P204,,"vi"),""))

Sheet 04_課題ToDo
A1: =INDEX(_ゴミ箱_Backup!$B$117:$D$247,MATCH("ISSUE_TITLE",_ゴミ箱_Backup!$A$117:$A$247,0),MATCH(言語切替!$B$3,_ゴミ箱_Backup!$B$1:$D$1,0)) -> #N/A
A2: =INDEX(_ゴミ箱_Backup!$B$117:$D$247,MATCH("ISSUE_DESC",_ゴミ箱_Backup!$A$117:$A$247,0),MATCH(言語切替!$B$3,_ゴミ箱_Backup!$B$1:$D$1,0)) -> #N/A
A3: =INDEX([1]_翻訳マスタ!$B$2:$D$300,MATCH("PARA_HOWTO",[1]_翻訳マスタ!$A$2:$A$300,0),MATCH(言語切替!$B$3,[1]_翻訳マスタ!$B$1:$D$1,0)) -> #N/A
A4: =INDEX(_ゴミ箱_Backup!$B$117:$D$247,MATCH("ISSUE_COL_ID",_ゴミ箱_Backup!$A$117:$A$247,0),MATCH(言語切替!$B$3,_ゴミ箱_Backup!$B$1:$D$1,0)) -> #N/A | B4: =INDEX(_ゴミ箱_Backup!$B$117:$D$247,MATCH("ISSUE_COL_TYPE",_ゴミ箱_Backup!$A$117:$A$247,0),MATCH(言語切替!$B$3,_ゴミ箱_Backup!$B$1:$D$1,0)) -> #N/A | C4: =INDEX(_ゴミ箱_Backup!$B$117:$D$247,MATCH("ISSUE_COL_WG",_ゴミ箱_Backup!$A$117:$A$247,0),MATCH(言語切替!$B$3,_ゴミ箱_Backup!$B$1:$D$1,0)) -> #N/A | D4: =INDEX(_ゴミ箱_Backup!$B$117:$D$247,MATCH("ISSUE_COL_SITE",_ゴミ箱_Backup!$A$117:$A$247,0),MATCH(言語切替!$B$3,_ゴミ箱_Backup!$B$1:$D$1,0)) -> #N/A | E4: =INDEX(_ゴミ箱_Backup!$B$117:$D$247,MATCH("ISSUE_COL_TITLE",_ゴミ箱_Backup!$A$117:$A$247,0),MATCH(言語切替!$B$3,_ゴミ箱_Backup!$B$1:$D$1,0)) -> #N/A | F4: =INDEX(_ゴミ箱_Backup!$B$117:$D$247,MATCH("ISSUE_COL_BG",_ゴミ箱_Backup!$A$117:$A$247,0),MATCH(言語切替!$B$3,_ゴミ箱_Backup!$B$1:$D$1,0)) -> #N/A | G4: =INDEX(_ゴミ箱_Backup!$B$117:$D$247,MATCH("ISSUE_COL_ACTION",_ゴミ箱_Backup!$A$117:$A$247,0),MATCH(言語切替!$B$3,_ゴミ箱_Backup!$B$1:$D$1,0)) -> #N/A | H4: =INDEX(_ゴミ箱_Backup!$B$117:$D$247,MATCH("ISSUE_COL_OWNER",_ゴミ箱_Backup!$A$117:$A$247,0),MATCH(言語切替!$B$3,_ゴミ箱_Backup!$B$1:$D$1,0)) -> #N/A | I4: =INDEX(_ゴミ箱_Backup!$B$117:$D$247,MATCH("ISSUE_COL_COOP",_ゴミ箱_Backup!$A$117:$A$247,0),MATCH(言語切替!$B$3,_ゴミ箱_Backup!$B$1:$D$1,0)) -> #N/A | J4: =INDEX(_ゴミ箱_Backup!$B$117:$D$247,MATCH("ISSUE_COL_START",_ゴミ箱_Backup!$A$117:$A$247,0),MATCH(言語切替!$B$3,_ゴミ箱_Backup!$B$1:$D$1,0)) -> #N/A | K4: =INDEX(_ゴミ箱_Backup!$B$117:$D$247,MATCH("ISSUE_COL_DUE",_ゴミ箱_Backup!$A$117:$A$247,0),MATCH(言語切替!$B$3,_ゴミ箱_Backup!$B$1:$D$1,0)) -> #N/A | L4: =INDEX(_ゴミ箱_Backup!$B$117:$D$247,MATCH("ISSUE_COL_PRIORITY",_ゴミ箱_Backup!$A$117:$A$247,0),MATCH(言語切替!$B$3,_ゴミ箱_Backup!$B$1:$D$1,0)) -> #N/A | M4: =INDEX(_ゴミ箱_Backup!$B$117:$D$247,MATCH("ISSUE_COL_STATUS",_ゴミ箱_Backup!$A$117:$A$247,0),MATCH(言語切替!$B$3,_ゴミ箱_Backup!$B$1:$D$1,0)) -> #N/A | N4: =INDEX(_ゴミ箱_Backup!$B$117:$D$247,MATCH("ISSUE_COL_DEP",_ゴミ箱_Backup!$A$117:$A$247,0),MATCH(言語切替!$B$3,_ゴミ箱_Backup!$B$1:$D$1,0)) -> #N/A | O4: =INDEX(_ゴミ箱_Backup!$B$117:$D$247,MATCH("ISSUE_COL_COND",_ゴミ箱_Backup!$A$117:$A$247,0),MATCH(言語切替!$B$3,_ゴミ箱_Backup!$B$1:$D$1,0)) -> #N/A | P4: =INDEX(_ゴミ箱_Backup!$B$117:$D$247,MATCH("ISSUE_COL_RESULT",_ゴミ箱_Backup!$A$117:$A$247,0),MATCH(言語切替!$B$3,_ゴミ箱_Backup!$B$1:$D$1,0)) -> #N/A | Q4: =INDEX(_ゴミ箱_Backup!$B$117:$D$247,MATCH("ISSUE_COL_LINK",_ゴミ箱_Backup!$A$117:$A$247,0),MATCH(言語切替!$B$3,_ゴミ箱_Backup!$B$1:$D$1,0)) -> #N/A | R4: =INDEX(_ゴミ箱_Backup!$B$117:$D$247,MATCH("ISSUE_COL_DAYS",_ゴミ箱_Backup!$A$117:$A$247,0),MATCH(言語切替!$B$3,_ゴミ箱_Backup!$B$1:$D$1,0)) -> #N/A | S4: =INDEX(_ゴミ箱_Backup!$B$117:$D$247,MATCH("ISSUE_COL_ALERT",_ゴミ箱_Backup!$A$117:$A$247,0),MATCH(言語切替!$B$3,_ゴミ箱_Backup!$B$1:$D$1,0)) -> #N/A | T4: =INDEX(_ゴミ箱_Backup!$B$117:$D$247,MATCH("ISSUE_COL_UPDATED",_ゴミ箱_Backup!$A$117:$A$247,0),MATCH(言語切替!$B$3,_ゴミ箱_Backup!$B$1:$D$1,0)) -> #N/A | U4: =INDEX(_ゴミ箱_Backup!$B$2:$D$300,MATCH("ISSUE_COL_TITLE",_ゴミ箱_Backup!$A$2:$A$300,0),MATCH(言語切替!$B$3,_ゴミ箱_Backup!$B$1:$D$1,0))&INDEX(_ゴミ箱_Backup!$B$2:$D$300,MATCH("NEW_JP_SUFFIX",_ゴミ箱_Backup!$A$2:$A$300,0),MATCH(言語切替!$B$3,_ゴミ箱_Backup!$B$1:$D$1,0)) -> #N/A | V4: =INDEX(_ゴミ箱_Backup!$B$2:$D$300,MATCH("ISSUE_COL_TITLE",_ゴミ箱_Backup!$A$2:$A$300,0),MATCH(言語切替!$B$3,_ゴミ箱_Backup!$B$1:$D$1,0))&INDEX(_ゴミ箱_Backup!$B$2:$D$300,MATCH("NEW_CN_SUFFIX",_ゴミ箱_Backup!$A$2:$A$300,0),MATCH(言語切替!$B$3,_ゴミ箱_Backup!$B$1:$D$1,0)) -> #N/A | W4: =INDEX(_ゴミ箱_Backup!$B$2:$D$300,MATCH("ISSUE_COL_TITLE",_ゴミ箱_Backup!$A$2:$A$300,0),MATCH(言語切替!$B$3,_ゴミ箱_Backup!$B$1:$D$1,0))&INDEX(_ゴミ箱_Backup!$B$2:$D$300,MATCH("NEW_VI_SUFFIX",_ゴミ箱_Backup!$A$2:$A$300,0),MATCH(言語切替!$B$3,_ゴミ箱_Backup!$B$1:$D$1,0)) -> #N/A | X4: =INDEX(_ゴミ箱_Backup!$B$2:$D$300,MATCH("ISSUE_COL_BG",_ゴミ箱_Backup!$A$2:$A$300,0),MATCH(言語切替!$B$3,_ゴミ箱_Backup!$B$1:$D$1,0))&INDEX(_ゴミ箱_Backup!$B$2:$D$300,MATCH("NEW_JP_SUFFIX",_ゴミ箱_Backup!$A$2:$A$300,0),MATCH(言語切替!$B$3,_ゴミ箱_Backup!$B$1:$D$1,0)) -> #N/A | Y4: =INDEX(_ゴミ箱_Backup!$B$2:$D$300,MATCH("ISSUE_COL_BG",_ゴミ箱_Backup!$A$2:$A$300,0),MATCH(言語切替!$B$3,_ゴミ箱_Backup!$B$1:$D$1,0))&INDEX(_ゴミ箱_Backup!$B$2:$D$300,MATCH("NEW_CN_SUFFIX",_ゴミ箱_Backup!$A$2:$A$300,0),MATCH(言語切替!$B$3,_ゴミ箱_Backup!$B$1:$D$1,0)) -> #N/A | Z4: =INDEX(_ゴミ箱_Backup!$B$2:$D$300,MATCH("ISSUE_COL_BG",_ゴミ箱_Backup!$A$2:$A$300,0),MATCH(言語切替!$B$3,_ゴミ箱_Backup!$B$1:$D$1,0))&INDEX(_ゴミ箱_Backup!$B$2:$D$300,MATCH("NEW_VI_SUFFIX",_ゴミ箱_Backup!$A$2:$A$300,0),MATCH(言語切替!$B$3,_ゴミ箱_Backup!$B$1:$D$1,0)) -> #N/A | AA4: =INDEX(_ゴミ箱_Backup!$B$2:$D$300,MATCH("ISSUE_COL_ACTION",_ゴミ箱_Backup!$A$2:$A$300,0),MATCH(言語切替!$B$3,_ゴミ箱_Backup!$B$1:$D$1,0))&INDEX(_ゴミ箱_Backup!$B$2:$D$300,MATCH("NEW_JP_SUFFIX",_ゴミ箱_Backup!$A$2:$A$300,0),MATCH(言語切替!$B$3,_ゴミ箱_Backup!$B$1:$D$1,0)) -> #N/A | AB4: =INDEX(_ゴミ箱_Backup!$B$2:$D$300,MATCH("ISSUE_COL_ACTION",_ゴミ箱_Backup!$A$2:$A$300,0),MATCH(言語切替!$B$3,_ゴミ箱_Backup!$B$1:$D$1,0))&INDEX(_ゴミ箱_Backup!$B$2:$D$300,MATCH("NEW_CN_SUFFIX",_ゴミ箱_Backup!$A$2:$A$300,0),MATCH(言語切替!$B$3,_ゴミ箱_Backup!$B$1:$D$1,0)) -> #N/A | AC4: =INDEX(_ゴミ箱_Backup!$B$2:$D$300,MATCH("ISSUE_COL_ACTION",_ゴミ箱_Backup!$A$2:$A$300,0),MATCH(言語切替!$B$3,_ゴミ箱_Backup!$B$1:$D$1,0))&INDEX(_ゴミ箱_Backup!$B$2:$D$300,MATCH("NEW_VI_SUFFIX",_ゴミ箱_Backup!$A$2:$A$300,0),MATCH(言語切替!$B$3,_ゴミ箱_Backup!$B$1:$D$1,0)) -> #N/A | AD4: =INDEX(_ゴミ箱_Backup!$B$2:$D$300,MATCH("ISSUE_COL_COND",_ゴミ箱_Backup!$A$2:$A$300,0),MATCH(言語切替!$B$3,_ゴミ箱_Backup!$B$1:$D$1,0))&INDEX(_ゴミ箱_Backup!$B$2:$D$300,MATCH("NEW_JP_SUFFIX",_ゴミ箱_Backup!$A$2:$A$300,0),MATCH(言語切替!$B$3,_ゴミ箱_Backup!$B$1:$D$1,0)) -> #N/A | AE4: =INDEX(_ゴミ箱_Backup!$B$2:$D$300,MATCH("ISSUE_COL_COND",_ゴミ箱_Backup!$A$2:$A$300,0),MATCH(言語切替!$B$3,_ゴミ箱_Backup!$B$1:$D$1,0))&INDEX(_ゴミ箱_Backup!$B$2:$D$300,MATCH("NEW_CN_SUFFIX",_ゴミ箱_Backup!$A$2:$A$300,0),MATCH(言語切替!$B$3,_ゴミ箱_Backup!$B$1:$D$1,0)) -> #N/A | AF4: =INDEX(_ゴミ箱_Backup!$B$2:$D$300,MATCH("ISSUE_COL_COND",_ゴミ箱_Backup!$A$2:$A$300,0),MATCH(言語切替!$B$3,_ゴミ箱_Backup!$B$1:$D$1,0))&INDEX(_ゴミ箱_Backup!$B$2:$D$300,MATCH("NEW_VI_SUFFIX",_ゴミ箱_Backup!$A$2:$A$300,0),MATCH(言語切替!$B$3,_ゴミ箱_Backup!$B$1:$D$1,0)) -> #N/A | AG4: =INDEX(_ゴミ箱_Backup!$B$2:$D$300,MATCH("ISSUE_COL_RESULT",_ゴミ箱_Backup!$A$2:$A$300,0),MATCH(言語切替!$B$3,_ゴミ箱_Backup!$B$1:$D$1,0))&INDEX(_ゴミ箱_Backup!$B$2:$D$300,MATCH("NEW_JP_SUFFIX",_ゴミ箱_Backup!$A$2:$A$300,0),MATCH(言語切替!$B$3,_ゴミ箱_Backup!$B$1:$D$1,0)) -> #N/A | AH4: =INDEX(_ゴミ箱_Backup!$B$2:$D$300,MATCH("ISSUE_COL_RESULT",_ゴミ箱_Backup!$A$2:$A$300,0),MATCH(言語切替!$B$3,_ゴミ箱_Backup!$B$1:$D$1,0))&INDEX(_ゴミ箱_Backup!$B$2:$D$300,MATCH("NEW_CN_SUFFIX",_ゴミ箱_Backup!$A$2:$A$300,0),MATCH(言語切替!$B$3,_ゴミ箱_Backup!$B$1:$D$1,0)) -> #N/A | AI4: =INDEX(_ゴミ箱_Backup!$B$2:$D$300,MATCH("ISSUE_COL_RESULT",_ゴミ箱_Backup!$A$2:$A$300,0),MATCH(言語切替!$B$3,_ゴミ箱_Backup!$B$1:$D$1,0))&INDEX(_ゴミ箱_Backup!$B$2:$D$300,MATCH("NEW_VI_SUFFIX",_ゴミ箱_Backup!$A$2:$A$300,0),MATCH(言語切替!$B$3,_ゴミ箱_Backup!$B$1:$D$1,0)) -> #N/A
A5: IT-001 | B5: ='02_マスタ'!$I$6 -> #N/A | C5: ='02_マスタ'!$A$5 -> #N/A | D5: ='02_マスタ'!$C$5 -> #N/A | E5: =INDEX(_ゴミ箱_Backup!$B$117:$D$247,MATCH("ISSUE_EX1_TITLE",_ゴミ箱_Backup!$A$117:$A$247,0),MATCH(言語切替!$B$3,_ゴミ箱_Backup!$B$1:$D$1,0)) -> #N/A | F5: =INDEX(_ゴミ箱_Backup!$B$117:$D$247,MATCH("ISSUE_EX1_BG",_ゴミ箱_Backup!$A$117:$A$247,0),MATCH(言語切替!$B$3,_ゴミ箱_Backup!$B$1:$D$1,0)) -> #N/A | G5: =INDEX(_ゴミ箱_Backup!$B$117:$D$247,MATCH("ISSUE_EX1_ACT",_ゴミ箱_Backup!$A$117:$A$247,0),MATCH(言語切替!$B$3,_ゴミ箱_Backup!$B$1:$D$1,0)) -> #N/A | H5: =INDEX(_ゴミ箱_Backup!$B$117:$D$247,MATCH("ROLE_PMO",_ゴミ箱_Backup!$A$117:$A$247,0),MATCH(言語切替!$B$3,_ゴミ箱_Backup!$B$1:$D$1,0)) -> #N/A | I5: =INDEX(_ゴミ箱_Backup!$B$117:$D$247,MATCH("ROLE_ALL_LEADERS",_ゴミ箱_Backup!$A$117:$A$247,0),MATCH(言語切替!$B$3,_ゴミ箱_Backup!$B$1:$D$1,0)) -> #N/A | J5: 46288 | K5: 46295 | L5: High | M5: ='02_マスタ'!$E$6 -> #N/A | O5: =INDEX(_ゴミ箱_Backup!$B$117:$D$247,MATCH("ISSUE_EX1_COND",_ゴミ箱_Backup!$A$117:$A$247,0),MATCH(言語切替!$B$3,_ゴミ箱_Backup!$B$1:$D$1,0)) -> #N/A | R5: =IF(K5="","",K5-TODAY()) -> 1 | S5: =IF(A5="","",IF(OR(M5='02_マスタ'!$E$10,M5='02_マスタ'!$E$12),"",IF(L5="High","High",IF(AND(K5<>"",K5<TODAY()),INDEX(_ゴミ箱_Backup!$B$117:$D$247,MATCH("ALERT_OVERDUE",_ゴミ箱_Backup!$A$117:$A$247,0),MATCH(言語切替!$B$3,_ゴミ箱_Backup!$B$1:$D$1,0)),IF(AND(K5<>"",K5-TODAY()<=7),INDEX(_ゴミ箱_Backup!$B$117:$D$247,MATCH("ALERT_APPROACHING",_ゴミ箱_Backup!$A$117:$A$247,0),MATCH(言語切替!$B$3,_ゴミ箱_Backup!$B$1:$D$1,0)),IF(OR(M5='02_マスタ'!$E$7,M5='02_マスタ'!$E$8),INDEX(_ゴミ箱_Backup!$B$117:$D$247,MATCH("ALERT_CHECK",_ゴミ箱_Backup!$A$117:$A$247,0),MATCH(言語切替!$B$3,_ゴミ箱_Backup!$B$1:$D$1,0)),"")))))) -> #N/A | T5: 46288 | U5: =IF(E5="","",IFERROR(_xlfn.TRANSLATE(E5,,"ja"),"")) -> #N/A | V5: =IF(E5="","",IFERROR(_xlfn.TRANSLATE(E5,,"zh-Hans"),"")) -> #N/A | W5: =IF(E5="","",IFERROR(_xlfn.TRANSLATE(E5,,"vi"),"")) -> #N/A | X5: =IF(F5="","",IFERROR(_xlfn.TRANSLATE(F5,,"ja"),"")) -> #N/A | Y5: =IF(F5="","",IFERROR(_xlfn.TRANSLATE(F5,,"zh-Hans"),"")) -> #N/A | Z5: =IF(F5="","",IFERROR(_xlfn.TRANSLATE(F5,,"vi"),"")) -> #N/A | AA5: =IF(G5="","",IFERROR(_xlfn.TRANSLATE(G5,,"ja"),"")) -> #N/A | AB5: =IF(G5="","",IFERROR(_xlfn.TRANSLATE(G5,,"zh-Hans"),"")) -> #N/A | AC5: =IF(G5="","",IFERROR(_xlfn.TRANSLATE(G5,,"vi"),"")) -> #N/A | AD5: =IF(O5="","",IFERROR(_xlfn.TRANSLATE(O5,,"ja"),"")) -> #N/A | AE5: =IF(O5="","",IFERROR(_xlfn.TRANSLATE(O5,,"zh-Hans"),"")) -> #N/A | AF5: =IF(O5="","",IFERROR(_xlfn.TRANSLATE(O5,,"vi"),"")) -> #N/A | AG5: =IF(P5="","",IFERROR(_xlfn.TRANSLATE(P5,,"ja"),"")) | AH5: =IF(P5="","",IFERROR(_xlfn.TRANSLATE(P5,,"zh-Hans"),"")) | AI5: =IF(P5="","",IFERROR(_xlfn.TRANSLATE(P5,,"vi"),""))
A6: IS-001 | B6: ='02_マスタ'!$I$5 -> #N/A | C6: ='02_マスタ'!$A$9 -> #N/A | D6: ='02_マスタ'!$C$5 -> #N/A | E6: =INDEX(_ゴミ箱_Backup!$B$117:$D$247,MATCH("ISSUE_EX2_TITLE",_ゴミ箱_Backup!$A$117:$A$247,0),MATCH(言語切替!$B$3,_ゴミ箱_Backup!$B$1:$D$1,0)) -> #N/A | F6: =INDEX(_ゴミ箱_Backup!$B$117:$D$247,MATCH("ISSUE_EX2_BG",_ゴミ箱_Backup!$A$117:$A$247,0),MATCH(言語切替!$B$3,_ゴミ箱_Backup!$B$1:$D$1,0)) -> #N/A | G6: =INDEX(_ゴミ箱_Backup!$B$117:$D$247,MATCH("ISSUE_EX2_ACT",_ゴミ箱_Backup!$A$117:$A$247,0),MATCH(言語切替!$B$3,_ゴミ箱_Backup!$B$1:$D$1,0)) -> #N/A | H6: WG Leader | I6: WG-8 | J6: 46294 | K6: 46311 | L6: High | M6: ='02_マスタ'!$E$5 -> #N/A | N6: =INDEX(_ゴミ箱_Backup!$B$117:$D$247,MATCH("ISSUE_EX2_DEP",_ゴミ箱_Backup!$A$117:$A$247,0),MATCH(言語切替!$B$3,_ゴミ箱_Backup!$B$1:$D$1,0)) -> #N/A | O6: =INDEX(_ゴミ箱_Backup!$B$117:$D$247,MATCH("ISSUE_EX2_COND",_ゴミ箱_Backup!$A$117:$A$247,0),MATCH(言語切替!$B$3,_ゴミ箱_Backup!$B$1:$D$1,0)) -> #N/A | R6: =IF(K6="","",K6-TODAY()) -> 17 | S6: =IF(A6="","",IF(OR(M6='02_マスタ'!$E$10,M6='02_マスタ'!$E$12),"",IF(L6="High","High",IF(AND(K6<>"",K6<TODAY()),INDEX(_ゴミ箱_Backup!$B$117:$D$247,MATCH("ALERT_OVERDUE",_ゴミ箱_Backup!$A$117:$A$247,0),MATCH(言語切替!$B$3,_ゴミ箱_Backup!$B$1:$D$1,0)),IF(AND(K6<>"",K6-TODAY()<=7),INDEX(_ゴミ箱_Backup!$B$117:$D$247,MATCH("ALERT_APPROACHING",_ゴミ箱_Backup!$A$117:$A$247,0),MATCH(言語切替!$B$3,_ゴミ箱_Backup!$B$1:$D$1,0)),IF(OR(M6='02_マスタ'!$E$7,M6='02_マスタ'!$E$8),INDEX(_ゴミ箱_Backup!$B$117:$D$247,MATCH("ALERT_CHECK",_ゴミ箱_Backup!$A$117:$A$247,0),MATCH(言語切替!$B$3,_ゴミ箱_Backup!$B$1:$D$1,0)),"")))))) -> #N/A | T6: 46288 | U6: =IF(E6="","",IFERROR(_xlfn.TRANSLATE(E6,,"ja"),"")) -> #N/A | V6: =IF(E6="","",IFERROR(_xlfn.TRANSLATE(E6,,"zh-Hans"),"")) -> #N/A | W6: =IF(E6="","",IFERROR(_xlfn.TRANSLATE(E6,,"vi"),"")) -> #N/A | X6: =IF(F6="","",IFERROR(_xlfn.TRANSLATE(F6,,"ja"),"")) -> #N/A | Y6: =IF(F6="","",IFERROR(_xlfn.TRANSLATE(F6,,"zh-Hans"),"")) -> #N/A | Z6: =IF(F6="","",IFERROR(_xlfn.TRANSLATE(F6,,"vi"),"")) -> #N/A | AA6: =IF(G6="","",IFERROR(_xlfn.TRANSLATE(G6,,"ja"),"")) -> #N/A | AB6: =IF(G6="","",IFERROR(_xlfn.TRANSLATE(G6,,"zh-Hans"),"")) -> #N/A | AC6: =IF(G6="","",IFERROR(_xlfn.TRANSLATE(G6,,"vi"),"")) -> #N/A | AD6: =IF(O6="","",IFERROR(_xlfn.TRANSLATE(O6,,"ja"),"")) -> #N/A | AE6: =IF(O6="","",IFERROR(_xlfn.TRANSLATE(O6,,"zh-Hans"),"")) -> #N/A | AF6: =IF(O6="","",IFERROR(_xlfn.TRANSLATE(O6,,"vi"),"")) -> #N/A | AG6: =IF(P6="","",IFERROR(_xlfn.TRANSLATE(P6,,"ja"),"")) | AH6: =IF(P6="","",IFERROR(_xlfn.TRANSLATE(P6,,"zh-Hans"),"")) | AI6: =IF(P6="","",IFERROR(_xlfn.TRANSLATE(P6,,"vi"),""))
