Workbook

Sheet 言語切替
A1: 言語切替 / 语言切换 / Chuyển ngôn ngữ
A3: 表示言語 | B3: Tiếng Việt
A6: Language code / Ma ngon ngu (TRANSLATE, do not edit)
A7: 日本語 | B7: ja
A8: 中文 | B8: zh-Hans
A9: Tiếng Việt | B9: vi
A11: Auto-translate needs M365+internet. If #NAME?, use Copilot manual.

Sheet 00_運用ルール
A1: =INDEX(_翻訳マスタ!$B$2:$D$32,MATCH("TITLE",_翻訳マスタ!$A$2:$A$32,0),MATCH(言語切替!$B$3,_翻訳マスタ!$B$1:$D$1,0)) -> Công cụ quản lý Tiểu ban Nhà máy Thông minh
A2: =INDEX(_翻訳マスタ!$B$2:$D$32,MATCH("PURPOSE",_翻訳マスタ!$A$2:$A$32,0),MATCH(言語切替!$B$3,_翻訳マスタ!$B$1:$D$1,0)) -> Mục đích: Bản dự thảo đầu tiên nhằm quản lý kế hoạch, vấn đề, quyết định và KPI của 9 WG trong một chu trình quản lý thống nhất
A4: =INDEX(_翻訳マスタ!$B$2:$D$32,MATCH("PRINCIPLE_HEADER",_翻訳マスタ!$A$2:$A$32,0),MATCH(言語切替!$B$3,_翻訳マスタ!$B$1:$D$1,0)) -> 1. Nguyên tắc cơ bản | J4: =INDEX(_翻訳マスタ!$B$2:$D$32,MATCH("COL_SHEET",_翻訳マスタ!$A$2:$A$32,0),MATCH(言語切替!$B$3,_翻訳マスタ!$B$1:$D$1,0)) -> Trang tính | K4: =INDEX(_翻訳マスタ!$B$2:$D$32,MATCH("COL_USAGE",_翻訳マスタ!$A$2:$A$32,0),MATCH(言語切替!$B$3,_翻訳マスタ!$B$1:$D$1,0)) -> Mục đích sử dụng
A5: =INDEX(_翻訳マスタ!$B$2:$D$32,MATCH("P1",_翻訳マスタ!$A$2:$A$32,0),MATCH(言語切替!$B$3,_翻訳マスタ!$B$1:$D$1,0)) -> • Lưu các thảo luận chi tiết trong biên bản họp và tài liệu liên quan | J5: 01_全体サマリー | K5: =INDEX(_翻訳マスタ!$B$2:$D$32,MATCH("U1",_翻訳マスタ!$A$2:$A$32,0),MATCH(言語切替!$B$3,_翻訳マスタ!$B$1:$D$1,0)) -> Bảng điều khiển cho ban điều hành và cuộc họp trưởng nhóm
A6: =INDEX(_翻訳マスタ!$B$2:$D$32,MATCH("P2",_翻訳マスタ!$A$2:$A$32,0),MATCH(言語切替!$B$3,_翻訳マスタ!$B$1:$D$1,0)) -> • Trong tệp này, ghi lại kết luận, hành động tiếp theo, người phụ trách, thời hạn và liên kết | J6: 02_マスタ | K6: =INDEX(_翻訳マスタ!$B$2:$D$32,MATCH("U2",_翻訳マスタ!$A$2:$A$32,0),MATCH(言語切替!$B$3,_翻訳マスタ!$B$1:$D$1,0)) -> Danh sách lựa chọn nhập liệu và định nghĩa WG
A7: =INDEX(_翻訳マスタ!$B$2:$D$32,MATCH("P3",_翻訳マスタ!$A$2:$A$32,0),MATCH(言語切替!$B$3,_翻訳マスタ!$B$1:$D$1,0)) -> • Không nhập trùng cùng một nội dung trên nhiều trang tính | J7: 03_WBS | K7: =INDEX(_翻訳マスタ!$B$2:$D$32,MATCH("U3",_翻訳マスタ!$A$2:$A$32,0),MATCH(言語切替!$B$3,_翻訳マスタ!$B$1:$D$1,0)) -> Quản lý kế hoạch sản phẩm bàn giao và mốc tiến độ
A8: =INDEX(_翻訳マスタ!$B$2:$D$32,MATCH("P4",_翻訳マスタ!$A$2:$A$32,0),MATCH(言語切替!$B$3,_翻訳マスタ!$B$1:$D$1,0)) -> • Không xóa dòng; hãy ghi lại lý do thay đổi hoặc rút lại | J8: 04_課題ToDo | K8: =INDEX(_翻訳マスタ!$B$2:$D$32,MATCH("U4",_翻訳マスタ!$A$2:$A$32,0),MATCH(言語切替!$B$3,_翻訳マスタ!$B$1:$D$1,0)) -> Quản lý trở ngại, hành động và rủi ro
J9: 05_決定事項 | K9: =INDEX(_翻訳マスタ!$B$2:$D$32,MATCH("U5",_翻訳マスタ!$A$2:$A$32,0),MATCH(言語切替!$B$3,_翻訳マスタ!$B$1:$D$1,0)) -> Ghi lại lịch sử quyết định và phạm vi ảnh hưởng
A10: =INDEX(_翻訳マスタ!$B$2:$D$32,MATCH("RESP_HEADER",_翻訳マスタ!$A$2:$A$32,0),MATCH(言語切替!$B$3,_翻訳マスタ!$B$1:$D$1,0)) -> 2. Trách nhiệm cập nhật | J10: 06_KPI | K10: =INDEX(_翻訳マスタ!$B$2:$D$32,MATCH("U6",_翻訳マスタ!$A$2:$A$32,0),MATCH(言語切替!$B$3,_翻訳マスタ!$B$1:$D$1,0)) -> Định nghĩa KPI, giá trị cơ sở, mục tiêu và thực tế
A11: =INDEX(_翻訳マスタ!$B$2:$D$32,MATCH("R1",_翻訳マスタ!$A$2:$A$32,0),MATCH(言語切替!$B$3,_翻訳マスタ!$B$1:$D$1,0)) -> • Trưởng WG: Cập nhật WBS, vấn đề và KPI sau cuộc họp WG | J11: 07_更新履歴 | K11: =INDEX(_翻訳マスタ!$B$2:$D$32,MATCH("U7",_翻訳マスタ!$A$2:$A$32,0),MATCH(言語切替!$B$3,_翻訳マスタ!$B$1:$D$1,0)) -> Ghi lại các thay đổi quan trọng
A12: =INDEX(_翻訳マスタ!$B$2:$D$32,MATCH("R2",_翻訳マスタ!$A$2:$A$32,0),MATCH(言語切替!$B$3,_翻訳マスタ!$B$1:$D$1,0)) -> • Ban điều hành: Hàng tuần rà soát các mục chưa cập nhật, quá hạn, mức High và phụ thuộc giữa các WG
A13: =INDEX(_翻訳マスタ!$B$2:$D$32,MATCH("R3",_翻訳マスタ!$A$2:$A$32,0),MATCH(言語切替!$B$3,_翻訳マスタ!$B$1:$D$1,0)) -> • Người xác nhận hoàn thành: Kiểm tra sản phẩm bàn giao hoặc kết quả xử lý và phê duyệt hoàn thành
A14: =INDEX(_翻訳マスタ!$B$2:$D$32,MATCH("R4",_翻訳マスタ!$A$2:$A$32,0),MATCH(言語切替!$B$3,_翻訳マスタ!$B$1:$D$1,0)) -> • Trưởng tiểu ban / Phó trưởng đơn vị: Quyết định các vấn đề quan trọng
A16: =INDEX(_翻訳マスタ!$B$2:$D$32,MATCH("CYCLE_HEADER",_翻訳マスタ!$A$2:$A$32,0),MATCH(言語切替!$B$3,_翻訳マスタ!$B$1:$D$1,0)) -> 3. Chu trình hàng tuần
A17: =INDEX(_翻訳マスタ!$B$2:$D$32,MATCH("C1",_翻訳マスタ!$A$2:$A$32,0),MATCH(言語切替!$B$3,_翻訳マスタ!$B$1:$D$1,0)) -> • Sau hoạt động WG: Đăng ký vấn đề mới, quyết định và hành động tiếp theo
A18: =INDEX(_翻訳マスタ!$B$2:$D$32,MATCH("C2",_翻訳マスタ!$A$2:$A$32,0),MATCH(言語切替!$B$3,_翻訳マスタ!$B$1:$D$1,0)) -> • Trước cuộc họp trưởng nhóm: Ban điều hành trích xuất các cảnh báo
A19: =INDEX(_翻訳マスタ!$B$2:$D$32,MATCH("C3",_翻訳マスタ!$A$2:$A$32,0),MATCH(言語切替!$B$3,_翻訳マスタ!$B$1:$D$1,0)) -> • Họp trưởng nhóm hàng tuần: Tập trung thảo luận các mục chờ quyết định, vấn đề liên WG và chậm tiến độ
A20: =INDEX(_翻訳マスタ!$B$2:$D$32,MATCH("C4",_翻訳マスタ!$A$2:$A$32,0),MATCH(言語切替!$B$3,_翻訳マスタ!$B$1:$D$1,0)) -> • Sau cuộc họp: Cập nhật quyết định, người phụ trách và thời hạn
A22: =INDEX(_翻訳マスタ!$B$2:$D$32,MATCH("ESC_HEADER",_翻訳マスタ!$A$2:$A$32,0),MATCH(言語切替!$B$3,_翻訳マスタ!$B$1:$D$1,0)) -> 4. Điều kiện báo cáo cấp trên
A23: =INDEX(_翻訳マスタ!$B$2:$D$32,MATCH("E1",_翻訳マスタ!$A$2:$A$32,0),MATCH(言語切替!$B$3,_翻訳マスタ!$B$1:$D$1,0)) -> • Mức ưu tiên High
A24: =INDEX(_翻訳マスタ!$B$2:$D$32,MATCH("E2",_翻訳マスタ!$A$2:$A$32,0),MATCH(言語切替!$B$3,_翻訳マスタ!$B$1:$D$1,0)) -> • Đã quá hạn hoặc có khả năng quá hạn
A25: =INDEX(_翻訳マスタ!$B$2:$D$32,MATCH("E3",_翻訳マスタ!$A$2:$A$32,0),MATCH(言語切替!$B$3,_翻訳マスタ!$B$1:$D$1,0)) -> • Ảnh hưởng đến nhiều WG hoặc nhiều đơn vị
A26: =INDEX(_翻訳マスタ!$B$2:$D$32,MATCH("E4",_翻訳マスタ!$A$2:$A$32,0),MATCH(言語切替!$B$3,_翻訳マスタ!$B$1:$D$1,0)) -> • Cần thay đổi phạm vi, đầu tư, nhân sự hoặc quyết định cấp cao hơn
A27: =INDEX(_翻訳マスタ!$B$2:$D$300,MATCH("PARA_TITLE",_翻訳マスタ!$A$2:$A$300,0),MATCH(言語切替!$B$3,_翻訳マスタ!$B$1:$D$1,0)) -> 5. Quy tắc dịch song song (nội dung mới)
A28: =INDEX(_翻訳マスタ!$B$2:$D$300,MATCH("PARA_DESC",_翻訳マスタ!$A$2:$A$300,0),MATCH(言語切替!$B$3,_翻訳マスタ!$B$1:$D$1,0)) -> Cột tiếng Việt nhập liệu bình thường. Các cột JP/CN kề cạnh tự động dịch bằng hàm TRANSLATE (cần M365 + mạng).
A29: =INDEX(_翻訳マスタ!$B$2:$D$300,MATCH("PARA_HOWTO",_翻訳マスタ!$A$2:$A$300,0),MATCH(言語切替!$B$3,_翻訳マスタ!$B$1:$D$1,0)) -> Cách dùng: Nhập tiếng mẹ đẻ → đọc cột khác → ô trống không dịch → dưới 3000 ký tự
A30: =INDEX(_翻訳マスタ!$B$2:$D$300,MATCH("BACKUP_TITLE",_翻訳マスタ!$A$2:$A$300,0),MATCH(言語切替!$B$3,_翻訳マスタ!$B$1:$D$1,0)) -> 6. Chống xóa & sao lưu
A31: =INDEX(_翻訳マスタ!$B$2:$D$300,MATCH("BACKUP_DESC",_翻訳マスタ!$A$2:$A$300,0),MATCH(言語切替!$B$3,_翻訳マスタ!$B$1:$D$1,0)) -> Cấm xóa dòng vật lý. Chuyển sang "Rút lại" và sao chép sang _ゴミ箱_Backup. Bật Version History 500 bản trên SharePoint, hàng tuần lưu riêng.

Sheet 01_全体サマリー
A1: =INDEX(_翻訳マスタ!$B$33:$D$45,MATCH("DASH_TITLE",_翻訳マスタ!$A$33:$A$45,0),MATCH(言語切替!$B$3,_翻訳マスタ!$B$1:$D$1,0)) -> Tổng quan
A2: =INDEX(_翻訳マスタ!$B$33:$D$45,MATCH("DASH_DESC",_翻訳マスタ!$A$33:$A$45,0),MATCH(言語切替!$B$3,_翻訳マスタ!$B$1:$D$1,0)) -> Dùng cho ban điều hành và cuộc họp trưởng WG hàng tuần. Không cần nhập liệu; thông tin WBS, Vấn đề/ToDo và KPI được tự động tổng hợp.
B4: =INDEX(_翻訳マスタ!$B$33:$D$45,MATCH("DASH_OPEN_WBS",_翻訳マスタ!$A$33:$A$45,0),MATCH(言語切替!$B$3,_翻訳マスタ!$B$1:$D$1,0)) -> WBS chưa hoàn thành | D4: =INDEX(_翻訳マスタ!$B$33:$D$45,MATCH("DASH_DELAY_WBS",_翻訳マスタ!$A$33:$A$45,0),MATCH(言語切替!$B$3,_翻訳マスタ!$B$1:$D$1,0)) -> WBS chậm tiến độ | F4: =INDEX(_翻訳マスタ!$B$33:$D$45,MATCH("DASH_OPEN_ISSUES",_翻訳マスタ!$A$33:$A$45,0),MATCH(言語切替!$B$3,_翻訳マスタ!$B$1:$D$1,0)) -> Vấn đề/ToDo chưa hoàn thành | H4: =INDEX(_翻訳マスタ!$B$33:$D$45,MATCH("DASH_HIGH_OVERDUE",_翻訳マスタ!$A$33:$A$45,0),MATCH(言語切替!$B$3,_翻訳マスタ!$B$1:$D$1,0)) -> High / Quá hạn | J4: =INDEX(_翻訳マスタ!$B$33:$D$45,MATCH("DASH_KPI_MISS",_翻訳マスタ!$A$33:$A$45,0),MATCH(言語切替!$B$3,_翻訳マスタ!$B$1:$D$1,0)) -> KPI chưa đạt
B5: =COUNTIFS('03_WBS'!$A$5:$A$204,"<>",'03_WBS'!$N$5:$N$204,"<>"&INDEX(_翻訳マスタ!$B$75:$D$75,1,MATCH(言語切替!$B$3,_翻訳マスタ!$B$1:$D$1,0))) -> 3 | D5: =COUNTIF('03_WBS'!$P$5:$P$204,INDEX(_翻訳マスタ!$B$92:$D$92,1,MATCH(言語切替!$B$3,_翻訳マスタ!$B$1:$D$1,0))) -> 0 | F5: =COUNTIFS('04_課題ToDo'!$A$5:$A$304,"<>",'04_課題ToDo'!$S$5:$S$304,"<>"&INDEX(_翻訳マスタ!$B$75:$D$75,1,MATCH(言語切替!$B$3,_翻訳マスタ!$B$1:$D$1,0)),'04_課題ToDo'!$S$5:$S$304,"<>"&INDEX(_翻訳マスタ!$B$77:$D$77,1,MATCH(言語切替!$B$3,_翻訳マスタ!$B$1:$D$1,0))) -> 4 | H5: =COUNTIFS('04_課題ToDo'!$A$5:$A$304,"<>",'04_課題ToDo'!$AC$5:$AC$304,"High")+COUNTIFS('04_課題ToDo'!$A$5:$A$304,"<>",'04_課題ToDo'!$AC$5:$AC$304,INDEX(_翻訳マスタ!$B$117:$D$247,MATCH("ALERT_OVERDUE",_翻訳マスタ!$A$117:$A$247,0),MATCH(言語切替!$B$3,_翻訳マスタ!$B$1:$D$1,0))) -> 2 | J5: =COUNTIFS('06_KPI'!$A$5:$A$204,"<>",'06_KPI'!$U$5:$U$204,INDEX(_翻訳マスタ!$B$94:$D$94,1,MATCH(言語切替!$B$3,_翻訳マスタ!$B$1:$D$1,0))) -> 0
A9: =INDEX(_翻訳マスタ!$B$33:$D$45,MATCH("DASH_WG",_翻訳マスタ!$A$33:$A$45,0),MATCH(言語切替!$B$3,_翻訳マスタ!$B$1:$D$1,0)) -> WG | B9: =INDEX(_翻訳マスタ!$B$33:$D$45,MATCH("DASH_OPEN_WBS",_翻訳マスタ!$A$33:$A$45,0),MATCH(言語切替!$B$3,_翻訳マスタ!$B$1:$D$1,0)) -> WBS chưa hoàn thành | C9: =INDEX(_翻訳マスタ!$B$33:$D$45,MATCH("DASH_DELAY_WBS",_翻訳マスタ!$A$33:$A$45,0),MATCH(言語切替!$B$3,_翻訳マスタ!$B$1:$D$1,0)) -> WBS chậm tiến độ | D9: =INDEX(_翻訳マスタ!$B$33:$D$45,MATCH("DASH_OPEN_ISSUES_SHORT",_翻訳マスタ!$A$33:$A$45,0),MATCH(言語切替!$B$3,_翻訳マスタ!$B$1:$D$1,0)) -> Vấn đề chưa hoàn thành | E9: =INDEX(_翻訳マスタ!$B$33:$D$45,MATCH("DASH_HIGH_OVERDUE_SHORT",_翻訳マスタ!$A$33:$A$45,0),MATCH(言語切替!$B$3,_翻訳マスタ!$B$1:$D$1,0)) -> High/Quá hạn | F9: =INDEX(_翻訳マスタ!$B$33:$D$45,MATCH("DASH_WAITING",_翻訳マスタ!$A$33:$A$45,0),MATCH(言語切替!$B$3,_翻訳マスタ!$B$1:$D$1,0)) -> Chờ quyết định/WG khác | G9: =INDEX(_翻訳マスタ!$B$33:$D$45,MATCH("DASH_KPI_MISS",_翻訳マスタ!$A$33:$A$45,0),MATCH(言語切替!$B$3,_翻訳マスタ!$B$1:$D$1,0)) -> KPI chưa đạt
A10: ='02_マスタ'!$A$5 -> Toàn bộ | B10: =COUNTIFS('03_WBS'!$B$5:$B$204,$A10,'03_WBS'!$N$5:$N$204,"<>"&INDEX(_翻訳マスタ!$B$75:$D$75,1,MATCH(言語切替!$B$3,_翻訳マスタ!$B$1:$D$1,0))) -> 1 | C10: =COUNTIFS('03_WBS'!$B$5:$B$204,$A10,'03_WBS'!$P$5:$P$204,INDEX(_翻訳マスタ!$B$92:$D$92,1,MATCH(言語切替!$B$3,_翻訳マスタ!$B$1:$D$1,0))) -> 0 | D10: =COUNTIFS('04_課題ToDo'!$C$5:$C$304,$A10,'04_課題ToDo'!$S$5:$S$304,"<>"&INDEX(_翻訳マスタ!$B$75:$D$75,1,MATCH(言語切替!$B$3,_翻訳マスタ!$B$1:$D$1,0)),'04_課題ToDo'!$S$5:$S$304,"<>"&INDEX(_翻訳マスタ!$B$77:$D$77,1,MATCH(言語切替!$B$3,_翻訳マスタ!$B$1:$D$1,0))) -> 1 | E10: =COUNTIFS('04_課題ToDo'!$C$5:$C$304,$A10,'04_課題ToDo'!$AC$5:$AC$304,"High")+COUNTIFS('04_課題ToDo'!$C$5:$C$304,$A10,'04_課題ToDo'!$AC$5:$AC$304,INDEX(_翻訳マスタ!$B$117:$D$247,MATCH("ALERT_OVERDUE",_翻訳マスタ!$A$117:$A$247,0),MATCH(言語切替!$B$3,_翻訳マスタ!$B$1:$D$1,0))) -> 1 | F10: =COUNTIFS('04_課題ToDo'!$C$5:$C$304,$A10,'04_課題ToDo'!$S$5:$S$304,INDEX(_翻訳マスタ!$B$72:$D$72,1,MATCH(言語切替!$B$3,_翻訳マスタ!$B$1:$D$1,0)))+COUNTIFS('04_課題ToDo'!$C$5:$C$304,$A10,'04_課題ToDo'!$S$5:$S$304,INDEX(_翻訳マスタ!$B$73:$D$73,1,MATCH(言語切替!$B$3,_翻訳マスタ!$B$1:$D$1,0))) -> 0 | G10: =COUNTIFS('06_KPI'!$B$5:$B$204,$A10,'06_KPI'!$U$5:$U$204,INDEX(_翻訳マスタ!$B$94:$D$94,1,MATCH(言語切替!$B$3,_翻訳マスタ!$B$1:$D$1,0))) -> 0
A11: WG-1 | B11: =COUNTIFS('03_WBS'!$B$5:$B$204,$A11,'03_WBS'!$N$5:$N$204,"<>"&INDEX(_翻訳マスタ!$B$75:$D$75,1,MATCH(言語切替!$B$3,_翻訳マスタ!$B$1:$D$1,0))) -> 1 | C11: =COUNTIFS('03_WBS'!$B$5:$B$204,$A11,'03_WBS'!$P$5:$P$204,INDEX(_翻訳マスタ!$B$92:$D$92,1,MATCH(言語切替!$B$3,_翻訳マスタ!$B$1:$D$1,0))) -> 0 | D11: =COUNTIFS('04_課題ToDo'!$C$5:$C$304,$A11,'04_課題ToDo'!$S$5:$S$304,"<>"&INDEX(_翻訳マスタ!$B$75:$D$75,1,MATCH(言語切替!$B$3,_翻訳マスタ!$B$1:$D$1,0)),'04_課題ToDo'!$S$5:$S$304,"<>"&INDEX(_翻訳マスタ!$B$77:$D$77,1,MATCH(言語切替!$B$3,_翻訳マスタ!$B$1:$D$1,0))) -> 0 | E11: =COUNTIFS('04_課題ToDo'!$C$5:$C$304,$A11,'04_課題ToDo'!$AC$5:$AC$304,"High")+COUNTIFS('04_課題ToDo'!$C$5:$C$304,$A11,'04_課題ToDo'!$AC$5:$AC$304,INDEX(_翻訳マスタ!$B$117:$D$247,MATCH("ALERT_OVERDUE",_翻訳マスタ!$A$117:$A$247,0),MATCH(言語切替!$B$3,_翻訳マスタ!$B$1:$D$1,0))) -> 0 | F11: =COUNTIFS('04_課題ToDo'!$C$5:$C$304,$A11,'04_課題ToDo'!$S$5:$S$304,INDEX(_翻訳マスタ!$B$72:$D$72,1,MATCH(言語切替!$B$3,_翻訳マスタ!$B$1:$D$1,0)))+COUNTIFS('04_課題ToDo'!$C$5:$C$304,$A11,'04_課題ToDo'!$S$5:$S$304,INDEX(_翻訳マスタ!$B$73:$D$73,1,MATCH(言語切替!$B$3,_翻訳マスタ!$B$1:$D$1,0))) -> 0 | G11: =COUNTIFS('06_KPI'!$B$5:$B$204,$A11,'06_KPI'!$U$5:$U$204,INDEX(_翻訳マスタ!$B$94:$D$94,1,MATCH(言語切替!$B$3,_翻訳マスタ!$B$1:$D$1,0))) -> 0
A12: WG-2 | B12: =COUNTIFS('03_WBS'!$B$5:$B$204,$A12,'03_WBS'!$N$5:$N$204,"<>"&INDEX(_翻訳マスタ!$B$75:$D$75,1,MATCH(言語切替!$B$3,_翻訳マスタ!$B$1:$D$1,0))) -> 0 | C12: =COUNTIFS('03_WBS'!$B$5:$B$204,$A12,'03_WBS'!$P$5:$P$204,INDEX(_翻訳マスタ!$B$92:$D$92,1,MATCH(言語切替!$B$3,_翻訳マスタ!$B$1:$D$1,0))) -> 0 | D12: =COUNTIFS('04_課題ToDo'!$C$5:$C$304,$A12,'04_課題ToDo'!$S$5:$S$304,"<>"&INDEX(_翻訳マスタ!$B$75:$D$75,1,MATCH(言語切替!$B$3,_翻訳マスタ!$B$1:$D$1,0)),'04_課題ToDo'!$S$5:$S$304,"<>"&INDEX(_翻訳マスタ!$B$77:$D$77,1,MATCH(言語切替!$B$3,_翻訳マスタ!$B$1:$D$1,0))) -> 0 | E12: =COUNTIFS('04_課題ToDo'!$C$5:$C$304,$A12,'04_課題ToDo'!$AC$5:$AC$304,"High")+COUNTIFS('04_課題ToDo'!$C$5:$C$304,$A12,'04_課題ToDo'!$AC$5:$AC$304,INDEX(_翻訳マスタ!$B$117:$D$247,MATCH("ALERT_OVERDUE",_翻訳マスタ!$A$117:$A$247,0),MATCH(言語切替!$B$3,_翻訳マスタ!$B$1:$D$1,0))) -> 0 | F12: =COUNTIFS('04_課題ToDo'!$C$5:$C$304,$A12,'04_課題ToDo'!$S$5:$S$304,INDEX(_翻訳マスタ!$B$72:$D$72,1,MATCH(言語切替!$B$3,_翻訳マスタ!$B$1:$D$1,0)))+COUNTIFS('04_課題ToDo'!$C$5:$C$304,$A12,'04_課題ToDo'!$S$5:$S$304,INDEX(_翻訳マスタ!$B$73:$D$73,1,MATCH(言語切替!$B$3,_翻訳マスタ!$B$1:$D$1,0))) -> 0 | G12: =COUNTIFS('06_KPI'!$B$5:$B$204,$A12,'06_KPI'!$U$5:$U$204,INDEX(_翻訳マスタ!$B$94:$D$94,1,MATCH(言語切替!$B$3,_翻訳マスタ!$B$1:$D$1,0))) -> 0
A13: WG-3 | B13: =COUNTIFS('03_WBS'!$B$5:$B$204,$A13,'03_WBS'!$N$5:$N$204,"<>"&INDEX(_翻訳マスタ!$B$75:$D$75,1,MATCH(言語切替!$B$3,_翻訳マスタ!$B$1:$D$1,0))) -> 0 | C13: =COUNTIFS('03_WBS'!$B$5:$B$204,$A13,'03_WBS'!$P$5:$P$204,INDEX(_翻訳マスタ!$B$92:$D$92,1,MATCH(言語切替!$B$3,_翻訳マスタ!$B$1:$D$1,0))) -> 0 | D13: =COUNTIFS('04_課題ToDo'!$C$5:$C$304,$A13,'04_課題ToDo'!$S$5:$S$304,"<>"&INDEX(_翻訳マスタ!$B$75:$D$75,1,MATCH(言語切替!$B$3,_翻訳マスタ!$B$1:$D$1,0)),'04_課題ToDo'!$S$5:$S$304,"<>"&INDEX(_翻訳マスタ!$B$77:$D$77,1,MATCH(言語切替!$B$3,_翻訳マスタ!$B$1:$D$1,0))) -> 0 | E13: =COUNTIFS('04_課題ToDo'!$C$5:$C$304,$A13,'04_課題ToDo'!$AC$5:$AC$304,"High")+COUNTIFS('04_課題ToDo'!$C$5:$C$304,$A13,'04_課題ToDo'!$AC$5:$AC$304,INDEX(_翻訳マスタ!$B$117:$D$247,MATCH("ALERT_OVERDUE",_翻訳マスタ!$A$117:$A$247,0),MATCH(言語切替!$B$3,_翻訳マスタ!$B$1:$D$1,0))) -> 0 | F13: =COUNTIFS('04_課題ToDo'!$C$5:$C$304,$A13,'04_課題ToDo'!$S$5:$S$304,INDEX(_翻訳マスタ!$B$72:$D$72,1,MATCH(言語切替!$B$3,_翻訳マスタ!$B$1:$D$1,0)))+COUNTIFS('04_課題ToDo'!$C$5:$C$304,$A13,'04_課題ToDo'!$S$5:$S$304,INDEX(_翻訳マスタ!$B$73:$D$73,1,MATCH(言語切替!$B$3,_翻訳マスタ!$B$1:$D$1,0))) -> 0 | G13: =COUNTIFS('06_KPI'!$B$5:$B$204,$A13,'06_KPI'!$U$5:$U$204,INDEX(_翻訳マスタ!$B$94:$D$94,1,MATCH(言語切替!$B$3,_翻訳マスタ!$B$1:$D$1,0))) -> 0
A14: WG-4 | B14: =COUNTIFS('03_WBS'!$B$5:$B$204,$A14,'03_WBS'!$N$5:$N$204,"<>"&INDEX(_翻訳マスタ!$B$75:$D$75,1,MATCH(言語切替!$B$3,_翻訳マスタ!$B$1:$D$1,0))) -> 0 | C14: =COUNTIFS('03_WBS'!$B$5:$B$204,$A14,'03_WBS'!$P$5:$P$204,INDEX(_翻訳マスタ!$B$92:$D$92,1,MATCH(言語切替!$B$3,_翻訳マスタ!$B$1:$D$1,0))) -> 0 | D14: =COUNTIFS('04_課題ToDo'!$C$5:$C$304,$A14,'04_課題ToDo'!$S$5:$S$304,"<>"&INDEX(_翻訳マスタ!$B$75:$D$75,1,MATCH(言語切替!$B$3,_翻訳マスタ!$B$1:$D$1,0)),'04_課題ToDo'!$S$5:$S$304,"<>"&INDEX(_翻訳マスタ!$B$77:$D$77,1,MATCH(言語切替!$B$3,_翻訳マスタ!$B$1:$D$1,0))) -> 1 | E14: =COUNTIFS('04_課題ToDo'!$C$5:$C$304,$A14,'04_課題ToDo'!$AC$5:$AC$304,"High")+COUNTIFS('04_課題ToDo'!$C$5:$C$304,$A14,'04_課題ToDo'!$AC$5:$AC$304,INDEX(_翻訳マスタ!$B$117:$D$247,MATCH("ALERT_OVERDUE",_翻訳マスタ!$A$117:$A$247,0),MATCH(言語切替!$B$3,_翻訳マスタ!$B$1:$D$1,0))) -> 1 | F14: =COUNTIFS('04_課題ToDo'!$C$5:$C$304,$A14,'04_課題ToDo'!$S$5:$S$304,INDEX(_翻訳マスタ!$B$72:$D$72,1,MATCH(言語切替!$B$3,_翻訳マスタ!$B$1:$D$1,0)))+COUNTIFS('04_課題ToDo'!$C$5:$C$304,$A14,'04_課題ToDo'!$S$5:$S$304,INDEX(_翻訳マスタ!$B$73:$D$73,1,MATCH(言語切替!$B$3,_翻訳マスタ!$B$1:$D$1,0))) -> 0 | G14: =COUNTIFS('06_KPI'!$B$5:$B$204,$A14,'06_KPI'!$U$5:$U$204,INDEX(_翻訳マスタ!$B$94:$D$94,1,MATCH(言語切替!$B$3,_翻訳マスタ!$B$1:$D$1,0))) -> 0
A15: WG-5 | B15: =COUNTIFS('03_WBS'!$B$5:$B$204,$A15,'03_WBS'!$N$5:$N$204,"<>"&INDEX(_翻訳マスタ!$B$75:$D$75,1,MATCH(言語切替!$B$3,_翻訳マスタ!$B$1:$D$1,0))) -> 0 | C15: =COUNTIFS('03_WBS'!$B$5:$B$204,$A15,'03_WBS'!$P$5:$P$204,INDEX(_翻訳マスタ!$B$92:$D$92,1,MATCH(言語切替!$B$3,_翻訳マスタ!$B$1:$D$1,0))) -> 0 | D15: =COUNTIFS('04_課題ToDo'!$C$5:$C$304,$A15,'04_課題ToDo'!$S$5:$S$304,"<>"&INDEX(_翻訳マスタ!$B$75:$D$75,1,MATCH(言語切替!$B$3,_翻訳マスタ!$B$1:$D$1,0)),'04_課題ToDo'!$S$5:$S$304,"<>"&INDEX(_翻訳マスタ!$B$77:$D$77,1,MATCH(言語切替!$B$3,_翻訳マスタ!$B$1:$D$1,0))) -> 0 | E15: =COUNTIFS('04_課題ToDo'!$C$5:$C$304,$A15,'04_課題ToDo'!$AC$5:$AC$304,"High")+COUNTIFS('04_課題ToDo'!$C$5:$C$304,$A15,'04_課題ToDo'!$AC$5:$AC$304,INDEX(_翻訳マスタ!$B$117:$D$247,MATCH("ALERT_OVERDUE",_翻訳マスタ!$A$117:$A$247,0),MATCH(言語切替!$B$3,_翻訳マスタ!$B$1:$D$1,0))) -> 0 | F15: =COUNTIFS('04_課題ToDo'!$C$5:$C$304,$A15,'04_課題ToDo'!$S$5:$S$304,INDEX(_翻訳マスタ!$B$72:$D$72,1,MATCH(言語切替!$B$3,_翻訳マスタ!$B$1:$D$1,0)))+COUNTIFS('04_課題ToDo'!$C$5:$C$304,$A15,'04_課題ToDo'!$S$5:$S$304,INDEX(_翻訳マスタ!$B$73:$D$73,1,MATCH(言語切替!$B$3,_翻訳マスタ!$B$1:$D$1,0))) -> 0 | G15: =COUNTIFS('06_KPI'!$B$5:$B$204,$A15,'06_KPI'!$U$5:$U$204,INDEX(_翻訳マスタ!$B$94:$D$94,1,MATCH(言語切替!$B$3,_翻訳マスタ!$B$1:$D$1,0))) -> 0
A16: WG-6 | B16: =COUNTIFS('03_WBS'!$B$5:$B$204,$A16,'03_WBS'!$N$5:$N$204,"<>"&INDEX(_翻訳マスタ!$B$75:$D$75,1,MATCH(言語切替!$B$3,_翻訳マスタ!$B$1:$D$1,0))) -> 0 | C16: =COUNTIFS('03_WBS'!$B$5:$B$204,$A16,'03_WBS'!$P$5:$P$204,INDEX(_翻訳マスタ!$B$92:$D$92,1,MATCH(言語切替!$B$3,_翻訳マスタ!$B$1:$D$1,0))) -> 0 | D16: =COUNTIFS('04_課題ToDo'!$C$5:$C$304,$A16,'04_課題ToDo'!$S$5:$S$304,"<>"&INDEX(_翻訳マスタ!$B$75:$D$75,1,MATCH(言語切替!$B$3,_翻訳マスタ!$B$1:$D$1,0)),'04_課題ToDo'!$S$5:$S$304,"<>"&INDEX(_翻訳マスタ!$B$77:$D$77,1,MATCH(言語切替!$B$3,_翻訳マスタ!$B$1:$D$1,0))) -> 0 | E16: =COUNTIFS('04_課題ToDo'!$C$5:$C$304,$A16,'04_課題ToDo'!$AC$5:$AC$304,"High")+COUNTIFS('04_課題ToDo'!$C$5:$C$304,$A16,'04_課題ToDo'!$AC$5:$AC$304,INDEX(_翻訳マスタ!$B$117:$D$247,MATCH("ALERT_OVERDUE",_翻訳マスタ!$A$117:$A$247,0),MATCH(言語切替!$B$3,_翻訳マスタ!$B$1:$D$1,0))) -> 0 | F16: =COUNTIFS('04_課題ToDo'!$C$5:$C$304,$A16,'04_課題ToDo'!$S$5:$S$304,INDEX(_翻訳マスタ!$B$72:$D$72,1,MATCH(言語切替!$B$3,_翻訳マスタ!$B$1:$D$1,0)))+COUNTIFS('04_課題ToDo'!$C$5:$C$304,$A16,'04_課題ToDo'!$S$5:$S$304,INDEX(_翻訳マスタ!$B$73:$D$73,1,MATCH(言語切替!$B$3,_翻訳マスタ!$B$1:$D$1,0))) -> 0 | G16: =COUNTIFS('06_KPI'!$B$5:$B$204,$A16,'06_KPI'!$U$5:$U$204,INDEX(_翻訳マスタ!$B$94:$D$94,1,MATCH(言語切替!$B$3,_翻訳マスタ!$B$1:$D$1,0))) -> 0
A17: WG-7 | B17: =COUNTIFS('03_WBS'!$B$5:$B$204,$A17,'03_WBS'!$N$5:$N$204,"<>"&INDEX(_翻訳マスタ!$B$75:$D$75,1,MATCH(言語切替!$B$3,_翻訳マスタ!$B$1:$D$1,0))) -> 0 | C17: =COUNTIFS('03_WBS'!$B$5:$B$204,$A17,'03_WBS'!$P$5:$P$204,INDEX(_翻訳マスタ!$B$92:$D$92,1,MATCH(言語切替!$B$3,_翻訳マスタ!$B$1:$D$1,0))) -> 0 | D17: =COUNTIFS('04_課題ToDo'!$C$5:$C$304,$A17,'04_課題ToDo'!$S$5:$S$304,"<>"&INDEX(_翻訳マスタ!$B$75:$D$75,1,MATCH(言語切替!$B$3,_翻訳マスタ!$B$1:$D$1,0)),'04_課題ToDo'!$S$5:$S$304,"<>"&INDEX(_翻訳マスタ!$B$77:$D$77,1,MATCH(言語切替!$B$3,_翻訳マスタ!$B$1:$D$1,0))) -> 1 | E17: =COUNTIFS('04_課題ToDo'!$C$5:$C$304,$A17,'04_課題ToDo'!$AC$5:$AC$304,"High")+COUNTIFS('04_課題ToDo'!$C$5:$C$304,$A17,'04_課題ToDo'!$AC$5:$AC$304,INDEX(_翻訳マスタ!$B$117:$D$247,MATCH("ALERT_OVERDUE",_翻訳マスタ!$A$117:$A$247,0),MATCH(言語切替!$B$3,_翻訳マスタ!$B$1:$D$1,0))) -> 0 | F17: =COUNTIFS('04_課題ToDo'!$C$5:$C$304,$A17,'04_課題ToDo'!$S$5:$S$304,INDEX(_翻訳マスタ!$B$72:$D$72,1,MATCH(言語切替!$B$3,_翻訳マスタ!$B$1:$D$1,0)))+COUNTIFS('04_課題ToDo'!$C$5:$C$304,$A17,'04_課題ToDo'!$S$5:$S$304,INDEX(_翻訳マスタ!$B$73:$D$73,1,MATCH(言語切替!$B$3,_翻訳マスタ!$B$1:$D$1,0))) -> 0 | G17: =COUNTIFS('06_KPI'!$B$5:$B$204,$A17,'06_KPI'!$U$5:$U$204,INDEX(_翻訳マスタ!$B$94:$D$94,1,MATCH(言語切替!$B$3,_翻訳マスタ!$B$1:$D$1,0))) -> 0
A18: WG-8 | B18: =COUNTIFS('03_WBS'!$B$5:$B$204,$A18,'03_WBS'!$N$5:$N$204,"<>"&INDEX(_翻訳マスタ!$B$75:$D$75,1,MATCH(言語切替!$B$3,_翻訳マスタ!$B$1:$D$1,0))) -> 1 | C18: =COUNTIFS('03_WBS'!$B$5:$B$204,$A18,'03_WBS'!$P$5:$P$204,INDEX(_翻訳マスタ!$B$92:$D$92,1,MATCH(言語切替!$B$3,_翻訳マスタ!$B$1:$D$1,0))) -> 0 | D18: =COUNTIFS('04_課題ToDo'!$C$5:$C$304,$A18,'04_課題ToDo'!$S$5:$S$304,"<>"&INDEX(_翻訳マスタ!$B$75:$D$75,1,MATCH(言語切替!$B$3,_翻訳マスタ!$B$1:$D$1,0)),'04_課題ToDo'!$S$5:$S$304,"<>"&INDEX(_翻訳マスタ!$B$77:$D$77,1,MATCH(言語切替!$B$3,_翻訳マスタ!$B$1:$D$1,0))) -> 0 | E18: =COUNTIFS('04_課題ToDo'!$C$5:$C$304,$A18,'04_課題ToDo'!$AC$5:$AC$304,"High")+COUNTIFS('04_課題ToDo'!$C$5:$C$304,$A18,'04_課題ToDo'!$AC$5:$AC$304,INDEX(_翻訳マスタ!$B$117:$D$247,MATCH("ALERT_OVERDUE",_翻訳マスタ!$A$117:$A$247,0),MATCH(言語切替!$B$3,_翻訳マスタ!$B$1:$D$1,0))) -> 0 | F18: =COUNTIFS('04_課題ToDo'!$C$5:$C$304,$A18,'04_課題ToDo'!$S$5:$S$304,INDEX(_翻訳マスタ!$B$72:$D$72,1,MATCH(言語切替!$B$3,_翻訳マスタ!$B$1:$D$1,0)))+COUNTIFS('04_課題ToDo'!$C$5:$C$304,$A18,'04_課題ToDo'!$S$5:$S$304,INDEX(_翻訳マスタ!$B$73:$D$73,1,MATCH(言語切替!$B$3,_翻訳マスタ!$B$1:$D$1,0))) -> 0 | G18: =COUNTIFS('06_KPI'!$B$5:$B$204,$A18,'06_KPI'!$U$5:$U$204,INDEX(_翻訳マスタ!$B$94:$D$94,1,MATCH(言語切替!$B$3,_翻訳マスタ!$B$1:$D$1,0))) -> 0
A19: WG-9 | B19: =COUNTIFS('03_WBS'!$B$5:$B$204,$A19,'03_WBS'!$N$5:$N$204,"<>"&INDEX(_翻訳マスタ!$B$75:$D$75,1,MATCH(言語切替!$B$3,_翻訳マスタ!$B$1:$D$1,0))) -> 0 | C19: =COUNTIFS('03_WBS'!$B$5:$B$204,$A19,'03_WBS'!$P$5:$P$204,INDEX(_翻訳マスタ!$B$92:$D$92,1,MATCH(言語切替!$B$3,_翻訳マスタ!$B$1:$D$1,0))) -> 0 | D19: =COUNTIFS('04_課題ToDo'!$C$5:$C$304,$A19,'04_課題ToDo'!$S$5:$S$304,"<>"&INDEX(_翻訳マスタ!$B$75:$D$75,1,MATCH(言語切替!$B$3,_翻訳マスタ!$B$1:$D$1,0)),'04_課題ToDo'!$S$5:$S$304,"<>"&INDEX(_翻訳マスタ!$B$77:$D$77,1,MATCH(言語切替!$B$3,_翻訳マスタ!$B$1:$D$1,0))) -> 1 | E19: =COUNTIFS('04_課題ToDo'!$C$5:$C$304,$A19,'04_課題ToDo'!$AC$5:$AC$304,"High")+COUNTIFS('04_課題ToDo'!$C$5:$C$304,$A19,'04_課題ToDo'!$AC$5:$AC$304,INDEX(_翻訳マスタ!$B$117:$D$247,MATCH("ALERT_OVERDUE",_翻訳マスタ!$A$117:$A$247,0),MATCH(言語切替!$B$3,_翻訳マスタ!$B$1:$D$1,0))) -> 0 | F19: =COUNTIFS('04_課題ToDo'!$C$5:$C$304,$A19,'04_課題ToDo'!$S$5:$S$304,INDEX(_翻訳マスタ!$B$72:$D$72,1,MATCH(言語切替!$B$3,_翻訳マスタ!$B$1:$D$1,0)))+COUNTIFS('04_課題ToDo'!$C$5:$C$304,$A19,'04_課題ToDo'!$S$5:$S$304,INDEX(_翻訳マスタ!$B$73:$D$73,1,MATCH(言語切替!$B$3,_翻訳マスタ!$B$1:$D$1,0))) -> 0 | G19: =COUNTIFS('06_KPI'!$B$5:$B$204,$A19,'06_KPI'!$U$5:$U$204,INDEX(_翻訳マスタ!$B$94:$D$94,1,MATCH(言語切替!$B$3,_翻訳マスタ!$B$1:$D$1,0))) -> 0

Sheet 02_マスタ
A1: =INDEX(_翻訳マスタ!$B$47:$D$98,MATCH("M_TITLE",_翻訳マスタ!$A$47:$A$98,0),MATCH(言語切替!$B$3,_翻訳マスタ!$B$1:$D$1,0)) -> Danh mục nhập liệu
A2: =INDEX(_翻訳マスタ!$B$47:$D$98,MATCH("M_DESC",_翻訳マスタ!$A$47:$A$98,0),MATCH(言語切替!$B$3,_翻訳マスタ!$B$1:$D$1,0)) -> Các giá trị lựa chọn dùng cho xác thực dữ liệu. Chỉ ban điều hành được thay đổi.
A4: =INDEX(_翻訳マスタ!$B$47:$D$98,MATCH("M_WG",_翻訳マスタ!$A$47:$A$98,0),MATCH(言語切替!$B$3,_翻訳マスタ!$B$1:$D$1,0)) -> WG | C4: =INDEX(_翻訳マスタ!$B$47:$D$98,MATCH("M_SITE",_翻訳マスタ!$A$47:$A$98,0),MATCH(言語切替!$B$3,_翻訳マスタ!$B$1:$D$1,0)) -> Đơn vị | E4: =INDEX(_翻訳マスタ!$B$47:$D$98,MATCH("M_STATUS",_翻訳マスタ!$A$47:$A$98,0),MATCH(言語切替!$B$3,_翻訳マスタ!$B$1:$D$1,0)) -> Trạng thái | G4: =INDEX(_翻訳マスタ!$B$47:$D$98,MATCH("M_PRIORITY",_翻訳マスタ!$A$47:$A$98,0),MATCH(言語切替!$B$3,_翻訳マスタ!$B$1:$D$1,0)) -> Mức ưu tiên | I4: =INDEX(_翻訳マスタ!$B$47:$D$98,MATCH("M_TYPE",_翻訳マスタ!$A$47:$A$98,0),MATCH(言語切替!$B$3,_翻訳マスタ!$B$1:$D$1,0)) -> Phân loại | K4: =INDEX(_翻訳マスタ!$B$47:$D$98,MATCH("M_KPI_LEVEL",_翻訳マスタ!$A$47:$A$98,0),MATCH(言語切替!$B$3,_翻訳マスタ!$B$1:$D$1,0)) -> Cấp KPI | M4: =INDEX(_翻訳マスタ!$B$47:$D$98,MATCH("M_JUDGMENT",_翻訳マスタ!$A$47:$A$98,0),MATCH(言語切替!$B$3,_翻訳マスタ!$B$1:$D$1,0)) -> Đánh giá
A5: =INDEX(_翻訳マスタ!$B$47:$D$98,MATCH("M_ALL",_翻訳マスタ!$A$47:$A$98,0),MATCH(言語切替!$B$3,_翻訳マスタ!$B$1:$D$1,0)) -> Toàn bộ | C5: =INDEX(_翻訳マスタ!$B$47:$D$98,MATCH("M_COMMON",_翻訳マスタ!$A$47:$A$98,0),MATCH(言語切替!$B$3,_翻訳マスタ!$B$1:$D$1,0)) -> Chung | E5: =INDEX(_翻訳マスタ!$B$47:$D$98,MATCH("M_NOT_STARTED",_翻訳マスタ!$A$47:$A$98,0),MATCH(言語切替!$B$3,_翻訳マスタ!$B$1:$D$1,0)) -> Chưa bắt đầu | G5: =INDEX(_翻訳マスタ!$B$47:$D$98,MATCH("M_HIGH",_翻訳マスタ!$A$47:$A$98,0),MATCH(言語切替!$B$3,_翻訳マスタ!$B$1:$D$1,0)) -> High | I5: =INDEX(_翻訳マスタ!$B$47:$D$98,MATCH("M_ISSUE",_翻訳マスタ!$A$47:$A$98,0),MATCH(言語切替!$B$3,_翻訳マスタ!$B$1:$D$1,0)) -> Vấn đề | K5: =INDEX(_翻訳マスタ!$B$47:$D$98,MATCH("M_FOUNDATION",_翻訳マスタ!$A$47:$A$98,0),MATCH(言語切替!$B$3,_翻訳マスタ!$B$1:$D$1,0)) -> Thiết lập nền tảng | M5: =INDEX(_翻訳マスタ!$B$47:$D$98,MATCH("M_UNSET",_翻訳マスタ!$A$47:$A$98,0),MATCH(言語切替!$B$3,_翻訳マスタ!$B$1:$D$1,0)) -> Chưa thiết lập
A6: =INDEX(_翻訳マスタ!$B$47:$D$98,MATCH("M_WG1",_翻訳マスタ!$A$47:$A$98,0),MATCH(言語切替!$B$3,_翻訳マスタ!$B$1:$D$1,0)) -> WG-1 | C6: =INDEX(_翻訳マスタ!$B$47:$D$98,MATCH("M_KDC",_翻訳マスタ!$A$47:$A$98,0),MATCH(言語切替!$B$3,_翻訳マスタ!$B$1:$D$1,0)) -> KDC | E6: =INDEX(_翻訳マスタ!$B$47:$D$98,MATCH("M_IN_PROGRESS",_翻訳マスタ!$A$47:$A$98,0),MATCH(言語切替!$B$3,_翻訳マスタ!$B$1:$D$1,0)) -> Đang xử lý | G6: =INDEX(_翻訳マスタ!$B$47:$D$98,MATCH("M_MIDDLE",_翻訳マスタ!$A$47:$A$98,0),MATCH(言語切替!$B$3,_翻訳マスタ!$B$1:$D$1,0)) -> Middle | I6: =INDEX(_翻訳マスタ!$B$47:$D$98,MATCH("M_TODO",_翻訳マスタ!$A$47:$A$98,0),MATCH(言語切替!$B$3,_翻訳マスタ!$B$1:$D$1,0)) -> ToDo | K6: =INDEX(_翻訳マスタ!$B$47:$D$98,MATCH("M_ADOPTION",_翻訳マスタ!$A$47:$A$98,0),MATCH(言語切替!$B$3,_翻訳マスタ!$B$1:$D$1,0)) -> Vận hành ổn định | M6: =INDEX(_翻訳マスタ!$B$47:$D$98,MATCH("M_ON_TRACK",_翻訳マスタ!$A$47:$A$98,0),MATCH(言語切替!$B$3,_翻訳マスタ!$B$1:$D$1,0)) -> Đúng tiến độ
A7: =INDEX(_翻訳マスタ!$B$47:$D$98,MATCH("M_WG2",_翻訳マスタ!$A$47:$A$98,0),MATCH(言語切替!$B$3,_翻訳マスタ!$B$1:$D$1,0)) -> WG-2 | C7: =INDEX(_翻訳マスタ!$B$47:$D$98,MATCH("M_KDTCN",_翻訳マスタ!$A$47:$A$98,0),MATCH(言語切替!$B$3,_翻訳マスタ!$B$1:$D$1,0)) -> KDTCN | E7: =INDEX(_翻訳マスタ!$B$47:$D$98,MATCH("M_WAIT_DECISION",_翻訳マスタ!$A$47:$A$98,0),MATCH(言語切替!$B$3,_翻訳マスタ!$B$1:$D$1,0)) -> Chờ quyết định | G7: =INDEX(_翻訳マスタ!$B$47:$D$98,MATCH("M_LOW",_翻訳マスタ!$A$47:$A$98,0),MATCH(言語切替!$B$3,_翻訳マスタ!$B$1:$D$1,0)) -> Low | I7: =INDEX(_翻訳マスタ!$B$47:$D$98,MATCH("M_DECISION",_翻訳マスタ!$A$47:$A$98,0),MATCH(言語切替!$B$3,_翻訳マスタ!$B$1:$D$1,0)) -> Quyết định | K7: =INDEX(_翻訳マスタ!$B$47:$D$98,MATCH("M_BUSINESS",_翻訳マスタ!$A$47:$A$98,0),MATCH(言語切替!$B$3,_翻訳マスタ!$B$1:$D$1,0)) -> Kết quả nghiệp vụ | M7: =INDEX(_翻訳マスタ!$B$47:$D$98,MATCH("M_CAUTION",_翻訳マスタ!$A$47:$A$98,0),MATCH(言語切替!$B$3,_翻訳マスタ!$B$1:$D$1,0)) -> Cần chú ý
A8: =INDEX(_翻訳マスタ!$B$47:$D$98,MATCH("M_WG3",_翻訳マスタ!$A$47:$A$98,0),MATCH(言語切替!$B$3,_翻訳マスタ!$B$1:$D$1,0)) -> WG-3 | C8: =INDEX(_翻訳マスタ!$B$47:$D$98,MATCH("M_KDTVN",_翻訳マスタ!$A$47:$A$98,0),MATCH(言語切替!$B$3,_翻訳マスタ!$B$1:$D$1,0)) -> KDTVN | E8: =INDEX(_翻訳マスタ!$B$47:$D$98,MATCH("M_WAIT_WG",_翻訳マスタ!$A$47:$A$98,0),MATCH(言語切替!$B$3,_翻訳マスタ!$B$1:$D$1,0)) -> Chờ WG khác | I8: =INDEX(_翻訳マスタ!$B$47:$D$98,MATCH("M_RISK",_翻訳マスタ!$A$47:$A$98,0),MATCH(言語切替!$B$3,_翻訳マスタ!$B$1:$D$1,0)) -> Rủi ro | K8: =INDEX(_翻訳マスタ!$B$47:$D$98,MATCH("M_INVESTMENT",_翻訳マスタ!$A$47:$A$98,0),MATCH(言語切替!$B$3,_翻訳マスタ!$B$1:$D$1,0)) -> Kết quả đầu tư | M8: =INDEX(_翻訳マスタ!$B$47:$D$98,MATCH("M_DELAY",_翻訳マスタ!$A$47:$A$98,0),MATCH(言語切替!$B$3,_翻訳マスタ!$B$1:$D$1,0)) -> Chậm tiến độ
A9: =INDEX(_翻訳マスタ!$B$47:$D$98,MATCH("M_WG4",_翻訳マスタ!$A$47:$A$98,0),MATCH(言語切替!$B$3,_翻訳マスタ!$B$1:$D$1,0)) -> WG-4 | E9: =INDEX(_翻訳マスタ!$B$47:$D$98,MATCH("M_WAIT_COMPLETE",_翻訳マスタ!$A$47:$A$98,0),MATCH(言語切替!$B$3,_翻訳マスタ!$B$1:$D$1,0)) -> Chờ xác nhận hoàn thành | M9: =INDEX(_翻訳マスタ!$B$47:$D$98,MATCH("M_ACHIEVED",_翻訳マスタ!$A$47:$A$98,0),MATCH(言語切替!$B$3,_翻訳マスタ!$B$1:$D$1,0)) -> Đạt
A10: =INDEX(_翻訳マスタ!$B$47:$D$98,MATCH("M_WG5",_翻訳マスタ!$A$47:$A$98,0),MATCH(言語切替!$B$3,_翻訳マスタ!$B$1:$D$1,0)) -> WG-5 | E10: =INDEX(_翻訳マスタ!$B$47:$D$98,MATCH("M_COMPLETE",_翻訳マスタ!$A$47:$A$98,0),MATCH(言語切替!$B$3,_翻訳マスタ!$B$1:$D$1,0)) -> Hoàn thành | M10: =INDEX(_翻訳マスタ!$B$47:$D$98,MATCH("M_NOT_ACHIEVED",_翻訳マスタ!$A$47:$A$98,0),MATCH(言語切替!$B$3,_翻訳マスタ!$B$1:$D$1,0)) -> Chưa đạt
A11: =INDEX(_翻訳マスタ!$B$47:$D$98,MATCH("M_WG6",_翻訳マスタ!$A$47:$A$98,0),MATCH(言語切替!$B$3,_翻訳マスタ!$B$1:$D$1,0)) -> WG-6 | E11: =INDEX(_翻訳マスタ!$B$47:$D$98,MATCH("M_HOLD",_翻訳マスタ!$A$47:$A$98,0),MATCH(言語切替!$B$3,_翻訳マスタ!$B$1:$D$1,0)) -> Tạm hoãn
A12: =INDEX(_翻訳マスタ!$B$47:$D$98,MATCH("M_WG7",_翻訳マスタ!$A$47:$A$98,0),MATCH(言語切替!$B$3,_翻訳マスタ!$B$1:$D$1,0)) -> WG-7 | E12: =INDEX(_翻訳マスタ!$B$47:$D$98,MATCH("M_WITHDRAWN",_翻訳マスタ!$A$47:$A$98,0),MATCH(言語切替!$B$3,_翻訳マスタ!$B$1:$D$1,0)) -> Rút lại
A13: =INDEX(_翻訳マスタ!$B$47:$D$98,MATCH("M_WG8",_翻訳マスタ!$A$47:$A$98,0),MATCH(言語切替!$B$3,_翻訳マスタ!$B$1:$D$1,0)) -> WG-8
A14: =INDEX(_翻訳マスタ!$B$47:$D$98,MATCH("M_WG9",_翻訳マスタ!$A$47:$A$98,0),MATCH(言語切替!$B$3,_翻訳マスタ!$B$1:$D$1,0)) -> WG-9
A18: =INDEX(_翻訳マスタ!$B$47:$D$98,MATCH("M_PRIORITY_GUIDE",_翻訳マスタ!$A$47:$A$98,0),MATCH(言語切替!$B$3,_翻訳マスタ!$B$1:$D$1,0)) -> Nguyên tắc ưu tiên
A19: =INDEX(_翻訳マスタ!$B$47:$D$98,MATCH("M_HIGH_DESC",_翻訳マスタ!$A$47:$A$98,0),MATCH(言語切替!$B$3,_翻訳マスタ!$B$1:$D$1,0)) -> High: Ảnh hưởng trực tiếp đến tiến độ, chi phí và chất lượng của toàn tiểu ban.
A20: =INDEX(_翻訳マスタ!$B$47:$D$98,MATCH("M_MIDDLE_DESC",_翻訳マスタ!$A$47:$A$98,0),MATCH(言語切替!$B$3,_翻訳マスタ!$B$1:$D$1,0)) -> Middle: Ảnh hưởng trực tiếp đến tiến độ, chi phí và chất lượng của từng WG.
A21: =INDEX(_翻訳マスタ!$B$47:$D$98,MATCH("M_LOW_DESC",_翻訳マスタ!$A$47:$A$98,0),MATCH(言語切替!$B$3,_翻訳マスタ!$B$1:$D$1,0)) -> Low: Ảnh hưởng trực tiếp nhỏ nhưng cần thiết để thành công.

Sheet 03_WBS
A1: =INDEX(_翻訳マスタ!$B$99:$D$116,MATCH("WBS_TITLE",_翻訳マスタ!$A$99:$A$116,0),MATCH(言語切替!$B$3,_翻訳マスタ!$B$1:$D$1,0)) -> WBS & Mốc tiến độ
A2: =INDEX(_翻訳マスタ!$B$99:$D$116,MATCH("WBS_DESC",_翻訳マスタ!$A$99:$A$116,0),MATCH(言語切替!$B$3,_翻訳マスタ!$B$1:$D$1,0)) -> Các ô chữ màu xanh là ô nhập liệu. Tỷ lệ tiến độ, số ngày còn lại và đánh giá chậm tiến độ được tính tự động. 3 dòng là ví dụ nhập liệu.
A3: =INDEX(_翻訳マスタ!$B$2:$D$300,MATCH("PARA_HOWTO",_翻訳マスタ!$A$2:$A$300,0),MATCH(言語切替!$B$3,_翻訳マスタ!$B$1:$D$1,0)) -> Cách dùng: Nhập tiếng mẹ đẻ → đọc cột khác → ô trống không dịch → dưới 3000 ký tự
A4: =INDEX(_翻訳マスタ!$B$99:$D$116,MATCH("WBS_ID",_翻訳マスタ!$A$99:$A$116,0),MATCH(言語切替!$B$3,_翻訳マスタ!$B$1:$D$1,0)) -> WBS ID | B4: =INDEX(_翻訳マスタ!$B$99:$D$116,MATCH("WBS_WG",_翻訳マスタ!$A$99:$A$116,0),MATCH(言語切替!$B$3,_翻訳マスタ!$B$1:$D$1,0)) -> WG | C4: =INDEX(_翻訳マスタ!$B$99:$D$116,MATCH("WBS_SITE",_翻訳マスタ!$A$99:$A$116,0),MATCH(言語切替!$B$3,_翻訳マスタ!$B$1:$D$1,0)) -> Đơn vị | D4: =INDEX(_翻訳マスタ!$B$99:$D$116,MATCH("WBS_CATEGORY",_翻訳マスタ!$A$99:$A$116,0),MATCH(言語切替!$B$3,_翻訳マスタ!$B$1:$D$1,0)) -> Phân loại chính | E4: =INDEX(_翻訳マスタ!$B$2:$D$300,MATCH("WBS_TASK",_翻訳マスタ!$A$2:$A$300,0),MATCH(言語切替!$B$3,_翻訳マスタ!$B$1:$D$1,0))&INDEX(_翻訳マスタ!$B$2:$D$300,MATCH("NEW_VI_SUFFIX",_翻訳マスタ!$A$2:$A$300,0),MATCH(言語切替!$B$3,_翻訳マスタ!$B$1:$D$1,0)) -> Nhiệm vụ / Sản phẩm bàn giao (VI) | F4: =INDEX(_翻訳マスタ!$B$2:$D$300,MATCH("WBS_TASK",_翻訳マスタ!$A$2:$A$300,0),MATCH(言語切替!$B$3,_翻訳マスタ!$B$1:$D$1,0))&INDEX(_翻訳マスタ!$B$2:$D$300,MATCH("NEW_JP_SUFFIX",_翻訳マスタ!$A$2:$A$300,0),MATCH(言語切替!$B$3,_翻訳マスタ!$B$1:$D$1,0)) -> Nhiệm vụ / Sản phẩm bàn giao (JP) | G4: =INDEX(_翻訳マスタ!$B$2:$D$300,MATCH("WBS_TASK",_翻訳マスタ!$A$2:$A$300,0),MATCH(言語切替!$B$3,_翻訳マスタ!$B$1:$D$1,0))&INDEX(_翻訳マスタ!$B$2:$D$300,MATCH("NEW_CN_SUFFIX",_翻訳マスタ!$A$2:$A$300,0),MATCH(言語切替!$B$3,_翻訳マスタ!$B$1:$D$1,0)) -> Nhiệm vụ / Sản phẩm bàn giao (CN) | H4: =INDEX(_翻訳マスタ!$B$99:$D$116,MATCH("WBS_OWNER",_翻訳マスタ!$A$99:$A$116,0),MATCH(言語切替!$B$3,_翻訳マスタ!$B$1:$D$1,0)) -> Người chịu trách nhiệm | I4: =INDEX(_翻訳マスタ!$B$99:$D$116,MATCH("WBS_PLAN_START",_翻訳マスタ!$A$99:$A$116,0),MATCH(言語切替!$B$3,_翻訳マスタ!$B$1:$D$1,0)) -> Ngày bắt đầu kế hoạch | J4: =INDEX(_翻訳マスタ!$B$99:$D$116,MATCH("WBS_PLAN_END",_翻訳マスタ!$A$99:$A$116,0),MATCH(言語切替!$B$3,_翻訳マスタ!$B$1:$D$1,0)) -> Ngày kết thúc kế hoạch | K4: =INDEX(_翻訳マスタ!$B$99:$D$116,MATCH("WBS_ACTUAL_START",_翻訳マスタ!$A$99:$A$116,0),MATCH(言語切替!$B$3,_翻訳マスタ!$B$1:$D$1,0)) -> Ngày bắt đầu thực tế | L4: =INDEX(_翻訳マスタ!$B$99:$D$116,MATCH("WBS_ACTUAL_END",_翻訳マスタ!$A$99:$A$116,0),MATCH(言語切替!$B$3,_翻訳マスタ!$B$1:$D$1,0)) -> Ngày kết thúc thực tế | M4: =INDEX(_翻訳マスタ!$B$99:$D$116,MATCH("WBS_PROGRESS",_翻訳マスタ!$A$99:$A$116,0),MATCH(言語切替!$B$3,_翻訳マスタ!$B$1:$D$1,0)) -> Tỷ lệ tiến độ | N4: =INDEX(_翻訳マスタ!$B$99:$D$116,MATCH("WBS_STATUS",_翻訳マスタ!$A$99:$A$116,0),MATCH(言語切替!$B$3,_翻訳マスタ!$B$1:$D$1,0)) -> Trạng thái | O4: =INDEX(_翻訳マスタ!$B$99:$D$116,MATCH("WBS_DAYS",_翻訳マスタ!$A$99:$A$116,0),MATCH(言語切替!$B$3,_翻訳マスタ!$B$1:$D$1,0)) -> Số ngày còn lại | P4: =INDEX(_翻訳マスタ!$B$99:$D$116,MATCH("WBS_DELAY",_翻訳マスタ!$A$99:$A$116,0),MATCH(言語切替!$B$3,_翻訳マスタ!$B$1:$D$1,0)) -> Đánh giá chậm tiến độ | Q4: =INDEX(_翻訳マスタ!$B$99:$D$116,MATCH("WBS_LINK",_翻訳マスタ!$A$99:$A$116,0),MATCH(言語切替!$B$3,_翻訳マスタ!$B$1:$D$1,0)) -> Liên kết liên quan | R4: =INDEX(_翻訳マスタ!$B$2:$D$300,MATCH("WBS_NOTE",_翻訳マスタ!$A$2:$A$300,0),MATCH(言語切替!$B$3,_翻訳マスタ!$B$1:$D$1,0))&INDEX(_翻訳マスタ!$B$2:$D$300,MATCH("NEW_VI_SUFFIX",_翻訳マスタ!$A$2:$A$300,0),MATCH(言語切替!$B$3,_翻訳マスタ!$B$1:$D$1,0)) -> Ghi chú (VI) | S4: =INDEX(_翻訳マスタ!$B$2:$D$300,MATCH("WBS_NOTE",_翻訳マスタ!$A$2:$A$300,0),MATCH(言語切替!$B$3,_翻訳マスタ!$B$1:$D$1,0))&INDEX(_翻訳マスタ!$B$2:$D$300,MATCH("NEW_JP_SUFFIX",_翻訳マスタ!$A$2:$A$300,0),MATCH(言語切替!$B$3,_翻訳マスタ!$B$1:$D$1,0)) -> Ghi chú (JP) | T4: =INDEX(_翻訳マスタ!$B$2:$D$300,MATCH("WBS_NOTE",_翻訳マスタ!$A$2:$A$300,0),MATCH(言語切替!$B$3,_翻訳マスタ!$B$1:$D$1,0))&INDEX(_翻訳マスタ!$B$2:$D$300,MATCH("NEW_CN_SUFFIX",_翻訳マスタ!$A$2:$A$300,0),MATCH(言語切替!$B$3,_翻訳マスタ!$B$1:$D$1,0)) -> Ghi chú (CN)
A5: WBS-001 | B5: ='02_マスタ'!$A$5 -> Toàn bộ | C5: KDC | D5: =INDEX(_翻訳マスタ!$B$117:$D$247,MATCH("WBS_CAT_STARTUP",_翻訳マスタ!$A$117:$A$247,0),MATCH(言語切替!$B$3,_翻訳マスタ!$B$1:$D$1,0)) -> Khởi động | E5: =INDEX(_翻訳マスタ!$D$2:$D$300,MATCH("WBS_TASK_1",_翻訳マスタ!$A$2:$A$300,0)) -> Xác định quy tắc vận hành WG | F5: =IF(E5="","",_xlfn.TRANSLATE(E5,"","ja")) -> #VALUE! | G5: =IF(E5="","",_xlfn.TRANSLATE(E5,"","zh-Hans")) -> #VALUE! | H5: =INDEX(_翻訳マスタ!$B$117:$D$247,MATCH("ROLE_PMO",_翻訳マスタ!$A$117:$A$247,0),MATCH(言語切替!$B$3,_翻訳マスタ!$B$1:$D$1,0)) -> Ban điều hành | I5: 46288 | J5: 46295 | M5: =IF(OR(I5="",J5=""),"",IF(L5<>"",1,IF(K5="",0,MAX(0,MIN(1,(TODAY()-I5)/(J5-I5+1)))))) -> 0 | N5: ='02_マスタ'!$E$6 -> Đang xử lý | O5: =IF(J5="","",J5-TODAY()) -> 0 | P5: =IF(J5="","",IF(L5<>"",INDEX(_翻訳マスタ!$B$75:$D$75,1,MATCH(言語切替!$B$3,_翻訳マスタ!$B$1:$D$1,0)),IF(TODAY()>J5,INDEX(_翻訳マスタ!$B$92:$D$92,1,MATCH(言語切替!$B$3,_翻訳マスタ!$B$1:$D$1,0)),IF(J5-TODAY()<=7,INDEX(_翻訳マスタ!$B$91:$D$91,1,MATCH(言語切替!$B$3,_翻訳マスタ!$B$1:$D$1,0)),INDEX(_翻訳マスタ!$B$90:$D$90,1,MATCH(言語切替!$B$3,_翻訳マスタ!$B$1:$D$1,0)))))) -> Cần chú ý | R5: =INDEX(_翻訳マスタ!$D$2:$D$300,MATCH("COMMON_EXAMPLE",_翻訳マスタ!$A$2:$A$300,0)) -> Ví dụ nhập liệu | S5: =IF(R5="","",_xlfn.TRANSLATE(R5,"","ja")) -> #VALUE! | T5: =IF(R5="","",_xlfn.TRANSLATE(R5,"","zh-Hans")) -> #VALUE!
A6: WBS-002 | B6: WG-1 | C6: KDTVN | D6: =INDEX(_翻訳マスタ!$B$117:$D$247,MATCH("WBS_CAT_ANALYSIS",_翻訳マスタ!$A$117:$A$247,0),MATCH(言語切替!$B$3,_翻訳マスタ!$B$1:$D$1,0)) -> Phân tích hiện trạng | E6: =INDEX(_翻訳マスタ!$D$2:$D$300,MATCH("WBS_TASK_2",_翻訳マスタ!$A$2:$A$300,0)) -> Rà soát nghiệp vụ hiện tại | F6: =IF(E6="","",_xlfn.TRANSLATE(E6,"","ja")) -> #VALUE! | G6: =IF(E6="","",_xlfn.TRANSLATE(E6,"","zh-Hans")) -> #VALUE! | H6: WG Leader | I6: 46294 | J6: 46311 | M6: =IF(OR(I6="",J6=""),"",IF(L6<>"",1,IF(K6="",0,MAX(0,MIN(1,(TODAY()-I6)/(J6-I6+1)))))) -> 0 | N6: ='02_マスタ'!$E$5 -> Chưa bắt đầu | O6: =IF(J6="","",J6-TODAY()) -> 16 | P6: =IF(J6="","",IF(L6<>"",INDEX(_翻訳マスタ!$B$75:$D$75,1,MATCH(言語切替!$B$3,_翻訳マスタ!$B$1:$D$1,0)),IF(TODAY()>J6,INDEX(_翻訳マスタ!$B$92:$D$92,1,MATCH(言語切替!$B$3,_翻訳マスタ!$B$1:$D$1,0)),IF(J6-TODAY()<=7,INDEX(_翻訳マスタ!$B$91:$D$91,1,MATCH(言語切替!$B$3,_翻訳マスタ!$B$1:$D$1,0)),INDEX(_翻訳マスタ!$B$90:$D$90,1,MATCH(言語切替!$B$3,_翻訳マスタ!$B$1:$D$1,0)))))) -> Đúng tiến độ | R6: =INDEX(_翻訳マスタ!$D$2:$D$300,MATCH("COMMON_EXAMPLE",_翻訳マスタ!$A$2:$A$300,0)) -> Ví dụ nhập liệu | S6: =IF(R6="","",_xlfn.TRANSLATE(R6,"","ja")) -> #VALUE! | T6: =IF(R6="","",_xlfn.TRANSLATE(R6,"","zh-Hans")) -> #VALUE!
A7: WBS-003 | B7: WG-8 | C7: ='02_マスタ'!$C$5 -> Chung | D7: =INDEX(_翻訳マスタ!$B$117:$D$247,MATCH("WBS_CAT_POLICY",_翻訳マスタ!$A$117:$A$247,0),MATCH(言語切替!$B$3,_翻訳マスタ!$B$1:$D$1,0)) -> Xây dựng định hướng | E7: =INDEX(_翻訳マスタ!$D$2:$D$300,MATCH("WBS_TASK_3",_翻訳マスタ!$A$2:$A$300,0)) -> Sắp xếp vai trò hệ thống hiện hữu | F7: =IF(E7="","",_xlfn.TRANSLATE(E7,"","ja")) -> #VALUE! | G7: =IF(E7="","",_xlfn.TRANSLATE(E7,"","zh-Hans")) -> #VALUE! | H7: WG Leader | I7: 46296 | J7: 46325 | M7: =IF(OR(I7="",J7=""),"",IF(L7<>"",1,IF(K7="",0,MAX(0,MIN(1,(TODAY()-I7)/(J7-I7+1)))))) -> 0 | N7: ='02_マスタ'!$E$5 -> Chưa bắt đầu | O7: =IF(J7="","",J7-TODAY()) -> 30 | P7: =IF(J7="","",IF(L7<>"",INDEX(_翻訳マスタ!$B$75:$D$75,1,MATCH(言語切替!$B$3,_翻訳マスタ!$B$1:$D$1,0)),IF(TODAY()>J7,INDEX(_翻訳マスタ!$B$92:$D$92,1,MATCH(言語切替!$B$3,_翻訳マスタ!$B$1:$D$1,0)),IF(J7-TODAY()<=7,INDEX(_翻訳マスタ!$B$91:$D$91,1,MATCH(言語切替!$B$3,_翻訳マスタ!$B$1:$D$1,0)),INDEX(_翻訳マスタ!$B$90:$D$90,1,MATCH(言語切替!$B$3,_翻訳マスタ!$B$1:$D$1,0)))))) -> Đúng tiến độ | R7: =INDEX(_翻訳マスタ!$D$2:$D$300,MATCH("COMMON_EXAMPLE",_翻訳マスタ!$A$2:$A$300,0)) -> Ví dụ nhập liệu | S7: =IF(R7="","",_xlfn.TRANSLATE(R7,"","ja")) -> #VALUE! | T7: =IF(R7="","",_xlfn.TRANSLATE(R7,"","zh-Hans")) -> #VALUE!
F8: =IF(E8="","",_xlfn.TRANSLATE(E8,"","ja")) | G8: =IF(E8="","",_xlfn.TRANSLATE(E8,"","zh-Hans")) | M8: =IF(OR(I8="",J8=""),"",IF(L8<>"",1,IF(K8="",0,MAX(0,MIN(1,(TODAY()-I8)/(J8-I8+1)))))) | O8: =IF(J8="","",J8-TODAY()) | P8: =IF(J8="","",IF(L8<>"",INDEX(_翻訳マスタ!$B$75:$D$75,1,MATCH(言語切替!$B$3,_翻訳マスタ!$B$1:$D$1,0)),IF(TODAY()>J8,INDEX(_翻訳マスタ!$B$92:$D$92,1,MATCH(言語切替!$B$3,_翻訳マスタ!$B$1:$D$1,0)),IF(J8-TODAY()<=7,INDEX(_翻訳マスタ!$B$91:$D$91,1,MATCH(言語切替!$B$3,_翻訳マスタ!$B$1:$D$1,0)),INDEX(_翻訳マスタ!$B$90:$D$90,1,MATCH(言語切替!$B$3,_翻訳マスタ!$B$1:$D$1,0)))))) | S8: =IF(R8="","",_xlfn.TRANSLATE(R8,"","ja")) | T8: =IF(R8="","",_xlfn.TRANSLATE(R8,"","zh-Hans"))
F9: =IF(E9="","",_xlfn.TRANSLATE(E9,"","ja")) | G9: =IF(E9="","",_xlfn.TRANSLATE(E9,"","zh-Hans")) | M9: =IF(OR(I9="",J9=""),"",IF(L9<>"",1,IF(K9="",0,MAX(0,MIN(1,(TODAY()-I9)/(J9-I9+1)))))) | O9: =IF(J9="","",J9-TODAY()) | P9: =IF(J9="","",IF(L9<>"",INDEX(_翻訳マスタ!$B$75:$D$75,1,MATCH(言語切替!$B$3,_翻訳マスタ!$B$1:$D$1,0)),IF(TODAY()>J9,INDEX(_翻訳マスタ!$B$92:$D$92,1,MATCH(言語切替!$B$3,_翻訳マスタ!$B$1:$D$1,0)),IF(J9-TODAY()<=7,INDEX(_翻訳マスタ!$B$91:$D$91,1,MATCH(言語切替!$B$3,_翻訳マスタ!$B$1:$D$1,0)),INDEX(_翻訳マスタ!$B$90:$D$90,1,MATCH(言語切替!$B$3,_翻訳マスタ!$B$1:$D$1,0)))))) | S9: =IF(R9="","",_xlfn.TRANSLATE(R9,"","ja")) | T9: =IF(R9="","",_xlfn.TRANSLATE(R9,"","zh-Hans"))
F10: =IF(E10="","",_xlfn.TRANSLATE(E10,"","ja")) | G10: =IF(E10="","",_xlfn.TRANSLATE(E10,"","zh-Hans")) | M10: =IF(OR(I10="",J10=""),"",IF(L10<>"",1,IF(K10="",0,MAX(0,MIN(1,(TODAY()-I10)/(J10-I10+1)))))) | O10: =IF(J10="","",J10-TODAY()) | P10: =IF(J10="","",IF(L10<>"",INDEX(_翻訳マスタ!$B$75:$D$75,1,MATCH(言語切替!$B$3,_翻訳マスタ!$B$1:$D$1,0)),IF(TODAY()>J10,INDEX(_翻訳マスタ!$B$92:$D$92,1,MATCH(言語切替!$B$3,_翻訳マスタ!$B$1:$D$1,0)),IF(J10-TODAY()<=7,INDEX(_翻訳マスタ!$B$91:$D$91,1,MATCH(言語切替!$B$3,_翻訳マスタ!$B$1:$D$1,0)),INDEX(_翻訳マスタ!$B$90:$D$90,1,MATCH(言語切替!$B$3,_翻訳マスタ!$B$1:$D$1,0)))))) | S10: =IF(R10="","",_xlfn.TRANSLATE(R10,"","ja")) | T10: =IF(R10="","",_xlfn.TRANSLATE(R10,"","zh-Hans"))
F11: =IF(E11="","",_xlfn.TRANSLATE(E11,"","ja")) | G11: =IF(E11="","",_xlfn.TRANSLATE(E11,"","zh-Hans")) | M11: =IF(OR(I11="",J11=""),"",IF(L11<>"",1,IF(K11="",0,MAX(0,MIN(1,(TODAY()-I11)/(J11-I11+1)))))) | O11: =IF(J11="","",J11-TODAY()) | P11: =IF(J11="","",IF(L11<>"",INDEX(_翻訳マスタ!$B$75:$D$75,1,MATCH(言語切替!$B$3,_翻訳マスタ!$B$1:$D$1,0)),IF(TODAY()>J11,INDEX(_翻訳マスタ!$B$92:$D$92,1,MATCH(言語切替!$B$3,_翻訳マスタ!$B$1:$D$1,0)),IF(J11-TODAY()<=7,INDEX(_翻訳マスタ!$B$91:$D$91,1,MATCH(言語切替!$B$3,_翻訳マスタ!$B$1:$D$1,0)),INDEX(_翻訳マスタ!$B$90:$D$90,1,MATCH(言語切替!$B$3,_翻訳マスタ!$B$1:$D$1,0)))))) | S11: =IF(R11="","",_xlfn.TRANSLATE(R11,"","ja")) | T11: =IF(R11="","",_xlfn.TRANSLATE(R11,"","zh-Hans"))
F12: =IF(E12="","",_xlfn.TRANSLATE(E12,"","ja")) | G12: =IF(E12="","",_xlfn.TRANSLATE(E12,"","zh-Hans")) | M12: =IF(OR(I12="",J12=""),"",IF(L12<>"",1,IF(K12="",0,MAX(0,MIN(1,(TODAY()-I12)/(J12-I12+1)))))) | O12: =IF(J12="","",J12-TODAY()) | P12: =IF(J12="","",IF(L12<>"",INDEX(_翻訳マスタ!$B$75:$D$75,1,MATCH(言語切替!$B$3,_翻訳マスタ!$B$1:$D$1,0)),IF(TODAY()>J12,INDEX(_翻訳マスタ!$B$92:$D$92,1,MATCH(言語切替!$B$3,_翻訳マスタ!$B$1:$D$1,0)),IF(J12-TODAY()<=7,INDEX(_翻訳マスタ!$B$91:$D$91,1,MATCH(言語切替!$B$3,_翻訳マスタ!$B$1:$D$1,0)),INDEX(_翻訳マスタ!$B$90:$D$90,1,MATCH(言語切替!$B$3,_翻訳マスタ!$B$1:$D$1,0)))))) | S12: =IF(R12="","",_xlfn.TRANSLATE(R12,"","ja")) | T12: =IF(R12="","",_xlfn.TRANSLATE(R12,"","zh-Hans"))
F13: =IF(E13="","",_xlfn.TRANSLATE(E13,"","ja")) | G13: =IF(E13="","",_xlfn.TRANSLATE(E13,"","zh-Hans")) | M13: =IF(OR(I13="",J13=""),"",IF(L13<>"",1,IF(K13="",0,MAX(0,MIN(1,(TODAY()-I13)/(J13-I13+1)))))) | O13: =IF(J13="","",J13-TODAY()) | P13: =IF(J13="","",IF(L13<>"",INDEX(_翻訳マスタ!$B$75:$D$75,1,MATCH(言語切替!$B$3,_翻訳マスタ!$B$1:$D$1,0)),IF(TODAY()>J13,INDEX(_翻訳マスタ!$B$92:$D$92,1,MATCH(言語切替!$B$3,_翻訳マスタ!$B$1:$D$1,0)),IF(J13-TODAY()<=7,INDEX(_翻訳マスタ!$B$91:$D$91,1,MATCH(言語切替!$B$3,_翻訳マスタ!$B$1:$D$1,0)),INDEX(_翻訳マスタ!$B$90:$D$90,1,MATCH(言語切替!$B$3,_翻訳マスタ!$B$1:$D$1,0)))))) | S13: =IF(R13="","",_xlfn.TRANSLATE(R13,"","ja")) | T13: =IF(R13="","",_xlfn.TRANSLATE(R13,"","zh-Hans"))
F14: =IF(E14="","",_xlfn.TRANSLATE(E14,"","ja")) | G14: =IF(E14="","",_xlfn.TRANSLATE(E14,"","zh-Hans")) | M14: =IF(OR(I14="",J14=""),"",IF(L14<>"",1,IF(K14="",0,MAX(0,MIN(1,(TODAY()-I14)/(J14-I14+1)))))) | O14: =IF(J14="","",J14-TODAY()) | P14: =IF(J14="","",IF(L14<>"",INDEX(_翻訳マスタ!$B$75:$D$75,1,MATCH(言語切替!$B$3,_翻訳マスタ!$B$1:$D$1,0)),IF(TODAY()>J14,INDEX(_翻訳マスタ!$B$92:$D$92,1,MATCH(言語切替!$B$3,_翻訳マスタ!$B$1:$D$1,0)),IF(J14-TODAY()<=7,INDEX(_翻訳マスタ!$B$91:$D$91,1,MATCH(言語切替!$B$3,_翻訳マスタ!$B$1:$D$1,0)),INDEX(_翻訳マスタ!$B$90:$D$90,1,MATCH(言語切替!$B$3,_翻訳マスタ!$B$1:$D$1,0)))))) | S14: =IF(R14="","",_xlfn.TRANSLATE(R14,"","ja")) | T14: =IF(R14="","",_xlfn.TRANSLATE(R14,"","zh-Hans"))
F15: =IF(E15="","",_xlfn.TRANSLATE(E15,"","ja")) | G15: =IF(E15="","",_xlfn.TRANSLATE(E15,"","zh-Hans")) | M15: =IF(OR(I15="",J15=""),"",IF(L15<>"",1,IF(K15="",0,MAX(0,MIN(1,(TODAY()-I15)/(J15-I15+1)))))) | O15: =IF(J15="","",J15-TODAY()) | P15: =IF(J15="","",IF(L15<>"",INDEX(_翻訳マスタ!$B$75:$D$75,1,MATCH(言語切替!$B$3,_翻訳マスタ!$B$1:$D$1,0)),IF(TODAY()>J15,INDEX(_翻訳マスタ!$B$92:$D$92,1,MATCH(言語切替!$B$3,_翻訳マスタ!$B$1:$D$1,0)),IF(J15-TODAY()<=7,INDEX(_翻訳マスタ!$B$91:$D$91,1,MATCH(言語切替!$B$3,_翻訳マスタ!$B$1:$D$1,0)),INDEX(_翻訳マスタ!$B$90:$D$90,1,MATCH(言語切替!$B$3,_翻訳マスタ!$B$1:$D$1,0)))))) | S15: =IF(R15="","",_xlfn.TRANSLATE(R15,"","ja")) | T15: =IF(R15="","",_xlfn.TRANSLATE(R15,"","zh-Hans"))
F16: =IF(E16="","",_xlfn.TRANSLATE(E16,"","ja")) | G16: =IF(E16="","",_xlfn.TRANSLATE(E16,"","zh-Hans")) | M16: =IF(OR(I16="",J16=""),"",IF(L16<>"",1,IF(K16="",0,MAX(0,MIN(1,(TODAY()-I16)/(J16-I16+1)))))) | O16: =IF(J16="","",J16-TODAY()) | P16: =IF(J16="","",IF(L16<>"",INDEX(_翻訳マスタ!$B$75:$D$75,1,MATCH(言語切替!$B$3,_翻訳マスタ!$B$1:$D$1,0)),IF(TODAY()>J16,INDEX(_翻訳マスタ!$B$92:$D$92,1,MATCH(言語切替!$B$3,_翻訳マスタ!$B$1:$D$1,0)),IF(J16-TODAY()<=7,INDEX(_翻訳マスタ!$B$91:$D$91,1,MATCH(言語切替!$B$3,_翻訳マスタ!$B$1:$D$1,0)),INDEX(_翻訳マスタ!$B$90:$D$90,1,MATCH(言語切替!$B$3,_翻訳マスタ!$B$1:$D$1,0)))))) | S16: =IF(R16="","",_xlfn.TRANSLATE(R16,"","ja")) | T16: =IF(R16="","",_xlfn.TRANSLATE(R16,"","zh-Hans"))
F17: =IF(E17="","",_xlfn.TRANSLATE(E17,"","ja")) | G17: =IF(E17="","",_xlfn.TRANSLATE(E17,"","zh-Hans")) | M17: =IF(OR(I17="",J17=""),"",IF(L17<>"",1,IF(K17="",0,MAX(0,MIN(1,(TODAY()-I17)/(J17-I17+1)))))) | O17: =IF(J17="","",J17-TODAY()) | P17: =IF(J17="","",IF(L17<>"",INDEX(_翻訳マスタ!$B$75:$D$75,1,MATCH(言語切替!$B$3,_翻訳マスタ!$B$1:$D$1,0)),IF(TODAY()>J17,INDEX(_翻訳マスタ!$B$92:$D$92,1,MATCH(言語切替!$B$3,_翻訳マスタ!$B$1:$D$1,0)),IF(J17-TODAY()<=7,INDEX(_翻訳マスタ!$B$91:$D$91,1,MATCH(言語切替!$B$3,_翻訳マスタ!$B$1:$D$1,0)),INDEX(_翻訳マスタ!$B$90:$D$90,1,MATCH(言語切替!$B$3,_翻訳マスタ!$B$1:$D$1,0)))))) | S17: =IF(R17="","",_xlfn.TRANSLATE(R17,"","ja")) | T17: =IF(R17="","",_xlfn.TRANSLATE(R17,"","zh-Hans"))
F18: =IF(E18="","",_xlfn.TRANSLATE(E18,"","ja")) | G18: =IF(E18="","",_xlfn.TRANSLATE(E18,"","zh-Hans")) | M18: =IF(OR(I18="",J18=""),"",IF(L18<>"",1,IF(K18="",0,MAX(0,MIN(1,(TODAY()-I18)/(J18-I18+1)))))) | O18: =IF(J18="","",J18-TODAY()) | P18: =IF(J18="","",IF(L18<>"",INDEX(_翻訳マスタ!$B$75:$D$75,1,MATCH(言語切替!$B$3,_翻訳マスタ!$B$1:$D$1,0)),IF(TODAY()>J18,INDEX(_翻訳マスタ!$B$92:$D$92,1,MATCH(言語切替!$B$3,_翻訳マスタ!$B$1:$D$1,0)),IF(J18-TODAY()<=7,INDEX(_翻訳マスタ!$B$91:$D$91,1,MATCH(言語切替!$B$3,_翻訳マスタ!$B$1:$D$1,0)),INDEX(_翻訳マスタ!$B$90:$D$90,1,MATCH(言語切替!$B$3,_翻訳マスタ!$B$1:$D$1,0)))))) | S18: =IF(R18="","",_xlfn.TRANSLATE(R18,"","ja")) | T18: =IF(R18="","",_xlfn.TRANSLATE(R18,"","zh-Hans"))
F19: =IF(E19="","",_xlfn.TRANSLATE(E19,"","ja")) | G19: =IF(E19="","",_xlfn.TRANSLATE(E19,"","zh-Hans")) | M19: =IF(OR(I19="",J19=""),"",IF(L19<>"",1,IF(K19="",0,MAX(0,MIN(1,(TODAY()-I19)/(J19-I19+1)))))) | O19: =IF(J19="","",J19-TODAY()) | P19: =IF(J19="","",IF(L19<>"",INDEX(_翻訳マスタ!$B$75:$D$75,1,MATCH(言語切替!$B$3,_翻訳マスタ!$B$1:$D$1,0)),IF(TODAY()>J19,INDEX(_翻訳マスタ!$B$92:$D$92,1,MATCH(言語切替!$B$3,_翻訳マスタ!$B$1:$D$1,0)),IF(J19-TODAY()<=7,INDEX(_翻訳マスタ!$B$91:$D$91,1,MATCH(言語切替!$B$3,_翻訳マスタ!$B$1:$D$1,0)),INDEX(_翻訳マスタ!$B$90:$D$90,1,MATCH(言語切替!$B$3,_翻訳マスタ!$B$1:$D$1,0)))))) | S19: =IF(R19="","",_xlfn.TRANSLATE(R19,"","ja")) | T19: =IF(R19="","",_xlfn.TRANSLATE(R19,"","zh-Hans"))
... F24: =IF(E24="","",_xlfn.TRANSLATE(E24,"","ja")) | G24: =IF(E24="","",_xlfn.TRANSLATE(E24,"","zh-Hans")) | M24: =IF(OR(I24="",J24=""),"",IF(L24<>"",1,IF(K24="",0,MAX(0,MIN(1,(TODAY()-I24)/(J24-I24+1)))))) | O24: =IF(J24="","",J24-TODAY()) | P24: =IF(J24="","",IF(L24<>"",INDEX(_翻訳マスタ!$B$75:$D$75,1,MATCH(言語切替!$B$3,_翻訳マスタ!$B$1:$D$1,0)),IF(TODAY()>J24,INDEX(_翻訳マスタ!$B$92:$D$92,1,MATCH(言語切替!$B$3,_翻訳マスタ!$B$1:$D$1,0)),IF(J24-TODAY()<=7,INDEX(_翻訳マスタ!$B$91:$D$91,1,MATCH(言語切替!$B$3,_翻訳マスタ!$B$1:$D$1,0)),INDEX(_翻訳マスタ!$B$90:$D$90,1,MATCH(言語切替!$B$3,_翻訳マスタ!$B$1:$D$1,0)))))) | S24: =IF(R24="","",_xlfn.TRANSLATE(R24,"","ja")) | T24: =IF(R24="","",_xlfn.TRANSLATE(R24,"","zh-Hans"))
F25: =IF(E25="","",_xlfn.TRANSLATE(E25,"vi","ja")) | G25: =IF(E25="","",_xlfn.TRANSLATE(E25,"vi","zh-Hans")) | M25: =IF(OR(I25="",J25=""),"",IF(L25<>"",1,IF(K25="",0,MAX(0,MIN(1,(TODAY()-I25)/(J25-I25+1)))))) | O25: =IF(J25="","",J25-TODAY()) | P25: =IF(J25="","",IF(L25<>"",INDEX(_翻訳マスタ!$B$75:$D$75,1,MATCH(言語切替!$B$3,_翻訳マスタ!$B$1:$D$1,0)),IF(TODAY()>J25,INDEX(_翻訳マスタ!$B$92:$D$92,1,MATCH(言語切替!$B$3,_翻訳マスタ!$B$1:$D$1,0)),IF(J25-TODAY()<=7,INDEX(_翻訳マスタ!$B$91:$D$91,1,MATCH(言語切替!$B$3,_翻訳マスタ!$B$1:$D$1,0)),INDEX(_翻訳マスタ!$B$90:$D$90,1,MATCH(言語切替!$B$3,_翻訳マスタ!$B$1:$D$1,0)))))) | S25: =IF(R25="","",_xlfn.TRANSLATE(R25,"vi","ja")) | T25: =IF(R25="","",_xlfn.TRANSLATE(R25,"vi","zh-Hans"))
F26: =IF(E26="","",_xlfn.TRANSLATE(E26,"vi","ja")) | G26: =IF(E26="","",_xlfn.TRANSLATE(E26,"vi","zh-Hans")) | M26: =IF(OR(I26="",J26=""),"",IF(L26<>"",1,IF(K26="",0,MAX(0,MIN(1,(TODAY()-I26)/(J26-I26+1)))))) | O26: =IF(J26="","",J26-TODAY()) | P26: =IF(J26="","",IF(L26<>"",INDEX(_翻訳マスタ!$B$75:$D$75,1,MATCH(言語切替!$B$3,_翻訳マスタ!$B$1:$D$1,0)),IF(TODAY()>J26,INDEX(_翻訳マスタ!$B$92:$D$92,1,MATCH(言語切替!$B$3,_翻訳マスタ!$B$1:$D$1,0)),IF(J26-TODAY()<=7,INDEX(_翻訳マスタ!$B$91:$D$91,1,MATCH(言語切替!$B$3,_翻訳マスタ!$B$1:$D$1,0)),INDEX(_翻訳マスタ!$B$90:$D$90,1,MATCH(言語切替!$B$3,_翻訳マスタ!$B$1:$D$1,0)))))) | S26: =IF(R26="","",_xlfn.TRANSLATE(R26,"vi","ja")) | T26: =IF(R26="","",_xlfn.TRANSLATE(R26,"vi","zh-Hans"))
F27: =IF(E27="","",_xlfn.TRANSLATE(E27,"vi","ja")) | G27: =IF(E27="","",_xlfn.TRANSLATE(E27,"vi","zh-Hans")) | M27: =IF(OR(I27="",J27=""),"",IF(L27<>"",1,IF(K27="",0,MAX(0,MIN(1,(TODAY()-I27)/(J27-I27+1)))))) | O27: =IF(J27="","",J27-TODAY()) | P27: =IF(J27="","",IF(L27<>"",INDEX(_翻訳マスタ!$B$75:$D$75,1,MATCH(言語切替!$B$3,_翻訳マスタ!$B$1:$D$1,0)),IF(TODAY()>J27,INDEX(_翻訳マスタ!$B$92:$D$92,1,MATCH(言語切替!$B$3,_翻訳マスタ!$B$1:$D$1,0)),IF(J27-TODAY()<=7,INDEX(_翻訳マスタ!$B$91:$D$91,1,MATCH(言語切替!$B$3,_翻訳マスタ!$B$1:$D$1,0)),INDEX(_翻訳マスタ!$B$90:$D$90,1,MATCH(言語切替!$B$3,_翻訳マスタ!$B$1:$D$1,0)))))) | S27: =IF(R27="","",_xlfn.TRANSLATE(R27,"vi","ja")) | T27: =IF(R27="","",_xlfn.TRANSLATE(R27,"vi","zh-Hans"))
F28: =IF(E28="","",_xlfn.TRANSLATE(E28,"vi","ja")) | G28: =IF(E28="","",_xlfn.TRANSLATE(E28,"vi","zh-Hans")) | M28: =IF(OR(I28="",J28=""),"",IF(L28<>"",1,IF(K28="",0,MAX(0,MIN(1,(TODAY()-I28)/(J28-I28+1)))))) | O28: =IF(J28="","",J28-TODAY()) | P28: =IF(J28="","",IF(L28<>"",INDEX(_翻訳マスタ!$B$75:$D$75,1,MATCH(言語切替!$B$3,_翻訳マスタ!$B$1:$D$1,0)),IF(TODAY()>J28,INDEX(_翻訳マスタ!$B$92:$D$92,1,MATCH(言語切替!$B$3,_翻訳マスタ!$B$1:$D$1,0)),IF(J28-TODAY()<=7,INDEX(_翻訳マスタ!$B$91:$D$91,1,MATCH(言語切替!$B$3,_翻訳マスタ!$B$1:$D$1,0)),INDEX(_翻訳マスタ!$B$90:$D$90,1,MATCH(言語切替!$B$3,_翻訳マスタ!$B$1:$D$1,0)))))) | S28: =IF(R28="","",_xlfn.TRANSLATE(R28,"vi","ja")) | T28: =IF(R28="","",_xlfn.TRANSLATE(R28,"vi","zh-Hans"))
F29: =IF(E29="","",_xlfn.TRANSLATE(E29,"vi","ja")) | G29: =IF(E29="","",_xlfn.TRANSLATE(E29,"vi","zh-Hans")) | M29: =IF(OR(I29="",J29=""),"",IF(L29<>"",1,IF(K29="",0,MAX(0,MIN(1,(TODAY()-I29)/(J29-I29+1)))))) | O29: =IF(J29="","",J29-TODAY()) | P29: =IF(J29="","",IF(L29<>"",INDEX(_翻訳マスタ!$B$75:$D$75,1,MATCH(言語切替!$B$3,_翻訳マスタ!$B$1:$D$1,0)),IF(TODAY()>J29,INDEX(_翻訳マスタ!$B$92:$D$92,1,MATCH(言語切替!$B$3,_翻訳マスタ!$B$1:$D$1,0)),IF(J29-TODAY()<=7,INDEX(_翻訳マスタ!$B$91:$D$91,1,MATCH(言語切替!$B$3,_翻訳マスタ!$B$1:$D$1,0)),INDEX(_翻訳マスタ!$B$90:$D$90,1,MATCH(言語切替!$B$3,_翻訳マスタ!$B$1:$D$1,0)))))) | S29: =IF(R29="","",_xlfn.TRANSLATE(R29,"vi","ja")) | T29: =IF(R29="","",_xlfn.TRANSLATE(R29,"vi","zh-Hans"))
F30: =IF(E30="","",_xlfn.TRANSLATE(E30,"vi","ja")) | G30: =IF(E30="","",_xlfn.TRANSLATE(E30,"vi","zh-Hans")) | M30: =IF(OR(I30="",J30=""),"",IF(L30<>"",1,IF(K30="",0,MAX(0,MIN(1,(TODAY()-I30)/(J30-I30+1)))))) | O30: =IF(J30="","",J30-TODAY()) | P30: =IF(J30="","",IF(L30<>"",INDEX(_翻訳マスタ!$B$75:$D$75,1,MATCH(言語切替!$B$3,_翻訳マスタ!$B$1:$D$1,0)),IF(TODAY()>J30,INDEX(_翻訳マスタ!$B$92:$D$92,1,MATCH(言語切替!$B$3,_翻訳マスタ!$B$1:$D$1,0)),IF(J30-TODAY()<=7,INDEX(_翻訳マスタ!$B$91:$D$91,1,MATCH(言語切替!$B$3,_翻訳マスタ!$B$1:$D$1,0)),INDEX(_翻訳マスタ!$B$90:$D$90,1,MATCH(言語切替!$B$3,_翻訳マスタ!$B$1:$D$1,0)))))) | S30: =IF(R30="","",_xlfn.TRANSLATE(R30,"vi","ja")) | T30: =IF(R30="","",_xlfn.TRANSLATE(R30,"vi","zh-Hans"))
F31: =IF(E31="","",_xlfn.TRANSLATE(E31,"vi","ja")) | G31: =IF(E31="","",_xlfn.TRANSLATE(E31,"vi","zh-Hans")) | M31: =IF(OR(I31="",J31=""),"",IF(L31<>"",1,IF(K31="",0,MAX(0,MIN(1,(TODAY()-I31)/(J31-I31+1)))))) | O31: =IF(J31="","",J31-TODAY()) | P31: =IF(J31="","",IF(L31<>"",INDEX(_翻訳マスタ!$B$75:$D$75,1,MATCH(言語切替!$B$3,_翻訳マスタ!$B$1:$D$1,0)),IF(TODAY()>J31,INDEX(_翻訳マスタ!$B$92:$D$92,1,MATCH(言語切替!$B$3,_翻訳マスタ!$B$1:$D$1,0)),IF(J31-TODAY()<=7,INDEX(_翻訳マスタ!$B$91:$D$91,1,MATCH(言語切替!$B$3,_翻訳マスタ!$B$1:$D$1,0)),INDEX(_翻訳マスタ!$B$90:$D$90,1,MATCH(言語切替!$B$3,_翻訳マスタ!$B$1:$D$1,0)))))) | S31: =IF(R31="","",_xlfn.TRANSLATE(R31,"vi","ja")) | T31: =IF(R31="","",_xlfn.TRANSLATE(R31,"vi","zh-Hans"))
F32: =IF(E32="","",_xlfn.TRANSLATE(E32,"vi","ja")) | G32: =IF(E32="","",_xlfn.TRANSLATE(E32,"vi","zh-Hans")) | M32: =IF(OR(I32="",J32=""),"",IF(L32<>"",1,IF(K32="",0,MAX(0,MIN(1,(TODAY()-I32)/(J32-I32+1)))))) | O32: =IF(J32="","",J32-TODAY()) | P32: =IF(J32="","",IF(L32<>"",INDEX(_翻訳マスタ!$B$75:$D$75,1,MATCH(言語切替!$B$3,_翻訳マスタ!$B$1:$D$1,0)),IF(TODAY()>J32,INDEX(_翻訳マスタ!$B$92:$D$92,1,MATCH(言語切替!$B$3,_翻訳マスタ!$B$1:$D$1,0)),IF(J32-TODAY()<=7,INDEX(_翻訳マスタ!$B$91:$D$91,1,MATCH(言語切替!$B$3,_翻訳マスタ!$B$1:$D$1,0)),INDEX(_翻訳マスタ!$B$90:$D$90,1,MATCH(言語切替!$B$3,_翻訳マスタ!$B$1:$D$1,0)))))) | S32: =IF(R32="","",_xlfn.TRANSLATE(R32,"vi","ja")) | T32: =IF(R32="","",_xlfn.TRANSLATE(R32,"vi","zh-Hans"))
F33: =IF(E33="","",_xlfn.TRANSLATE(E33,"vi","ja")) | G33: =IF(E33="","",_xlfn.TRANSLATE(E33,"vi","zh-Hans")) | M33: =IF(OR(I33="",J33=""),"",IF(L33<>"",1,IF(K33="",0,MAX(0,MIN(1,(TODAY()-I33)/(J33-I33+1)))))) | O33: =IF(J33="","",J33-TODAY()) | P33: =IF(J33="","",IF(L33<>"",INDEX(_翻訳マスタ!$B$75:$D$75,1,MATCH(言語切替!$B$3,_翻訳マスタ!$B$1:$D$1,0)),IF(TODAY()>J33,INDEX(_翻訳マスタ!$B$92:$D$92,1,MATCH(言語切替!$B$3,_翻訳マスタ!$B$1:$D$1,0)),IF(J33-TODAY()<=7,INDEX(_翻訳マスタ!$B$91:$D$91,1,MATCH(言語切替!$B$3,_翻訳マスタ!$B$1:$D$1,0)),INDEX(_翻訳マスタ!$B$90:$D$90,1,MATCH(言語切替!$B$3,_翻訳マスタ!$B$1:$D$1,0)))))) | S33: =IF(R33="","",_xlfn.TRANSLATE(R33,"vi","ja")) | T33: =IF(R33="","",_xlfn.TRANSLATE(R33,"vi","zh-Hans"))
F34: =IF(E34="","",_xlfn.TRANSLATE(E34,"vi","ja")) | G34: =IF(E34="","",_xlfn.TRANSLATE(E34,"vi","zh-Hans")) | M34: =IF(OR(I34="",J34=""),"",IF(L34<>"",1,IF(K34="",0,MAX(0,MIN(1,(TODAY()-I34)/(J34-I34+1)))))) | O34: =IF(J34="","",J34-TODAY()) | P34: =IF(J34="","",IF(L34<>"",INDEX(_翻訳マスタ!$B$75:$D$75,1,MATCH(言語切替!$B$3,_翻訳マスタ!$B$1:$D$1,0)),IF(TODAY()>J34,INDEX(_翻訳マスタ!$B$92:$D$92,1,MATCH(言語切替!$B$3,_翻訳マスタ!$B$1:$D$1,0)),IF(J34-TODAY()<=7,INDEX(_翻訳マスタ!$B$91:$D$91,1,MATCH(言語切替!$B$3,_翻訳マスタ!$B$1:$D$1,0)),INDEX(_翻訳マスタ!$B$90:$D$90,1,MATCH(言語切替!$B$3,_翻訳マスタ!$B$1:$D$1,0)))))) | S34: =IF(R34="","",_xlfn.TRANSLATE(R34,"vi","ja")) | T34: =IF(R34="","",_xlfn.TRANSLATE(R34,"vi","zh-Hans"))
F35: =IF(E35="","",_xlfn.TRANSLATE(E35,"vi","ja")) | G35: =IF(E35="","",_xlfn.TRANSLATE(E35,"vi","zh-Hans")) | M35: =IF(OR(I35="",J35=""),"",IF(L35<>"",1,IF(K35="",0,MAX(0,MIN(1,(TODAY()-I35)/(J35-I35+1)))))) | O35: =IF(J35="","",J35-TODAY()) | P35: =IF(J35="","",IF(L35<>"",INDEX(_翻訳マスタ!$B$75:$D$75,1,MATCH(言語切替!$B$3,_翻訳マスタ!$B$1:$D$1,0)),IF(TODAY()>J35,INDEX(_翻訳マスタ!$B$92:$D$92,1,MATCH(言語切替!$B$3,_翻訳マスタ!$B$1:$D$1,0)),IF(J35-TODAY()<=7,INDEX(_翻訳マスタ!$B$91:$D$91,1,MATCH(言語切替!$B$3,_翻訳マスタ!$B$1:$D$1,0)),INDEX(_翻訳マスタ!$B$90:$D$90,1,MATCH(言語切替!$B$3,_翻訳マスタ!$B$1:$D$1,0)))))) | S35: =IF(R35="","",_xlfn.TRANSLATE(R35,"vi","ja")) | T35: =IF(R35="","",_xlfn.TRANSLATE(R35,"vi","zh-Hans"))
F36: =IF(E36="","",_xlfn.TRANSLATE(E36,"vi","ja")) | G36: =IF(E36="","",_xlfn.TRANSLATE(E36,"vi","zh-Hans")) | M36: =IF(OR(I36="",J36=""),"",IF(L36<>"",1,IF(K36="",0,MAX(0,MIN(1,(TODAY()-I36)/(J36-I36+1)))))) | O36: =IF(J36="","",J36-TODAY()) | P36: =IF(J36="","",IF(L36<>"",INDEX(_翻訳マスタ!$B$75:$D$75,1,MATCH(言語切替!$B$3,_翻訳マスタ!$B$1:$D$1,0)),IF(TODAY()>J36,INDEX(_翻訳マスタ!$B$92:$D$92,1,MATCH(言語切替!$B$3,_翻訳マスタ!$B$1:$D$1,0)),IF(J36-TODAY()<=7,INDEX(_翻訳マスタ!$B$91:$D$91,1,MATCH(言語切替!$B$3,_翻訳マスタ!$B$1:$D$1,0)),INDEX(_翻訳マスタ!$B$90:$D$90,1,MATCH(言語切替!$B$3,_翻訳マスタ!$B$1:$D$1,0)))))) | S36: =IF(R36="","",_xlfn.TRANSLATE(R36,"vi","ja")) | T36: =IF(R36="","",_xlfn.TRANSLATE(R36,"vi","zh-Hans"))
... F204: =IF(E204="","",_xlfn.TRANSLATE(E204,"vi","ja")) | G204: =IF(E204="","",_xlfn.TRANSLATE(E204,"vi","zh-Hans")) | M204: =IF(OR(I204="",J204=""),"",IF(L204<>"",1,IF(K204="",0,MAX(0,MIN(1,(TODAY()-I204)/(J204-I204+1)))))) | O204: =IF(J204="","",J204-TODAY()) | P204: =IF(J204="","",IF(L204<>"",INDEX(_翻訳マスタ!$B$75:$D$75,1,MATCH(言語切替!$B$3,_翻訳マスタ!$B$1:$D$1,0)),IF(TODAY()>J204,INDEX(_翻訳マスタ!$B$92:$D$92,1,MATCH(言語切替!$B$3,_翻訳マスタ!$B$1:$D$1,0)),IF(J204-TODAY()<=7,INDEX(_翻訳マスタ!$B$91:$D$91,1,MATCH(言語切替!$B$3,_翻訳マスタ!$B$1:$D$1,0)),INDEX(_翻訳マスタ!$B$90:$D$90,1,MATCH(言語切替!$B$3,_翻訳マスタ!$B$1:$D$1,0)))))) | S204: =IF(R204="","",_xlfn.TRANSLATE(R204,"vi","ja")) | T204: =IF(R204="","",_xlfn.TRANSLATE(R204,"vi","zh-Hans"))

Sheet 04_課題ToDo
A1: =INDEX(_翻訳マスタ!$B$117:$D$247,MATCH("ISSUE_TITLE",_翻訳マスタ!$A$117:$A$247,0),MATCH(言語切替!$B$3,_翻訳マスタ!$B$1:$D$1,0)) -> Quản lý Vấn đề & ToDo
A2: =INDEX(_翻訳マスタ!$B$117:$D$247,MATCH("ISSUE_DESC",_翻訳マスタ!$A$117:$A$247,0),MATCH(言語切替!$B$3,_翻訳マスタ!$B$1:$D$1,0)) -> Quản lý tập trung vấn đề, ToDo, quyết định và rủi ro. Số ngày còn lại và cảnh báo được tính tự động. 4 dòng là ví dụ nhập liệu.
A3: =INDEX(_翻訳マスタ!$B$2:$D$300,MATCH("PARA_HOWTO",_翻訳マスタ!$A$2:$A$300,0),MATCH(言語切替!$B$3,_翻訳マスタ!$B$1:$D$1,0)) -> Cách dùng: Nhập tiếng mẹ đẻ → đọc cột khác → ô trống không dịch → dưới 3000 ký tự
A4: =INDEX(_翻訳マスタ!$B$117:$D$247,MATCH("ISSUE_COL_ID",_翻訳マスタ!$A$117:$A$247,0),MATCH(言語切替!$B$3,_翻訳マスタ!$B$1:$D$1,0)) -> ID | B4: =INDEX(_翻訳マスタ!$B$117:$D$247,MATCH("ISSUE_COL_TYPE",_翻訳マスタ!$A$117:$A$247,0),MATCH(言語切替!$B$3,_翻訳マスタ!$B$1:$D$1,0)) -> Phân loại | C4: =INDEX(_翻訳マスタ!$B$117:$D$247,MATCH("ISSUE_COL_WG",_翻訳マスタ!$A$117:$A$247,0),MATCH(言語切替!$B$3,_翻訳マスタ!$B$1:$D$1,0)) -> WG | D4: =INDEX(_翻訳マスタ!$B$117:$D$247,MATCH("ISSUE_COL_SITE",_翻訳マスタ!$A$117:$A$247,0),MATCH(言語切替!$B$3,_翻訳マスタ!$B$1:$D$1,0)) -> Đơn vị | E4: =INDEX(_翻訳マスタ!$B$2:$D$300,MATCH("ISSUE_COL_TITLE",_翻訳マスタ!$A$2:$A$300,0),MATCH(言語切替!$B$3,_翻訳マスタ!$B$1:$D$1,0))&INDEX(_翻訳マスタ!$B$2:$D$300,MATCH("NEW_VI_SUFFIX",_翻訳マスタ!$A$2:$A$300,0),MATCH(言語切替!$B$3,_翻訳マスタ!$B$1:$D$1,0)) -> Tiêu đề (VI) | F4: =INDEX(_翻訳マスタ!$B$2:$D$300,MATCH("ISSUE_COL_TITLE",_翻訳マスタ!$A$2:$A$300,0),MATCH(言語切替!$B$3,_翻訳マスタ!$B$1:$D$1,0))&INDEX(_翻訳マスタ!$B$2:$D$300,MATCH("NEW_JP_SUFFIX",_翻訳マスタ!$A$2:$A$300,0),MATCH(言語切替!$B$3,_翻訳マスタ!$B$1:$D$1,0)) -> Tiêu đề (JP) | G4: =INDEX(_翻訳マスタ!$B$2:$D$300,MATCH("ISSUE_COL_TITLE",_翻訳マスタ!$A$2:$A$300,0),MATCH(言語切替!$B$3,_翻訳マスタ!$B$1:$D$1,0))&INDEX(_翻訳マスタ!$B$2:$D$300,MATCH("NEW_CN_SUFFIX",_翻訳マスタ!$A$2:$A$300,0),MATCH(言語切替!$B$3,_翻訳マスタ!$B$1:$D$1,0)) -> Tiêu đề (CN) | H4: =INDEX(_翻訳マスタ!$B$2:$D$300,MATCH("ISSUE_COL_BG",_翻訳マスタ!$A$2:$A$300,0),MATCH(言語切替!$B$3,_翻訳マスタ!$B$1:$D$1,0))&INDEX(_翻訳マスタ!$B$2:$D$300,MATCH("NEW_VI_SUFFIX",_翻訳マスタ!$A$2:$A$300,0),MATCH(言語切替!$B$3,_翻訳マスタ!$B$1:$D$1,0)) -> Bối cảnh / Vấn đề (VI) | I4: =INDEX(_翻訳マスタ!$B$2:$D$300,MATCH("ISSUE_COL_BG",_翻訳マスタ!$A$2:$A$300,0),MATCH(言語切替!$B$3,_翻訳マスタ!$B$1:$D$1,0))&INDEX(_翻訳マスタ!$B$2:$D$300,MATCH("NEW_JP_SUFFIX",_翻訳マスタ!$A$2:$A$300,0),MATCH(言語切替!$B$3,_翻訳マスタ!$B$1:$D$1,0)) -> Bối cảnh / Vấn đề (JP) | J4: =INDEX(_翻訳マスタ!$B$2:$D$300,MATCH("ISSUE_COL_BG",_翻訳マスタ!$A$2:$A$300,0),MATCH(言語切替!$B$3,_翻訳マスタ!$B$1:$D$1,0))&INDEX(_翻訳マスタ!$B$2:$D$300,MATCH("NEW_CN_SUFFIX",_翻訳マスタ!$A$2:$A$300,0),MATCH(言語切替!$B$3,_翻訳マスタ!$B$1:$D$1,0)) -> Bối cảnh / Vấn đề (CN) | K4: =INDEX(_翻訳マスタ!$B$2:$D$300,MATCH("ISSUE_COL_ACTION",_翻訳マスタ!$A$2:$A$300,0),MATCH(言語切替!$B$3,_翻訳マスタ!$B$1:$D$1,0))&INDEX(_翻訳マスタ!$B$2:$D$300,MATCH("NEW_VI_SUFFIX",_翻訳マスタ!$A$2:$A$300,0),MATCH(言語切替!$B$3,_翻訳マスタ!$B$1:$D$1,0)) -> Hành động tiếp theo (VI) | L4: =INDEX(_翻訳マスタ!$B$2:$D$300,MATCH("ISSUE_COL_ACTION",_翻訳マスタ!$A$2:$A$300,0),MATCH(言語切替!$B$3,_翻訳マスタ!$B$1:$D$1,0))&INDEX(_翻訳マスタ!$B$2:$D$300,MATCH("NEW_JP_SUFFIX",_翻訳マスタ!$A$2:$A$300,0),MATCH(言語切替!$B$3,_翻訳マスタ!$B$1:$D$1,0)) -> Hành động tiếp theo (JP) | M4: =INDEX(_翻訳マスタ!$B$2:$D$300,MATCH("ISSUE_COL_ACTION",_翻訳マスタ!$A$2:$A$300,0),MATCH(言語切替!$B$3,_翻訳マスタ!$B$1:$D$1,0))&INDEX(_翻訳マスタ!$B$2:$D$300,MATCH("NEW_CN_SUFFIX",_翻訳マスタ!$A$2:$A$300,0),MATCH(言語切替!$B$3,_翻訳マスタ!$B$1:$D$1,0)) -> Hành động tiếp theo (CN) | N4: =INDEX(_翻訳マスタ!$B$117:$D$247,MATCH("ISSUE_COL_OWNER",_翻訳マスタ!$A$117:$A$247,0),MATCH(言語切替!$B$3,_翻訳マスタ!$B$1:$D$1,0)) -> Người phụ trách | O4: =INDEX(_翻訳マスタ!$B$117:$D$247,MATCH("ISSUE_COL_COOP",_翻訳マスタ!$A$117:$A$247,0),MATCH(言語切替!$B$3,_翻訳マスタ!$B$1:$D$1,0)) -> Người phối hợp | P4: =INDEX(_翻訳マスタ!$B$117:$D$247,MATCH("ISSUE_COL_START",_翻訳マスタ!$A$117:$A$247,0),MATCH(言語切替!$B$3,_翻訳マスタ!$B$1:$D$1,0)) -> Ngày tạo | Q4: =INDEX(_翻訳マスタ!$B$117:$D$247,MATCH("ISSUE_COL_DUE",_翻訳マスタ!$A$117:$A$247,0),MATCH(言語切替!$B$3,_翻訳マスタ!$B$1:$D$1,0)) -> Thời hạn | R4: =INDEX(_翻訳マスタ!$B$117:$D$247,MATCH("ISSUE_COL_PRIORITY",_翻訳マスタ!$A$117:$A$247,0),MATCH(言語切替!$B$3,_翻訳マスタ!$B$1:$D$1,0)) -> Mức ưu tiên | S4: =INDEX(_翻訳マスタ!$B$117:$D$247,MATCH("ISSUE_COL_STATUS",_翻訳マスタ!$A$117:$A$247,0),MATCH(言語切替!$B$3,_翻訳マスタ!$B$1:$D$1,0)) -> Trạng thái | T4: =INDEX(_翻訳マスタ!$B$117:$D$247,MATCH("ISSUE_COL_DEP",_翻訳マスタ!$A$117:$A$247,0),MATCH(言語切替!$B$3,_翻訳マスタ!$B$1:$D$1,0)) -> WG liên quan / Phụ thuộc | U4: =INDEX(_翻訳マスタ!$B$2:$D$300,MATCH("ISSUE_COL_COND",_翻訳マスタ!$A$2:$A$300,0),MATCH(言語切替!$B$3,_翻訳マスタ!$B$1:$D$1,0))&INDEX(_翻訳マスタ!$B$2:$D$300,MATCH("NEW_VI_SUFFIX",_翻訳マスタ!$A$2:$A$300,0),MATCH(言語切替!$B$3,_翻訳マスタ!$B$1:$D$1,0)) -> Điều kiện hoàn thành (VI) | V4: =INDEX(_翻訳マスタ!$B$2:$D$300,MATCH("ISSUE_COL_COND",_翻訳マスタ!$A$2:$A$300,0),MATCH(言語切替!$B$3,_翻訳マスタ!$B$1:$D$1,0))&INDEX(_翻訳マスタ!$B$2:$D$300,MATCH("NEW_JP_SUFFIX",_翻訳マスタ!$A$2:$A$300,0),MATCH(言語切替!$B$3,_翻訳マスタ!$B$1:$D$1,0)) -> Điều kiện hoàn thành (JP) | W4: =INDEX(_翻訳マスタ!$B$2:$D$300,MATCH("ISSUE_COL_COND",_翻訳マスタ!$A$2:$A$300,0),MATCH(言語切替!$B$3,_翻訳マスタ!$B$1:$D$1,0))&INDEX(_翻訳マスタ!$B$2:$D$300,MATCH("NEW_CN_SUFFIX",_翻訳マスタ!$A$2:$A$300,0),MATCH(言語切替!$B$3,_翻訳マスタ!$B$1:$D$1,0)) -> Điều kiện hoàn thành (CN) | X4: =INDEX(_翻訳マスタ!$B$2:$D$300,MATCH("ISSUE_COL_RESULT",_翻訳マスタ!$A$2:$A$300,0),MATCH(言語切替!$B$3,_翻訳マスタ!$B$1:$D$1,0))&INDEX(_翻訳マスタ!$B$2:$D$300,MATCH("NEW_VI_SUFFIX",_翻訳マスタ!$A$2:$A$300,0),MATCH(言語切替!$B$3,_翻訳マスタ!$B$1:$D$1,0)) -> Tình trạng xử lý / Kết luận (VI) | Y4: =INDEX(_翻訳マスタ!$B$2:$D$300,MATCH("ISSUE_COL_RESULT",_翻訳マスタ!$A$2:$A$300,0),MATCH(言語切替!$B$3,_翻訳マスタ!$B$1:$D$1,0))&INDEX(_翻訳マスタ!$B$2:$D$300,MATCH("NEW_JP_SUFFIX",_翻訳マスタ!$A$2:$A$300,0),MATCH(言語切替!$B$3,_翻訳マスタ!$B$1:$D$1,0)) -> Tình trạng xử lý / Kết luận (JP) | Z4: =INDEX(_翻訳マスタ!$B$2:$D$300,MATCH("ISSUE_COL_RESULT",_翻訳マスタ!$A$2:$A$300,0),MATCH(言語切替!$B$3,_翻訳マスタ!$B$1:$D$1,0))&INDEX(_翻訳マスタ!$B$2:$D$300,MATCH("NEW_CN_SUFFIX",_翻訳マスタ!$A$2:$A$300,0),MATCH(言語切替!$B$3,_翻訳マスタ!$B$1:$D$1,0)) -> Tình trạng xử lý / Kết luận (CN) | AA4: =INDEX(_翻訳マスタ!$B$117:$D$247,MATCH("ISSUE_COL_LINK",_翻訳マスタ!$A$117:$A$247,0),MATCH(言語切替!$B$3,_翻訳マスタ!$B$1:$D$1,0)) -> Liên kết liên quan | AB4: =INDEX(_翻訳マスタ!$B$117:$D$247,MATCH("ISSUE_COL_DAYS",_翻訳マスタ!$A$117:$A$247,0),MATCH(言語切替!$B$3,_翻訳マスタ!$B$1:$D$1,0)) -> Số ngày còn lại | AC4: =INDEX(_翻訳マスタ!$B$117:$D$247,MATCH("ISSUE_COL_ALERT",_翻訳マスタ!$A$117:$A$247,0),MATCH(言語切替!$B$3,_翻訳マスタ!$B$1:$D$1,0)) -> Cảnh báo | AD4: =INDEX(_翻訳マスタ!$B$117:$D$247,MATCH("ISSUE_COL_UPDATED",_翻訳マスタ!$A$117:$A$247,0),MATCH(言語切替!$B$3,_翻訳マスタ!$B$1:$D$1,0)) -> Ngày cập nhật cuối
