Workbook

Sheet 言語切替
A1: 言語切替 / 语言切换 / Chuyển ngôn ngữ
A3: 表示言語選んでください Chọn ngôn ngữ hiển thị | B3: Tiếng Việt
A6: Language code / Ma ngon ngu (TRANSLATE, do not edit)
A7: 日本語 | B7: ja
A8: 中文 | B8: zh-Hans
A9: Tiếng Việt | B9: vi

Sheet 00_運用ルール
A1: =INDEX(_翻訳マスタ!$B$2:$D$32,MATCH("TITLE",_翻訳マスタ!$A$2:$A$32,0),MATCH(言語切替!$B$3,_翻訳マスタ!$B$1:$D$1,0)) -> Công cụ quản lý Tiểu ban Nhà máy Thông minh
A2: =INDEX(_翻訳マスタ!$B$2:$D$32,MATCH("PURPOSE",_翻訳マスタ!$A$2:$A$32,0),MATCH(言語切替!$B$3,_翻訳マスタ!$B$1:$D$1,0)) -> Mục đích: Bản dự thảo đầu tiên nhằm quản lý kế hoạch, vấn đề, quyết định và KPI của 9 WG trong một chu trình quản lý thống nhất
A4: =INDEX(_翻訳マスタ!$B$2:$D$32,MATCH("PRINCIPLE_HEADER",_翻訳マスタ!$A$2:$A$32,0),MATCH(言語切替!$B$3,_翻訳マスタ!$B$1:$D$1,0)) -> 1. Nguyên tắc cơ bản | J4: =INDEX(_翻訳マスタ!$B$2:$D$32,MATCH("COL_SHEET",_翻訳マスタ!$A$2:$A$32,0),MATCH(言語切替!$B$3,_翻訳マスタ!$B$1:$D$1,0)) -> Trang tính | K4: =INDEX(_翻訳マスタ!$B$2:$D$32,MATCH("COL_USAGE",_翻訳マスタ!$A$2:$A$32,0),MATCH(言語切替!$B$3,_翻訳マスタ!$B$1:$D$1,0)) -> Mục đích sử dụng
A5: =INDEX(_翻訳マスタ!$B$2:$D$32,MATCH("P1",_翻訳マスタ!$A$2:$A$32,0),MATCH(言語切替!$B$3,_翻訳マスタ!$B$1:$D$1,0)) -> • Lưu các thảo luận chi tiết trong biên bản họp và tài liệu liên quan | J5: 01_全体サマリー | K5: =INDEX(_翻訳マスタ!$B$2:$D$32,MATCH("U1",_翻訳マスタ!$A$2:$A$32,0),MATCH(言語切替!$B$3,_翻訳マスタ!$B$1:$D$1,0)) -> Bảng điều khiển cho ban điều hành và cuộc họp trưởng nhóm
A6: =INDEX(_翻訳マスタ!$B$2:$D$32,MATCH("P2",_翻訳マスタ!$A$2:$A$32,0),MATCH(言語切替!$B$3,_翻訳マスタ!$B$1:$D$1,0)) -> • Trong tệp này, ghi lại kết luận, hành động tiếp theo, người phụ trách, thời hạn và liên kết | J6: 02_マスタ | K6: =INDEX(_翻訳マスタ!$B$2:$D$32,MATCH("U2",_翻訳マスタ!$A$2:$A$32,0),MATCH(言語切替!$B$3,_翻訳マスタ!$B$1:$D$1,0)) -> Danh sách lựa chọn nhập liệu và định nghĩa WG
A7: =INDEX(_翻訳マスタ!$B$2:$D$32,MATCH("P3",_翻訳マスタ!$A$2:$A$32,0),MATCH(言語切替!$B$3,_翻訳マスタ!$B$1:$D$1,0)) -> • Không nhập trùng cùng một nội dung trên nhiều trang tính | J7: 03_WBS | K7: =INDEX(_翻訳マスタ!$B$2:$D$32,MATCH("U3",_翻訳マスタ!$A$2:$A$32,0),MATCH(言語切替!$B$3,_翻訳マスタ!$B$1:$D$1,0)) -> Quản lý kế hoạch sản phẩm bàn giao và mốc tiến độ
A8: =INDEX(_翻訳マスタ!$B$2:$D$32,MATCH("P4",_翻訳マスタ!$A$2:$A$32,0),MATCH(言語切替!$B$3,_翻訳マスタ!$B$1:$D$1,0)) -> • Không xóa dòng; hãy ghi lại lý do thay đổi hoặc rút lại | J8: 04_課題ToDo | K8: =INDEX(_翻訳マスタ!$B$2:$D$32,MATCH("U4",_翻訳マスタ!$A$2:$A$32,0),MATCH(言語切替!$B$3,_翻訳マスタ!$B$1:$D$1,0)) -> Quản lý trở ngại, hành động và rủi ro
J9: 05_決定事項 | K9: =INDEX(_翻訳マスタ!$B$2:$D$32,MATCH("U5",_翻訳マスタ!$A$2:$A$32,0),MATCH(言語切替!$B$3,_翻訳マスタ!$B$1:$D$1,0)) -> Ghi lại lịch sử quyết định và phạm vi ảnh hưởng
A10: =INDEX(_翻訳マスタ!$B$2:$D$32,MATCH("RESP_HEADER",_翻訳マスタ!$A$2:$A$32,0),MATCH(言語切替!$B$3,_翻訳マスタ!$B$1:$D$1,0)) -> 2. Trách nhiệm cập nhật | J10: 06_KPI | K10: =INDEX(_翻訳マスタ!$B$2:$D$32,MATCH("U6",_翻訳マスタ!$A$2:$A$32,0),MATCH(言語切替!$B$3,_翻訳マスタ!$B$1:$D$1,0)) -> Định nghĩa KPI, giá trị cơ sở, mục tiêu và thực tế
A11: =INDEX(_翻訳マスタ!$B$2:$D$32,MATCH("R1",_翻訳マスタ!$A$2:$A$32,0),MATCH(言語切替!$B$3,_翻訳マスタ!$B$1:$D$1,0)) -> • Trưởng WG: Cập nhật WBS, vấn đề và KPI sau cuộc họp WG | J11: 07_更新履歴 | K11: =INDEX(_翻訳マスタ!$B$2:$D$32,MATCH("U7",_翻訳マスタ!$A$2:$A$32,0),MATCH(言語切替!$B$3,_翻訳マスタ!$B$1:$D$1,0)) -> Ghi lại các thay đổi quan trọng
A12: =INDEX(_翻訳マスタ!$B$2:$D$32,MATCH("R2",_翻訳マスタ!$A$2:$A$32,0),MATCH(言語切替!$B$3,_翻訳マスタ!$B$1:$D$1,0)) -> • Ban điều hành: Hàng tuần rà soát các mục chưa cập nhật, quá hạn, mức High và phụ thuộc giữa các WG
A13: =INDEX(_翻訳マスタ!$B$2:$D$32,MATCH("R3",_翻訳マスタ!$A$2:$A$32,0),MATCH(言語切替!$B$3,_翻訳マスタ!$B$1:$D$1,0)) -> • Người xác nhận hoàn thành: Kiểm tra sản phẩm bàn giao hoặc kết quả xử lý và phê duyệt hoàn thành
A14: =INDEX(_翻訳マスタ!$B$2:$D$32,MATCH("R4",_翻訳マスタ!$A$2:$A$32,0),MATCH(言語切替!$B$3,_翻訳マスタ!$B$1:$D$1,0)) -> • Trưởng tiểu ban / Phó trưởng đơn vị: Quyết định các vấn đề quan trọng
A16: =INDEX(_翻訳マスタ!$B$2:$D$32,MATCH("CYCLE_HEADER",_翻訳マスタ!$A$2:$A$32,0),MATCH(言語切替!$B$3,_翻訳マスタ!$B$1:$D$1,0)) -> 3. Chu trình hàng tuần
A17: =INDEX(_翻訳マスタ!$B$2:$D$32,MATCH("C1",_翻訳マスタ!$A$2:$A$32,0),MATCH(言語切替!$B$3,_翻訳マスタ!$B$1:$D$1,0)) -> • Sau hoạt động WG: Đăng ký vấn đề mới, quyết định và hành động tiếp theo
A18: =INDEX(_翻訳マスタ!$B$2:$D$32,MATCH("C2",_翻訳マスタ!$A$2:$A$32,0),MATCH(言語切替!$B$3,_翻訳マスタ!$B$1:$D$1,0)) -> • Trước cuộc họp trưởng nhóm: Ban điều hành trích xuất các cảnh báo
A19: =INDEX(_翻訳マスタ!$B$2:$D$32,MATCH("C3",_翻訳マスタ!$A$2:$A$32,0),MATCH(言語切替!$B$3,_翻訳マスタ!$B$1:$D$1,0)) -> • Họp trưởng nhóm hàng tuần: Tập trung thảo luận các mục chờ quyết định, vấn đề liên WG và chậm tiến độ
A20: =INDEX(_翻訳マスタ!$B$2:$D$32,MATCH("C4",_翻訳マスタ!$A$2:$A$32,0),MATCH(言語切替!$B$3,_翻訳マスタ!$B$1:$D$1,0)) -> • Sau cuộc họp: Cập nhật quyết định, người phụ trách và thời hạn
A22: =INDEX(_翻訳マスタ!$B$2:$D$32,MATCH("ESC_HEADER",_翻訳マスタ!$A$2:$A$32,0),MATCH(言語切替!$B$3,_翻訳マスタ!$B$1:$D$1,0)) -> 4. Điều kiện báo cáo cấp trên
A23: =INDEX(_翻訳マスタ!$B$2:$D$32,MATCH("E1",_翻訳マスタ!$A$2:$A$32,0),MATCH(言語切替!$B$3,_翻訳マスタ!$B$1:$D$1,0)) -> • Mức ưu tiên High
A24: =INDEX(_翻訳マスタ!$B$2:$D$32,MATCH("E2",_翻訳マスタ!$A$2:$A$32,0),MATCH(言語切替!$B$3,_翻訳マスタ!$B$1:$D$1,0)) -> • Đã quá hạn hoặc có khả năng quá hạn
A25: =INDEX(_翻訳マスタ!$B$2:$D$32,MATCH("E3",_翻訳マスタ!$A$2:$A$32,0),MATCH(言語切替!$B$3,_翻訳マスタ!$B$1:$D$1,0)) -> • Ảnh hưởng đến nhiều WG hoặc nhiều đơn vị
A26: =INDEX(_翻訳マスタ!$B$2:$D$32,MATCH("E4",_翻訳マスタ!$A$2:$A$32,0),MATCH(言語切替!$B$3,_翻訳マスタ!$B$1:$D$1,0)) -> • Cần thay đổi phạm vi, đầu tư, nhân sự hoặc quyết định cấp cao hơn
A27: =INDEX(_翻訳マスタ!$B$2:$D$300,MATCH("PARA_TITLE",_翻訳マスタ!$A$2:$A$300,0),MATCH(言語切替!$B$3,_翻訳マスタ!$B$1:$D$1,0)) -> 5. Quy tắc dịch song song (nội dung mới)
A28: =INDEX(_翻訳マスタ!$B$2:$D$300,MATCH("PARA_DESC",_翻訳マスタ!$A$2:$A$300,0),MATCH(言語切替!$B$3,_翻訳マスタ!$B$1:$D$1,0)) -> Gõ vào cột [Nhập: VI/JP/CN] bằng tiếng mẹ đẻ (Việt/Nhật/Trung), các cột VI/JP/CN kề cạnh sẽ tự động dịch và hiển thị bằng hàm TRANSLATE.
A29: =INDEX(_翻訳マスタ!$B$2:$D$300,MATCH("PARA_HOWTO",_翻訳マスタ!$A$2:$A$300,0),MATCH(言語切替!$B$3,_翻訳マスタ!$B$1:$D$1,0)) -> Quy tắc nhập: 【Tiêu đề VÀNG】= Được phép nhập / chọn dữ liệu (Gõ bất kỳ tiếng Việt/Nhật/Trung vào ô [Nhập]) 【Tiêu đề XANH DƯƠNG】= Cấm nhập (Tự động tính toán & dịch tự động 3 thứ tiếng).
A30: =INDEX(_翻訳マスタ!$B$2:$D$300,MATCH("BACKUP_TITLE",_翻訳マスタ!$A$2:$A$300,0),MATCH(言語切替!$B$3,_翻訳マスタ!$B$1:$D$1,0)) -> 6. Chống xóa & sao lưu
A31: =INDEX(_翻訳マスタ!$B$2:$D$300,MATCH("BACKUP_DESC",_翻訳マスタ!$A$2:$A$300,0),MATCH(言語切替!$B$3,_翻訳マスタ!$B$1:$D$1,0)) -> Cấm xóa dòng vật lý. Chuyển sang "Rút lại" và sao chép sang _ゴミ箱_Backup. Bật Version History 500 bản trên SharePoint, hàng tuần lưu riêng.

Sheet 01_全体サマリー
A1: =INDEX(_翻訳マスタ!$B$33:$D$45,MATCH("DASH_TITLE",_翻訳マスタ!$A$33:$A$45,0),MATCH(言語切替!$B$3,_翻訳マスタ!$B$1:$D$1,0)) -> Tổng quan
A2: =INDEX(_翻訳マスタ!$B$33:$D$45,MATCH("DASH_DESC",_翻訳マスタ!$A$33:$A$45,0),MATCH(言語切替!$B$3,_翻訳マスタ!$B$1:$D$1,0)) -> Dùng cho ban điều hành và cuộc họp trưởng WG hàng tuần. Không cần nhập liệu; thông tin WBS, Vấn đề/ToDo và KPI được tự động tổng hợp.
B4: =INDEX(_翻訳マスタ!$B$33:$D$45,MATCH("DASH_OPEN_WBS",_翻訳マスタ!$A$33:$A$45,0),MATCH(言語切替!$B$3,_翻訳マスタ!$B$1:$D$1,0)) -> WBS chưa hoàn thành | D4: =INDEX(_翻訳マスタ!$B$33:$D$45,MATCH("DASH_DELAY_WBS",_翻訳マスタ!$A$33:$A$45,0),MATCH(言語切替!$B$3,_翻訳マスタ!$B$1:$D$1,0)) -> WBS chậm tiến độ | F4: =INDEX(_翻訳マスタ!$B$33:$D$45,MATCH("DASH_OPEN_ISSUES",_翻訳マスタ!$A$33:$A$45,0),MATCH(言語切替!$B$3,_翻訳マスタ!$B$1:$D$1,0)) -> Vấn đề/ToDo chưa hoàn thành | H4: =INDEX(_翻訳マスタ!$B$33:$D$45,MATCH("DASH_HIGH_OVERDUE",_翻訳マスタ!$A$33:$A$45,0),MATCH(言語切替!$B$3,_翻訳マスタ!$B$1:$D$1,0)) -> High / Quá hạn | J4: =INDEX(_翻訳マスタ!$B$33:$D$45,MATCH("DASH_KPI_MISS",_翻訳マスタ!$A$33:$A$45,0),MATCH(言語切替!$B$3,_翻訳マスタ!$B$1:$D$1,0)) -> KPI chưa đạt
B5: =COUNTIFS('03_WBS'!$A$5:$A$205,"<>",'03_WBS'!$T$5:$T$205,"<>"&INDEX(_翻訳マスタ!$B$75:$D$75,1,MATCH(言語切替!$B$3,_翻訳マスタ!$B$1:$D$1,0))) -> 8 | D5: =COUNTIF('03_WBS'!$T$5:$T$205,INDEX(_翻訳マスタ!$B$92:$D$92,1,MATCH(言語切替!$B$3,_翻訳マスタ!$B$1:$D$1,0))) -> 0 | F5: =COUNTIFS('04_課題ToDo'!$A$5:$A$304,"<>",'04_課題ToDo'!$W$5:$W$304,"<>"&INDEX(_翻訳マスタ!$B$75:$D$75,1,MATCH(言語切替!$B$3,_翻訳マスタ!$B$1:$D$1,0)),'04_課題ToDo'!$W$5:$W$304,"<>"&INDEX(_翻訳マスタ!$B$77:$D$77,1,MATCH(言語切替!$B$3,_翻訳マスタ!$B$1:$D$1,0))) -> 0 | H5: =COUNTIFS('04_課題ToDo'!$A$5:$A$304,"<>",'04_課題ToDo'!$AI$5:$AI$304,"High")+COUNTIFS('04_課題ToDo'!$A$5:$A$304,"<>",'04_課題ToDo'!$AI$5:$AI$304,INDEX(_翻訳マスタ!$B$117:$D$247,MATCH("ALERT_OVERDUE",_翻訳マスタ!$A$117:$A$247,0),MATCH(言語切替!$B$3,_翻訳マスタ!$B$1:$D$1,0))) -> 0 | J5: =COUNTIFS('06_KPI'!$A$5:$A$204,"<>",'06_KPI'!$X$5:$X$204,INDEX(_翻訳マスタ!$B$94:$D$94,1,MATCH(言語切替!$B$3,_翻訳マスタ!$B$1:$D$1,0))) -> 0
A9: =INDEX(_翻訳マスタ!$B$33:$D$45,MATCH("DASH_WG",_翻訳マスタ!$A$33:$A$45,0),MATCH(言語切替!$B$3,_翻訳マスタ!$B$1:$D$1,0)) -> WG | B9: =INDEX(_翻訳マスタ!$B$33:$D$45,MATCH("DASH_OPEN_WBS",_翻訳マスタ!$A$33:$A$45,0),MATCH(言語切替!$B$3,_翻訳マスタ!$B$1:$D$1,0)) -> WBS chưa hoàn thành | C9: =INDEX(_翻訳マスタ!$B$33:$D$45,MATCH("DASH_DELAY_WBS",_翻訳マスタ!$A$33:$A$45,0),MATCH(言語切替!$B$3,_翻訳マスタ!$B$1:$D$1,0)) -> WBS chậm tiến độ | D9: =INDEX(_翻訳マスタ!$B$33:$D$45,MATCH("DASH_OPEN_ISSUES_SHORT",_翻訳マスタ!$A$33:$A$45,0),MATCH(言語切替!$B$3,_翻訳マスタ!$B$1:$D$1,0)) -> Vấn đề chưa hoàn thành | E9: =INDEX(_翻訳マスタ!$B$33:$D$45,MATCH("DASH_HIGH_OVERDUE_SHORT",_翻訳マスタ!$A$33:$A$45,0),MATCH(言語切替!$B$3,_翻訳マスタ!$B$1:$D$1,0)) -> High/Quá hạn | F9: =INDEX(_翻訳マスタ!$B$33:$D$45,MATCH("DASH_WAITING",_翻訳マスタ!$A$33:$A$45,0),MATCH(言語切替!$B$3,_翻訳マスタ!$B$1:$D$1,0)) -> Chờ quyết định/WG khác | G9: =INDEX(_翻訳マスタ!$B$33:$D$45,MATCH("DASH_KPI_MISS",_翻訳マスタ!$A$33:$A$45,0),MATCH(言語切替!$B$3,_翻訳マスタ!$B$1:$D$1,0)) -> KPI chưa đạt
A10: ='02_マスタ'!$A$5 -> Toàn bộ | B10: =COUNTIFS('03_WBS'!$B$5:$B$205,$A10,'03_WBS'!$T$5:$T$205,"<>"&INDEX(_翻訳マスタ!$B$75:$D$75,1,MATCH(言語切替!$B$3,_翻訳マスタ!$B$1:$D$1,0))) -> 1 | C10: =COUNTIFS('03_WBS'!$B$5:$B$205,$A10,'03_WBS'!$T$5:$T$205,INDEX(_翻訳マスタ!$B$92:$D$92,1,MATCH(言語切替!$B$3,_翻訳マスタ!$B$1:$D$1,0))) -> 0 | D10: =COUNTIFS('04_課題ToDo'!$C$5:$C$304,$A10,'04_課題ToDo'!$W$5:$W$304,"<>"&INDEX(_翻訳マスタ!$B$75:$D$75,1,MATCH(言語切替!$B$3,_翻訳マスタ!$B$1:$D$1,0)),'04_課題ToDo'!$W$5:$W$304,"<>"&INDEX(_翻訳マスタ!$B$77:$D$77,1,MATCH(言語切替!$B$3,_翻訳マスタ!$B$1:$D$1,0))) -> 1 | E10: =COUNTIFS('04_課題ToDo'!$C$5:$C$304,$A10,'04_課題ToDo'!$AI$5:$AI$304,"High")+COUNTIFS('04_課題ToDo'!$C$5:$C$304,$A10,'04_課題ToDo'!$AI$5:$AI$304,INDEX(_翻訳マスタ!$B$117:$D$247,MATCH("ALERT_OVERDUE",_翻訳マスタ!$A$117:$A$247,0),MATCH(言語切替!$B$3,_翻訳マスタ!$B$1:$D$1,0))) -> 0 | F10: =COUNTIFS('04_課題ToDo'!$C$5:$C$304,$A10,'04_課題ToDo'!$W$5:$W$304,INDEX(_翻訳マスタ!$B$72:$D$72,1,MATCH(言語切替!$B$3,_翻訳マスタ!$B$1:$D$1,0)))+COUNTIFS('04_課題ToDo'!$C$5:$C$304,$A10,'04_課題ToDo'!$W$5:$W$304,INDEX(_翻訳マスタ!$B$73:$D$73,1,MATCH(言語切替!$B$3,_翻訳マスタ!$B$1:$D$1,0))) -> 0 | G10: =COUNTIFS('06_KPI'!$B$5:$B$204,$A10,'06_KPI'!$X$5:$X$204,INDEX(_翻訳マスタ!$B$94:$D$94,1,MATCH(言語切替!$B$3,_翻訳マスタ!$B$1:$D$1,0))) -> 0
A11: WG-1 | B11: =COUNTIFS('03_WBS'!$B$5:$B$205,$A11,'03_WBS'!$T$5:$T$205,"<>"&INDEX(_翻訳マスタ!$B$75:$D$75,1,MATCH(言語切替!$B$3,_翻訳マスタ!$B$1:$D$1,0))) -> 1 | C11: =COUNTIFS('03_WBS'!$B$5:$B$205,$A11,'03_WBS'!$T$5:$T$205,INDEX(_翻訳マスタ!$B$92:$D$92,1,MATCH(言語切替!$B$3,_翻訳マスタ!$B$1:$D$1,0))) -> 0 | D11: =COUNTIFS('04_課題ToDo'!$C$5:$C$304,$A11,'04_課題ToDo'!$W$5:$W$304,"<>"&INDEX(_翻訳マスタ!$B$75:$D$75,1,MATCH(言語切替!$B$3,_翻訳マスタ!$B$1:$D$1,0)),'04_課題ToDo'!$W$5:$W$304,"<>"&INDEX(_翻訳マスタ!$B$77:$D$77,1,MATCH(言語切替!$B$3,_翻訳マスタ!$B$1:$D$1,0))) -> 0 | E11: =COUNTIFS('04_課題ToDo'!$C$5:$C$304,$A11,'04_課題ToDo'!$AI$5:$AI$304,"High")+COUNTIFS('04_課題ToDo'!$C$5:$C$304,$A11,'04_課題ToDo'!$AI$5:$AI$304,INDEX(_翻訳マスタ!$B$117:$D$247,MATCH("ALERT_OVERDUE",_翻訳マスタ!$A$117:$A$247,0),MATCH(言語切替!$B$3,_翻訳マスタ!$B$1:$D$1,0))) -> 0 | F11: =COUNTIFS('04_課題ToDo'!$C$5:$C$304,$A11,'04_課題ToDo'!$W$5:$W$304,INDEX(_翻訳マスタ!$B$72:$D$72,1,MATCH(言語切替!$B$3,_翻訳マスタ!$B$1:$D$1,0)))+COUNTIFS('04_課題ToDo'!$C$5:$C$304,$A11,'04_課題ToDo'!$W$5:$W$304,INDEX(_翻訳マスタ!$B$73:$D$73,1,MATCH(言語切替!$B$3,_翻訳マスタ!$B$1:$D$1,0))) -> 0 | G11: =COUNTIFS('06_KPI'!$B$5:$B$204,$A11,'06_KPI'!$X$5:$X$204,INDEX(_翻訳マスタ!$B$94:$D$94,1,MATCH(言語切替!$B$3,_翻訳マスタ!$B$1:$D$1,0))) -> 0
A12: WG-2 | B12: =COUNTIFS('03_WBS'!$B$5:$B$205,$A12,'03_WBS'!$T$5:$T$205,"<>"&INDEX(_翻訳マスタ!$B$75:$D$75,1,MATCH(言語切替!$B$3,_翻訳マスタ!$B$1:$D$1,0))) -> 0 | C12: =COUNTIFS('03_WBS'!$B$5:$B$205,$A12,'03_WBS'!$T$5:$T$205,INDEX(_翻訳マスタ!$B$92:$D$92,1,MATCH(言語切替!$B$3,_翻訳マスタ!$B$1:$D$1,0))) -> 0 | D12: =COUNTIFS('04_課題ToDo'!$C$5:$C$304,$A12,'04_課題ToDo'!$W$5:$W$304,"<>"&INDEX(_翻訳マスタ!$B$75:$D$75,1,MATCH(言語切替!$B$3,_翻訳マスタ!$B$1:$D$1,0)),'04_課題ToDo'!$W$5:$W$304,"<>"&INDEX(_翻訳マスタ!$B$77:$D$77,1,MATCH(言語切替!$B$3,_翻訳マスタ!$B$1:$D$1,0))) -> 0 | E12: =COUNTIFS('04_課題ToDo'!$C$5:$C$304,$A12,'04_課題ToDo'!$AI$5:$AI$304,"High")+COUNTIFS('04_課題ToDo'!$C$5:$C$304,$A12,'04_課題ToDo'!$AI$5:$AI$304,INDEX(_翻訳マスタ!$B$117:$D$247,MATCH("ALERT_OVERDUE",_翻訳マスタ!$A$117:$A$247,0),MATCH(言語切替!$B$3,_翻訳マスタ!$B$1:$D$1,0))) -> 0 | F12: =COUNTIFS('04_課題ToDo'!$C$5:$C$304,$A12,'04_課題ToDo'!$W$5:$W$304,INDEX(_翻訳マスタ!$B$72:$D$72,1,MATCH(言語切替!$B$3,_翻訳マスタ!$B$1:$D$1,0)))+COUNTIFS('04_課題ToDo'!$C$5:$C$304,$A12,'04_課題ToDo'!$W$5:$W$304,INDEX(_翻訳マスタ!$B$73:$D$73,1,MATCH(言語切替!$B$3,_翻訳マスタ!$B$1:$D$1,0))) -> 0 | G12: =COUNTIFS('06_KPI'!$B$5:$B$204,$A12,'06_KPI'!$X$5:$X$204,INDEX(_翻訳マスタ!$B$94:$D$94,1,MATCH(言語切替!$B$3,_翻訳マスタ!$B$1:$D$1,0))) -> 0
A13: WG-3 | B13: =COUNTIFS('03_WBS'!$B$5:$B$205,$A13,'03_WBS'!$T$5:$T$205,"<>"&INDEX(_翻訳マスタ!$B$75:$D$75,1,MATCH(言語切替!$B$3,_翻訳マスタ!$B$1:$D$1,0))) -> 0 | C13: =COUNTIFS('03_WBS'!$B$5:$B$205,$A13,'03_WBS'!$T$5:$T$205,INDEX(_翻訳マスタ!$B$92:$D$92,1,MATCH(言語切替!$B$3,_翻訳マスタ!$B$1:$D$1,0))) -> 0 | D13: =COUNTIFS('04_課題ToDo'!$C$5:$C$304,$A13,'04_課題ToDo'!$W$5:$W$304,"<>"&INDEX(_翻訳マスタ!$B$75:$D$75,1,MATCH(言語切替!$B$3,_翻訳マスタ!$B$1:$D$1,0)),'04_課題ToDo'!$W$5:$W$304,"<>"&INDEX(_翻訳マスタ!$B$77:$D$77,1,MATCH(言語切替!$B$3,_翻訳マスタ!$B$1:$D$1,0))) -> 0 | E13: =COUNTIFS('04_課題ToDo'!$C$5:$C$304,$A13,'04_課題ToDo'!$AI$5:$AI$304,"High")+COUNTIFS('04_課題ToDo'!$C$5:$C$304,$A13,'04_課題ToDo'!$AI$5:$AI$304,INDEX(_翻訳マスタ!$B$117:$D$247,MATCH("ALERT_OVERDUE",_翻訳マスタ!$A$117:$A$247,0),MATCH(言語切替!$B$3,_翻訳マスタ!$B$1:$D$1,0))) -> 0 | F13: =COUNTIFS('04_課題ToDo'!$C$5:$C$304,$A13,'04_課題ToDo'!$W$5:$W$304,INDEX(_翻訳マスタ!$B$72:$D$72,1,MATCH(言語切替!$B$3,_翻訳マスタ!$B$1:$D$1,0)))+COUNTIFS('04_課題ToDo'!$C$5:$C$304,$A13,'04_課題ToDo'!$W$5:$W$304,INDEX(_翻訳マスタ!$B$73:$D$73,1,MATCH(言語切替!$B$3,_翻訳マスタ!$B$1:$D$1,0))) -> 0 | G13: =COUNTIFS('06_KPI'!$B$5:$B$204,$A13,'06_KPI'!$X$5:$X$204,INDEX(_翻訳マスタ!$B$94:$D$94,1,MATCH(言語切替!$B$3,_翻訳マスタ!$B$1:$D$1,0))) -> 0
A14: WG-4 | B14: =COUNTIFS('03_WBS'!$B$5:$B$205,$A14,'03_WBS'!$T$5:$T$205,"<>"&INDEX(_翻訳マスタ!$B$75:$D$75,1,MATCH(言語切替!$B$3,_翻訳マスタ!$B$1:$D$1,0))) -> 0 | C14: =COUNTIFS('03_WBS'!$B$5:$B$205,$A14,'03_WBS'!$T$5:$T$205,INDEX(_翻訳マスタ!$B$92:$D$92,1,MATCH(言語切替!$B$3,_翻訳マスタ!$B$1:$D$1,0))) -> 0 | D14: =COUNTIFS('04_課題ToDo'!$C$5:$C$304,$A14,'04_課題ToDo'!$W$5:$W$304,"<>"&INDEX(_翻訳マスタ!$B$75:$D$75,1,MATCH(言語切替!$B$3,_翻訳マスタ!$B$1:$D$1,0)),'04_課題ToDo'!$W$5:$W$304,"<>"&INDEX(_翻訳マスタ!$B$77:$D$77,1,MATCH(言語切替!$B$3,_翻訳マスタ!$B$1:$D$1,0))) -> 1 | E14: =COUNTIFS('04_課題ToDo'!$C$5:$C$304,$A14,'04_課題ToDo'!$AI$5:$AI$304,"High")+COUNTIFS('04_課題ToDo'!$C$5:$C$304,$A14,'04_課題ToDo'!$AI$5:$AI$304,INDEX(_翻訳マスタ!$B$117:$D$247,MATCH("ALERT_OVERDUE",_翻訳マスタ!$A$117:$A$247,0),MATCH(言語切替!$B$3,_翻訳マスタ!$B$1:$D$1,0))) -> 0 | F14: =COUNTIFS('04_課題ToDo'!$C$5:$C$304,$A14,'04_課題ToDo'!$W$5:$W$304,INDEX(_翻訳マスタ!$B$72:$D$72,1,MATCH(言語切替!$B$3,_翻訳マスタ!$B$1:$D$1,0)))+COUNTIFS('04_課題ToDo'!$C$5:$C$304,$A14,'04_課題ToDo'!$W$5:$W$304,INDEX(_翻訳マスタ!$B$73:$D$73,1,MATCH(言語切替!$B$3,_翻訳マスタ!$B$1:$D$1,0))) -> 0 | G14: =COUNTIFS('06_KPI'!$B$5:$B$204,$A14,'06_KPI'!$X$5:$X$204,INDEX(_翻訳マスタ!$B$94:$D$94,1,MATCH(言語切替!$B$3,_翻訳マスタ!$B$1:$D$1,0))) -> 0
A15: WG-5 | B15: =COUNTIFS('03_WBS'!$B$5:$B$205,$A15,'03_WBS'!$T$5:$T$205,"<>"&INDEX(_翻訳マスタ!$B$75:$D$75,1,MATCH(言語切替!$B$3,_翻訳マスタ!$B$1:$D$1,0))) -> 4 | C15: =COUNTIFS('03_WBS'!$B$5:$B$205,$A15,'03_WBS'!$T$5:$T$205,INDEX(_翻訳マスタ!$B$92:$D$92,1,MATCH(言語切替!$B$3,_翻訳マスタ!$B$1:$D$1,0))) -> 0 | D15: =COUNTIFS('04_課題ToDo'!$C$5:$C$304,$A15,'04_課題ToDo'!$W$5:$W$304,"<>"&INDEX(_翻訳マスタ!$B$75:$D$75,1,MATCH(言語切替!$B$3,_翻訳マスタ!$B$1:$D$1,0)),'04_課題ToDo'!$W$5:$W$304,"<>"&INDEX(_翻訳マスタ!$B$77:$D$77,1,MATCH(言語切替!$B$3,_翻訳マスタ!$B$1:$D$1,0))) -> 1 | E15: =COUNTIFS('04_課題ToDo'!$C$5:$C$304,$A15,'04_課題ToDo'!$AI$5:$AI$304,"High")+COUNTIFS('04_課題ToDo'!$C$5:$C$304,$A15,'04_課題ToDo'!$AI$5:$AI$304,INDEX(_翻訳マスタ!$B$117:$D$247,MATCH("ALERT_OVERDUE",_翻訳マスタ!$A$117:$A$247,0),MATCH(言語切替!$B$3,_翻訳マスタ!$B$1:$D$1,0))) -> 0 | F15: =COUNTIFS('04_課題ToDo'!$C$5:$C$304,$A15,'04_課題ToDo'!$W$5:$W$304,INDEX(_翻訳マスタ!$B$72:$D$72,1,MATCH(言語切替!$B$3,_翻訳マスタ!$B$1:$D$1,0)))+COUNTIFS('04_課題ToDo'!$C$5:$C$304,$A15,'04_課題ToDo'!$W$5:$W$304,INDEX(_翻訳マスタ!$B$73:$D$73,1,MATCH(言語切替!$B$3,_翻訳マスタ!$B$1:$D$1,0))) -> 0 | G15: =COUNTIFS('06_KPI'!$B$5:$B$204,$A15,'06_KPI'!$X$5:$X$204,INDEX(_翻訳マスタ!$B$94:$D$94,1,MATCH(言語切替!$B$3,_翻訳マスタ!$B$1:$D$1,0))) -> 0
A16: WG-6 | B16: =COUNTIFS('03_WBS'!$B$5:$B$205,$A16,'03_WBS'!$T$5:$T$205,"<>"&INDEX(_翻訳マスタ!$B$75:$D$75,1,MATCH(言語切替!$B$3,_翻訳マスタ!$B$1:$D$1,0))) -> 0 | C16: =COUNTIFS('03_WBS'!$B$5:$B$205,$A16,'03_WBS'!$T$5:$T$205,INDEX(_翻訳マスタ!$B$92:$D$92,1,MATCH(言語切替!$B$3,_翻訳マスタ!$B$1:$D$1,0))) -> 0 | D16: =COUNTIFS('04_課題ToDo'!$C$5:$C$304,$A16,'04_課題ToDo'!$W$5:$W$304,"<>"&INDEX(_翻訳マスタ!$B$75:$D$75,1,MATCH(言語切替!$B$3,_翻訳マスタ!$B$1:$D$1,0)),'04_課題ToDo'!$W$5:$W$304,"<>"&INDEX(_翻訳マスタ!$B$77:$D$77,1,MATCH(言語切替!$B$3,_翻訳マスタ!$B$1:$D$1,0))) -> 0 | E16: =COUNTIFS('04_課題ToDo'!$C$5:$C$304,$A16,'04_課題ToDo'!$AI$5:$AI$304,"High")+COUNTIFS('04_課題ToDo'!$C$5:$C$304,$A16,'04_課題ToDo'!$AI$5:$AI$304,INDEX(_翻訳マスタ!$B$117:$D$247,MATCH("ALERT_OVERDUE",_翻訳マスタ!$A$117:$A$247,0),MATCH(言語切替!$B$3,_翻訳マスタ!$B$1:$D$1,0))) -> 0 | F16: =COUNTIFS('04_課題ToDo'!$C$5:$C$304,$A16,'04_課題ToDo'!$W$5:$W$304,INDEX(_翻訳マスタ!$B$72:$D$72,1,MATCH(言語切替!$B$3,_翻訳マスタ!$B$1:$D$1,0)))+COUNTIFS('04_課題ToDo'!$C$5:$C$304,$A16,'04_課題ToDo'!$W$5:$W$304,INDEX(_翻訳マスタ!$B$73:$D$73,1,MATCH(言語切替!$B$3,_翻訳マスタ!$B$1:$D$1,0))) -> 0 | G16: =COUNTIFS('06_KPI'!$B$5:$B$204,$A16,'06_KPI'!$X$5:$X$204,INDEX(_翻訳マスタ!$B$94:$D$94,1,MATCH(言語切替!$B$3,_翻訳マスタ!$B$1:$D$1,0))) -> 0
A17: WG-7 | B17: =COUNTIFS('03_WBS'!$B$5:$B$205,$A17,'03_WBS'!$T$5:$T$205,"<>"&INDEX(_翻訳マスタ!$B$75:$D$75,1,MATCH(言語切替!$B$3,_翻訳マスタ!$B$1:$D$1,0))) -> 0 | C17: =COUNTIFS('03_WBS'!$B$5:$B$205,$A17,'03_WBS'!$T$5:$T$205,INDEX(_翻訳マスタ!$B$92:$D$92,1,MATCH(言語切替!$B$3,_翻訳マスタ!$B$1:$D$1,0))) -> 0 | D17: =COUNTIFS('04_課題ToDo'!$C$5:$C$304,$A17,'04_課題ToDo'!$W$5:$W$304,"<>"&INDEX(_翻訳マスタ!$B$75:$D$75,1,MATCH(言語切替!$B$3,_翻訳マスタ!$B$1:$D$1,0)),'04_課題ToDo'!$W$5:$W$304,"<>"&INDEX(_翻訳マスタ!$B$77:$D$77,1,MATCH(言語切替!$B$3,_翻訳マスタ!$B$1:$D$1,0))) -> 1 | E17: =COUNTIFS('04_課題ToDo'!$C$5:$C$304,$A17,'04_課題ToDo'!$AI$5:$AI$304,"High")+COUNTIFS('04_課題ToDo'!$C$5:$C$304,$A17,'04_課題ToDo'!$AI$5:$AI$304,INDEX(_翻訳マスタ!$B$117:$D$247,MATCH("ALERT_OVERDUE",_翻訳マスタ!$A$117:$A$247,0),MATCH(言語切替!$B$3,_翻訳マスタ!$B$1:$D$1,0))) -> 0 | F17: =COUNTIFS('04_課題ToDo'!$C$5:$C$304,$A17,'04_課題ToDo'!$W$5:$W$304,INDEX(_翻訳マスタ!$B$72:$D$72,1,MATCH(言語切替!$B$3,_翻訳マスタ!$B$1:$D$1,0)))+COUNTIFS('04_課題ToDo'!$C$5:$C$304,$A17,'04_課題ToDo'!$W$5:$W$304,INDEX(_翻訳マスタ!$B$73:$D$73,1,MATCH(言語切替!$B$3,_翻訳マスタ!$B$1:$D$1,0))) -> 0 | G17: =COUNTIFS('06_KPI'!$B$5:$B$204,$A17,'06_KPI'!$X$5:$X$204,INDEX(_翻訳マスタ!$B$94:$D$94,1,MATCH(言語切替!$B$3,_翻訳マスタ!$B$1:$D$1,0))) -> 0
A18: WG-8 | B18: =COUNTIFS('03_WBS'!$B$5:$B$205,$A18,'03_WBS'!$T$5:$T$205,"<>"&INDEX(_翻訳マスタ!$B$75:$D$75,1,MATCH(言語切替!$B$3,_翻訳マスタ!$B$1:$D$1,0))) -> 1 | C18: =COUNTIFS('03_WBS'!$B$5:$B$205,$A18,'03_WBS'!$T$5:$T$205,INDEX(_翻訳マスタ!$B$92:$D$92,1,MATCH(言語切替!$B$3,_翻訳マスタ!$B$1:$D$1,0))) -> 0 | D18: =COUNTIFS('04_課題ToDo'!$C$5:$C$304,$A18,'04_課題ToDo'!$W$5:$W$304,"<>"&INDEX(_翻訳マスタ!$B$75:$D$75,1,MATCH(言語切替!$B$3,_翻訳マスタ!$B$1:$D$1,0)),'04_課題ToDo'!$W$5:$W$304,"<>"&INDEX(_翻訳マスタ!$B$77:$D$77,1,MATCH(言語切替!$B$3,_翻訳マスタ!$B$1:$D$1,0))) -> 0 | E18: =COUNTIFS('04_課題ToDo'!$C$5:$C$304,$A18,'04_課題ToDo'!$AI$5:$AI$304,"High")+COUNTIFS('04_課題ToDo'!$C$5:$C$304,$A18,'04_課題ToDo'!$AI$5:$AI$304,INDEX(_翻訳マスタ!$B$117:$D$247,MATCH("ALERT_OVERDUE",_翻訳マスタ!$A$117:$A$247,0),MATCH(言語切替!$B$3,_翻訳マスタ!$B$1:$D$1,0))) -> 0 | F18: =COUNTIFS('04_課題ToDo'!$C$5:$C$304,$A18,'04_課題ToDo'!$W$5:$W$304,INDEX(_翻訳マスタ!$B$72:$D$72,1,MATCH(言語切替!$B$3,_翻訳マスタ!$B$1:$D$1,0)))+COUNTIFS('04_課題ToDo'!$C$5:$C$304,$A18,'04_課題ToDo'!$W$5:$W$304,INDEX(_翻訳マスタ!$B$73:$D$73,1,MATCH(言語切替!$B$3,_翻訳マスタ!$B$1:$D$1,0))) -> 0 | G18: =COUNTIFS('06_KPI'!$B$5:$B$204,$A18,'06_KPI'!$X$5:$X$204,INDEX(_翻訳マスタ!$B$94:$D$94,1,MATCH(言語切替!$B$3,_翻訳マスタ!$B$1:$D$1,0))) -> 0
A19: WG-9 | B19: =COUNTIFS('03_WBS'!$B$5:$B$205,$A19,'03_WBS'!$T$5:$T$205,"<>"&INDEX(_翻訳マスタ!$B$75:$D$75,1,MATCH(言語切替!$B$3,_翻訳マスタ!$B$1:$D$1,0))) -> 0 | C19: =COUNTIFS('03_WBS'!$B$5:$B$205,$A19,'03_WBS'!$T$5:$T$205,INDEX(_翻訳マスタ!$B$92:$D$92,1,MATCH(言語切替!$B$3,_翻訳マスタ!$B$1:$D$1,0))) -> 0 | D19: =COUNTIFS('04_課題ToDo'!$C$5:$C$304,$A19,'04_課題ToDo'!$W$5:$W$304,"<>"&INDEX(_翻訳マスタ!$B$75:$D$75,1,MATCH(言語切替!$B$3,_翻訳マスタ!$B$1:$D$1,0)),'04_課題ToDo'!$W$5:$W$304,"<>"&INDEX(_翻訳マスタ!$B$77:$D$77,1,MATCH(言語切替!$B$3,_翻訳マスタ!$B$1:$D$1,0))) -> 1 | E19: =COUNTIFS('04_課題ToDo'!$C$5:$C$304,$A19,'04_課題ToDo'!$AI$5:$AI$304,"High")+COUNTIFS('04_課題ToDo'!$C$5:$C$304,$A19,'04_課題ToDo'!$AI$5:$AI$304,INDEX(_翻訳マスタ!$B$117:$D$247,MATCH("ALERT_OVERDUE",_翻訳マスタ!$A$117:$A$247,0),MATCH(言語切替!$B$3,_翻訳マスタ!$B$1:$D$1,0))) -> 0 | F19: =COUNTIFS('04_課題ToDo'!$C$5:$C$304,$A19,'04_課題ToDo'!$W$5:$W$304,INDEX(_翻訳マスタ!$B$72:$D$72,1,MATCH(言語切替!$B$3,_翻訳マスタ!$B$1:$D$1,0)))+COUNTIFS('04_課題ToDo'!$C$5:$C$304,$A19,'04_課題ToDo'!$W$5:$W$304,INDEX(_翻訳マスタ!$B$73:$D$73,1,MATCH(言語切替!$B$3,_翻訳マスタ!$B$1:$D$1,0))) -> 0 | G19: =COUNTIFS('06_KPI'!$B$5:$B$204,$A19,'06_KPI'!$X$5:$X$204,INDEX(_翻訳マスタ!$B$94:$D$94,1,MATCH(言語切替!$B$3,_翻訳マスタ!$B$1:$D$1,0))) -> 0

Sheet 02_マスタ
A1: =INDEX(_翻訳マスタ!$B$47:$D$98,MATCH("M_TITLE",_翻訳マスタ!$A$47:$A$98,0),MATCH(言語切替!$B$3,_翻訳マスタ!$B$1:$D$1,0)) -> Danh mục nhập liệu
A2: =INDEX(_翻訳マスタ!$B$47:$D$98,MATCH("M_DESC",_翻訳マスタ!$A$47:$A$98,0),MATCH(言語切替!$B$3,_翻訳マスタ!$B$1:$D$1,0)) -> Các giá trị lựa chọn dùng cho xác thực dữ liệu. Chỉ ban điều hành được thay đổi.
A4: =INDEX(_翻訳マスタ!$B$47:$D$98,MATCH("M_WG",_翻訳マスタ!$A$47:$A$98,0),MATCH(言語切替!$B$3,_翻訳マスタ!$B$1:$D$1,0)) -> WG | C4: =INDEX(_翻訳マスタ!$B$47:$D$98,MATCH("M_SITE",_翻訳マスタ!$A$47:$A$98,0),MATCH(言語切替!$B$3,_翻訳マスタ!$B$1:$D$1,0)) -> Đơn vị | E4: =INDEX(_翻訳マスタ!$B$47:$D$98,MATCH("M_STATUS",_翻訳マスタ!$A$47:$A$98,0),MATCH(言語切替!$B$3,_翻訳マスタ!$B$1:$D$1,0)) -> Trạng thái | G4: =INDEX(_翻訳マスタ!$B$47:$D$98,MATCH("M_PRIORITY",_翻訳マスタ!$A$47:$A$98,0),MATCH(言語切替!$B$3,_翻訳マスタ!$B$1:$D$1,0)) -> Mức ưu tiên | I4: =INDEX(_翻訳マスタ!$B$47:$D$98,MATCH("M_TYPE",_翻訳マスタ!$A$47:$A$98,0),MATCH(言語切替!$B$3,_翻訳マスタ!$B$1:$D$1,0)) -> Phân loại | K4: =INDEX(_翻訳マスタ!$B$47:$D$98,MATCH("M_KPI_LEVEL",_翻訳マスタ!$A$47:$A$98,0),MATCH(言語切替!$B$3,_翻訳マスタ!$B$1:$D$1,0)) -> Cấp KPI | M4: =INDEX(_翻訳マスタ!$B$47:$D$98,MATCH("M_JUDGMENT",_翻訳マスタ!$A$47:$A$98,0),MATCH(言語切替!$B$3,_翻訳マスタ!$B$1:$D$1,0)) -> Đánh giá
A5: =INDEX(_翻訳マスタ!$B$47:$D$98,MATCH("M_ALL",_翻訳マスタ!$A$47:$A$98,0),MATCH(言語切替!$B$3,_翻訳マスタ!$B$1:$D$1,0)) -> Toàn bộ | C5: =INDEX(_翻訳マスタ!$B$47:$D$98,MATCH("M_COMMON",_翻訳マスタ!$A$47:$A$98,0),MATCH(言語切替!$B$3,_翻訳マスタ!$B$1:$D$1,0)) -> Chung | E5: =INDEX(_翻訳マスタ!$B$47:$D$98,MATCH("M_NOT_STARTED",_翻訳マスタ!$A$47:$A$98,0),MATCH(言語切替!$B$3,_翻訳マスタ!$B$1:$D$1,0)) -> Chưa bắt đầu | G5: =INDEX(_翻訳マスタ!$B$47:$D$98,MATCH("M_HIGH",_翻訳マスタ!$A$47:$A$98,0),MATCH(言語切替!$B$3,_翻訳マスタ!$B$1:$D$1,0)) -> High | I5: =INDEX(_翻訳マスタ!$B$47:$D$98,MATCH("M_ISSUE",_翻訳マスタ!$A$47:$A$98,0),MATCH(言語切替!$B$3,_翻訳マスタ!$B$1:$D$1,0)) -> Vấn đề | K5: =INDEX(_翻訳マスタ!$B$47:$D$98,MATCH("M_FOUNDATION",_翻訳マスタ!$A$47:$A$98,0),MATCH(言語切替!$B$3,_翻訳マスタ!$B$1:$D$1,0)) -> Thiết lập nền tảng | M5: =INDEX(_翻訳マスタ!$B$47:$D$98,MATCH("M_UNSET",_翻訳マスタ!$A$47:$A$98,0),MATCH(言語切替!$B$3,_翻訳マスタ!$B$1:$D$1,0)) -> Chưa thiết lập
A6: =INDEX(_翻訳マスタ!$B$47:$D$98,MATCH("M_WG1",_翻訳マスタ!$A$47:$A$98,0),MATCH(言語切替!$B$3,_翻訳マスタ!$B$1:$D$1,0)) -> WG-1 | C6: =INDEX(_翻訳マスタ!$B$47:$D$98,MATCH("M_KDC",_翻訳マスタ!$A$47:$A$98,0),MATCH(言語切替!$B$3,_翻訳マスタ!$B$1:$D$1,0)) -> KDC | E6: =INDEX(_翻訳マスタ!$B$47:$D$98,MATCH("M_IN_PROGRESS",_翻訳マスタ!$A$47:$A$98,0),MATCH(言語切替!$B$3,_翻訳マスタ!$B$1:$D$1,0)) -> Đang xử lý | G6: =INDEX(_翻訳マスタ!$B$47:$D$98,MATCH("M_MIDDLE",_翻訳マスタ!$A$47:$A$98,0),MATCH(言語切替!$B$3,_翻訳マスタ!$B$1:$D$1,0)) -> Middle | I6: =INDEX(_翻訳マスタ!$B$47:$D$98,MATCH("M_TODO",_翻訳マスタ!$A$47:$A$98,0),MATCH(言語切替!$B$3,_翻訳マスタ!$B$1:$D$1,0)) -> ToDo | K6: =INDEX(_翻訳マスタ!$B$47:$D$98,MATCH("M_ADOPTION",_翻訳マスタ!$A$47:$A$98,0),MATCH(言語切替!$B$3,_翻訳マスタ!$B$1:$D$1,0)) -> Vận hành ổn định | M6: =INDEX(_翻訳マスタ!$B$47:$D$98,MATCH("M_ON_TRACK",_翻訳マスタ!$A$47:$A$98,0),MATCH(言語切替!$B$3,_翻訳マスタ!$B$1:$D$1,0)) -> Đúng tiến độ
A7: =INDEX(_翻訳マスタ!$B$47:$D$98,MATCH("M_WG2",_翻訳マスタ!$A$47:$A$98,0),MATCH(言語切替!$B$3,_翻訳マスタ!$B$1:$D$1,0)) -> WG-2 | C7: =INDEX(_翻訳マスタ!$B$47:$D$98,MATCH("M_KDTCN",_翻訳マスタ!$A$47:$A$98,0),MATCH(言語切替!$B$3,_翻訳マスタ!$B$1:$D$1,0)) -> KDTCN | E7: =INDEX(_翻訳マスタ!$B$47:$D$98,MATCH("M_WAIT_DECISION",_翻訳マスタ!$A$47:$A$98,0),MATCH(言語切替!$B$3,_翻訳マスタ!$B$1:$D$1,0)) -> Chờ quyết định | G7: =INDEX(_翻訳マスタ!$B$47:$D$98,MATCH("M_LOW",_翻訳マスタ!$A$47:$A$98,0),MATCH(言語切替!$B$3,_翻訳マスタ!$B$1:$D$1,0)) -> Low | I7: =INDEX(_翻訳マスタ!$B$47:$D$98,MATCH("M_DECISION",_翻訳マスタ!$A$47:$A$98,0),MATCH(言語切替!$B$3,_翻訳マスタ!$B$1:$D$1,0)) -> Quyết định | K7: =INDEX(_翻訳マスタ!$B$47:$D$98,MATCH("M_BUSINESS",_翻訳マスタ!$A$47:$A$98,0),MATCH(言語切替!$B$3,_翻訳マスタ!$B$1:$D$1,0)) -> Kết quả nghiệp vụ | M7: =INDEX(_翻訳マスタ!$B$47:$D$98,MATCH("M_CAUTION",_翻訳マスタ!$A$47:$A$98,0),MATCH(言語切替!$B$3,_翻訳マスタ!$B$1:$D$1,0)) -> Cần chú ý
A8: =INDEX(_翻訳マスタ!$B$47:$D$98,MATCH("M_WG3",_翻訳マスタ!$A$47:$A$98,0),MATCH(言語切替!$B$3,_翻訳マスタ!$B$1:$D$1,0)) -> WG-3 | C8: =INDEX(_翻訳マスタ!$B$47:$D$98,MATCH("M_KDTVN",_翻訳マスタ!$A$47:$A$98,0),MATCH(言語切替!$B$3,_翻訳マスタ!$B$1:$D$1,0)) -> KDTVN | E8: =INDEX(_翻訳マスタ!$B$47:$D$98,MATCH("M_WAIT_WG",_翻訳マスタ!$A$47:$A$98,0),MATCH(言語切替!$B$3,_翻訳マスタ!$B$1:$D$1,0)) -> Chờ WG khác | I8: =INDEX(_翻訳マスタ!$B$47:$D$98,MATCH("M_RISK",_翻訳マスタ!$A$47:$A$98,0),MATCH(言語切替!$B$3,_翻訳マスタ!$B$1:$D$1,0)) -> Rủi ro | K8: =INDEX(_翻訳マスタ!$B$47:$D$98,MATCH("M_INVESTMENT",_翻訳マスタ!$A$47:$A$98,0),MATCH(言語切替!$B$3,_翻訳マスタ!$B$1:$D$1,0)) -> Kết quả đầu tư | M8: =INDEX(_翻訳マスタ!$B$47:$D$98,MATCH("M_DELAY",_翻訳マスタ!$A$47:$A$98,0),MATCH(言語切替!$B$3,_翻訳マスタ!$B$1:$D$1,0)) -> Chậm tiến độ
A9: =INDEX(_翻訳マスタ!$B$47:$D$98,MATCH("M_WG4",_翻訳マスタ!$A$47:$A$98,0),MATCH(言語切替!$B$3,_翻訳マスタ!$B$1:$D$1,0)) -> WG-4 | E9: =INDEX(_翻訳マスタ!$B$47:$D$98,MATCH("M_WAIT_COMPLETE",_翻訳マスタ!$A$47:$A$98,0),MATCH(言語切替!$B$3,_翻訳マスタ!$B$1:$D$1,0)) -> Chờ xác nhận hoàn thành | M9: =INDEX(_翻訳マスタ!$B$47:$D$98,MATCH("M_ACHIEVED",_翻訳マスタ!$A$47:$A$98,0),MATCH(言語切替!$B$3,_翻訳マスタ!$B$1:$D$1,0)) -> Đạt
A10: =INDEX(_翻訳マスタ!$B$47:$D$98,MATCH("M_WG5",_翻訳マスタ!$A$47:$A$98,0),MATCH(言語切替!$B$3,_翻訳マスタ!$B$1:$D$1,0)) -> WG-5 | E10: =INDEX(_翻訳マスタ!$B$47:$D$98,MATCH("M_COMPLETE",_翻訳マスタ!$A$47:$A$98,0),MATCH(言語切替!$B$3,_翻訳マスタ!$B$1:$D$1,0)) -> Hoàn thành | M10: =INDEX(_翻訳マスタ!$B$47:$D$98,MATCH("M_NOT_ACHIEVED",_翻訳マスタ!$A$47:$A$98,0),MATCH(言語切替!$B$3,_翻訳マスタ!$B$1:$D$1,0)) -> Chưa đạt
A11: =INDEX(_翻訳マスタ!$B$47:$D$98,MATCH("M_WG6",_翻訳マスタ!$A$47:$A$98,0),MATCH(言語切替!$B$3,_翻訳マスタ!$B$1:$D$1,0)) -> WG-6 | E11: =INDEX(_翻訳マスタ!$B$47:$D$98,MATCH("M_HOLD",_翻訳マスタ!$A$47:$A$98,0),MATCH(言語切替!$B$3,_翻訳マスタ!$B$1:$D$1,0)) -> Tạm hoãn
A12: =INDEX(_翻訳マスタ!$B$47:$D$98,MATCH("M_WG7",_翻訳マスタ!$A$47:$A$98,0),MATCH(言語切替!$B$3,_翻訳マスタ!$B$1:$D$1,0)) -> WG-7 | E12: =INDEX(_翻訳マスタ!$B$47:$D$98,MATCH("M_WITHDRAWN",_翻訳マスタ!$A$47:$A$98,0),MATCH(言語切替!$B$3,_翻訳マスタ!$B$1:$D$1,0)) -> Rút lại
A13: =INDEX(_翻訳マスタ!$B$47:$D$98,MATCH("M_WG8",_翻訳マスタ!$A$47:$A$98,0),MATCH(言語切替!$B$3,_翻訳マスタ!$B$1:$D$1,0)) -> WG-8
A14: =INDEX(_翻訳マスタ!$B$47:$D$98,MATCH("M_WG9",_翻訳マスタ!$A$47:$A$98,0),MATCH(言語切替!$B$3,_翻訳マスタ!$B$1:$D$1,0)) -> WG-9
A18: =INDEX(_翻訳マスタ!$B$47:$D$98,MATCH("M_PRIORITY_GUIDE",_翻訳マスタ!$A$47:$A$98,0),MATCH(言語切替!$B$3,_翻訳マスタ!$B$1:$D$1,0)) -> Nguyên tắc ưu tiên
A19: =INDEX(_翻訳マスタ!$B$47:$D$98,MATCH("M_HIGH_DESC",_翻訳マスタ!$A$47:$A$98,0),MATCH(言語切替!$B$3,_翻訳マスタ!$B$1:$D$1,0)) -> High: Ảnh hưởng trực tiếp đến tiến độ, chi phí và chất lượng của toàn tiểu ban.
A20: =INDEX(_翻訳マスタ!$B$47:$D$98,MATCH("M_MIDDLE_DESC",_翻訳マスタ!$A$47:$A$98,0),MATCH(言語切替!$B$3,_翻訳マスタ!$B$1:$D$1,0)) -> Middle: Ảnh hưởng trực tiếp đến tiến độ, chi phí và chất lượng của từng WG.
A21: =INDEX(_翻訳マスタ!$B$47:$D$98,MATCH("M_LOW_DESC",_翻訳マスタ!$A$47:$A$98,0),MATCH(言語切替!$B$3,_翻訳マスタ!$B$1:$D$1,0)) -> Low: Ảnh hưởng trực tiếp nhỏ nhưng cần thiết để thành công.

Sheet 03_WBS
A1: =INDEX(_翻訳マスタ!$B$99:$D$116,MATCH("WBS_TITLE",_翻訳マスタ!$A$99:$A$116,0),MATCH(言語切替!$B$3,_翻訳マスタ!$B$1:$D$1,0)) -> WBS & Mốc tiến độ
A2: =INDEX(_翻訳マスタ!$B$99:$D$116,MATCH("WBS_DESC",_翻訳マスタ!$A$99:$A$116,0),MATCH(言語切替!$B$3,_翻訳マスタ!$B$1:$D$1,0)) -> Các ô chữ màu xanh là ô nhập liệu. Tỷ lệ tiến độ, số ngày còn lại và đánh giá chậm tiến độ được tính tự động. 3 dòng là ví dụ nhập liệu.
A3: =INDEX(_翻訳マスタ!$B$2:$D$300,MATCH("PARA_HOWTO",_翻訳マスタ!$A$2:$A$300,0),MATCH(言語切替!$B$3,_翻訳マスタ!$B$1:$D$1,0)) -> Quy tắc nhập: 【Tiêu đề VÀNG】= Được phép nhập / chọn dữ liệu (Gõ bất kỳ tiếng Việt/Nhật/Trung vào ô [Nhập]) 【Tiêu đề XANH DƯƠNG】= Cấm nhập (Tự động tính toán & dịch tự động 3 thứ tiếng).
A4: =INDEX(_翻訳マスタ!$B$99:$D$116,MATCH("WBS_ID",_翻訳マスタ!$A$99:$A$116,0),MATCH(言語切替!$B$3,_翻訳マスタ!$B$1:$D$1,0)) -> WBS ID | B4: =INDEX(_翻訳マスタ!$B$99:$D$116,MATCH("WBS_WG",_翻訳マスタ!$A$99:$A$116,0),MATCH(言語切替!$B$3,_翻訳マスタ!$B$1:$D$1,0)) -> WG | C4: =INDEX(_翻訳マスタ!$B$99:$D$116,MATCH("WBS_ID",_翻訳マスタ!$A$99:$A$116,0),MATCH(言語切替!$B$3,_翻訳マスタ!$B$1:$D$1,0)) -> WBS ID | E4: =INDEX(_翻訳マスタ!$B$99:$D$116,MATCH("WBS_SITE",_翻訳マスタ!$A$99:$A$116,0),MATCH(言語切替!$B$3,_翻訳マスタ!$B$1:$D$1,0)) -> Cứ điểm | F4: =INDEX(_翻訳マスタ!$B$2:$D$300,MATCH("WBS_CATEGORY",_翻訳マスタ!$A$2:$A$300,0),MATCH(言語切替!$B$3,_翻訳マスタ!$B$1:$D$1,0))&INDEX(_翻訳マスタ!$B$2:$D$300,MATCH("NEW_INPUT_SUFFIX",_翻訳マスタ!$A$2:$A$300,0),MATCH(言語切替!$B$3,_翻訳マスタ!$B$1:$D$1,0)) -> Giai đoạn hoạt động [Nhập: VI/JP/CN] | G4: =INDEX(_翻訳マスタ!$B$2:$D$300,MATCH("WBS_CATEGORY",_翻訳マスタ!$A$2:$A$300,0),MATCH(言語切替!$B$3,_翻訳マスタ!$B$1:$D$1,0))&INDEX(_翻訳マスタ!$B$2:$D$300,MATCH("NEW_VI_SUFFIX",_翻訳マスタ!$A$2:$A$300,0),MATCH(言語切替!$B$3,_翻訳マスタ!$B$1:$D$1,0)) -> Giai đoạn hoạt động (VI) | H4: =INDEX(_翻訳マスタ!$B$2:$D$300,MATCH("WBS_CATEGORY",_翻訳マスタ!$A$2:$A$300,0),MATCH(言語切替!$B$3,_翻訳マスタ!$B$1:$D$1,0))&INDEX(_翻訳マスタ!$B$2:$D$300,MATCH("NEW_JP_SUFFIX",_翻訳マスタ!$A$2:$A$300,0),MATCH(言語切替!$B$3,_翻訳マスタ!$B$1:$D$1,0)) -> Giai đoạn hoạt động (JP) | I4: =INDEX(_翻訳マスタ!$B$2:$D$300,MATCH("WBS_CATEGORY",_翻訳マスタ!$A$2:$A$300,0),MATCH(言語切替!$B$3,_翻訳マスタ!$B$1:$D$1,0))&INDEX(_翻訳マスタ!$B$2:$D$300,MATCH("NEW_CN_SUFFIX",_翻訳マスタ!$A$2:$A$300,0),MATCH(言語切替!$B$3,_翻訳マスタ!$B$1:$D$1,0)) -> Giai đoạn hoạt động (CN) | J4: =INDEX(_翻訳マスタ!$B$2:$D$300,MATCH("WBS_TASK",_翻訳マスタ!$A$2:$A$300,0),MATCH(言語切替!$B$3,_翻訳マスタ!$B$1:$D$1,0))&INDEX(_翻訳マスタ!$B$2:$D$300,MATCH("NEW_INPUT_SUFFIX",_翻訳マスタ!$A$2:$A$300,0),MATCH(言語切替!$B$3,_翻訳マスタ!$B$1:$D$1,0)) -> Nhiệm vụ / Mục tiêu [Nhập: VI/JP/CN] | K4: =INDEX(_翻訳マスタ!$B$2:$D$300,MATCH("WBS_TASK",_翻訳マスタ!$A$2:$A$300,0),MATCH(言語切替!$B$3,_翻訳マスタ!$B$1:$D$1,0))&INDEX(_翻訳マスタ!$B$2:$D$300,MATCH("NEW_VI_SUFFIX",_翻訳マスタ!$A$2:$A$300,0),MATCH(言語切替!$B$3,_翻訳マスタ!$B$1:$D$1,0)) -> Nhiệm vụ / Mục tiêu (VI) | L4: =INDEX(_翻訳マスタ!$B$2:$D$300,MATCH("WBS_TASK",_翻訳マスタ!$A$2:$A$300,0),MATCH(言語切替!$B$3,_翻訳マスタ!$B$1:$D$1,0))&INDEX(_翻訳マスタ!$B$2:$D$300,MATCH("NEW_JP_SUFFIX",_翻訳マスタ!$A$2:$A$300,0),MATCH(言語切替!$B$3,_翻訳マスタ!$B$1:$D$1,0)) -> Nhiệm vụ / Mục tiêu (JP) | M4: =INDEX(_翻訳マスタ!$B$2:$D$300,MATCH("WBS_TASK",_翻訳マスタ!$A$2:$A$300,0),MATCH(言語切替!$B$3,_翻訳マスタ!$B$1:$D$1,0))&INDEX(_翻訳マスタ!$B$2:$D$300,MATCH("NEW_CN_SUFFIX",_翻訳マスタ!$A$2:$A$300,0),MATCH(言語切替!$B$3,_翻訳マスタ!$B$1:$D$1,0)) -> Nhiệm vụ / Mục tiêu (CN) | N4: =INDEX(_翻訳マスタ!$B$99:$D$116,MATCH("WBS_OWNER",_翻訳マスタ!$A$99:$A$116,0),MATCH(言語切替!$B$3,_翻訳マスタ!$B$1:$D$1,0)) -> Người chịu trách nhiệm | O4: =INDEX(_翻訳マスタ!$B$99:$D$116,MATCH("WBS_PLAN_START",_翻訳マスタ!$A$99:$A$116,0),MATCH(言語切替!$B$3,_翻訳マスタ!$B$1:$D$1,0)) -> Ngày bắt đầu kế hoạch | P4: =INDEX(_翻訳マスタ!$B$99:$D$116,MATCH("WBS_PLAN_END",_翻訳マスタ!$A$99:$A$116,0),MATCH(言語切替!$B$3,_翻訳マスタ!$B$1:$D$1,0)) -> Ngày kết thúc kế hoạch | Q4: =INDEX(_翻訳マスタ!$B$99:$D$116,MATCH("WBS_ACTUAL_START",_翻訳マスタ!$A$99:$A$116,0),MATCH(言語切替!$B$3,_翻訳マスタ!$B$1:$D$1,0)) -> Ngày bắt đầu thực tế | R4: =INDEX(_翻訳マスタ!$B$99:$D$116,MATCH("WBS_ACTUAL_END",_翻訳マスタ!$A$99:$A$116,0),MATCH(言語切替!$B$3,_翻訳マスタ!$B$1:$D$1,0)) -> Ngày kết thúc thực tế | S4: =INDEX(_翻訳マスタ!$B$99:$D$116,MATCH("WBS_PROGRESS",_翻訳マスタ!$A$99:$A$116,0),MATCH(言語切替!$B$3,_翻訳マスタ!$B$1:$D$1,0)) -> Tỷ lệ tiến độ | T4: =INDEX(_翻訳マスタ!$B$99:$D$116,MATCH("WBS_STATUS",_翻訳マスタ!$A$99:$A$116,0),MATCH(言語切替!$B$3,_翻訳マスタ!$B$1:$D$1,0)) -> Trạng thái | U4: =INDEX(_翻訳マスタ!$B$99:$D$116,MATCH("WBS_DAYS",_翻訳マスタ!$A$99:$A$116,0),MATCH(言語切替!$B$3,_翻訳マスタ!$B$1:$D$1,0)) -> Số ngày còn lại | V4: =INDEX(_翻訳マスタ!$B$2:$D$300,MATCH("WBS_NOTE",_翻訳マスタ!$A$2:$A$300,0),MATCH(言語切替!$B$3,_翻訳マスタ!$B$1:$D$1,0))&INDEX(_翻訳マスタ!$B$2:$D$300,MATCH("NEW_INPUT_SUFFIX",_翻訳マスタ!$A$2:$A$300,0),MATCH(言語切替!$B$3,_翻訳マスタ!$B$1:$D$1,0)) -> Ghi chú [Nhập: VI/JP/CN] | W4: =INDEX(_翻訳マスタ!$B$2:$D$300,MATCH("WBS_NOTE",_翻訳マスタ!$A$2:$A$300,0),MATCH(言語切替!$B$3,_翻訳マスタ!$B$1:$D$1,0))&INDEX(_翻訳マスタ!$B$2:$D$300,MATCH("NEW_VI_SUFFIX",_翻訳マスタ!$A$2:$A$300,0),MATCH(言語切替!$B$3,_翻訳マスタ!$B$1:$D$1,0)) -> Ghi chú (VI) | X4: =INDEX(_翻訳マスタ!$B$2:$D$300,MATCH("WBS_NOTE",_翻訳マスタ!$A$2:$A$300,0),MATCH(言語切替!$B$3,_翻訳マスタ!$B$1:$D$1,0))&INDEX(_翻訳マスタ!$B$2:$D$300,MATCH("NEW_JP_SUFFIX",_翻訳マスタ!$A$2:$A$300,0),MATCH(言語切替!$B$3,_翻訳マスタ!$B$1:$D$1,0)) -> Ghi chú (JP) | Y4: =INDEX(_翻訳マスタ!$B$2:$D$300,MATCH("WBS_NOTE",_翻訳マスタ!$A$2:$A$300,0),MATCH(言語切替!$B$3,_翻訳マスタ!$B$1:$D$1,0))&INDEX(_翻訳マスタ!$B$2:$D$300,MATCH("NEW_CN_SUFFIX",_翻訳マスタ!$A$2:$A$300,0),MATCH(言語切替!$B$3,_翻訳マスタ!$B$1:$D$1,0)) -> Ghi chú (CN)
A5: 1 | B5: ='02_マスタ'!$A$5 -> Toàn bộ | C5: 1 | E5: KDC | F5: =INDEX(_翻訳マスタ!$B$117:$D$247,MATCH("WBS_CAT_STARTUP",_翻訳マスタ!$A$117:$A$247,0),MATCH(言語切替!$B$3,_翻訳マスタ!$B$1:$D$1,0)) -> Khởi động | G5: VN | H5: JP | I5: CN | J5: =INDEX(_翻訳マスタ!$D$2:$D$300,MATCH("WBS_TASK_1",_翻訳マスタ!$A$2:$A$300,0)) -> Xác định quy tắc vận hành WG | K5: =IF(J5="","",_xlfn.TRANSLATE(J5,"","vi")) -> Xác định quy tắc vận hành WG | L5: =IF(J5="","",_xlfn.TRANSLATE(J5,"","ja")) -> WGの運用規則の決定 | M5: =IF(J5="","",_xlfn.TRANSLATE(J5,"","zh-Hans")) -> 制定工作组的操作规则 | N5: Lập list chọn | O5: 46288 | P5: 46295 | Q5: 46293 | R5: 46293 | S5: =IF(OR(O5="",P5=""),"",IF(R5<>"",1,IF(Q5="",0,MAX(0,MIN(1,(TODAY()-O5)/(P5-O5+1)))))) -> 1 | T5: 完了 | U5: =IF(P5="","",P5-TODAY()) -> -9 | V5: =INDEX(_翻訳マスタ!$D$2:$D$300,MATCH("COMMON_EXAMPLE",_翻訳マスタ!$A$2:$A$300,0)) -> Ví dụ nhập liệu | W5: =IF(V5="","",_xlfn.TRANSLATE(V5,"","vi")) -> Ví dụ nhập liệu | X5: =IF(V5="","",_xlfn.TRANSLATE(V5,"","ja")) -> データ入力の例 | Y5: =IF(V5="","",_xlfn.TRANSLATE(V5,"","zh-Hans")) -> 数据录入示例
A6: WG1-001 | B6: WG-1 | C6: WG-1 | D6: 001 | E6: KDTVN | F6: =INDEX(_翻訳マスタ!$B$117:$D$247,MATCH("WBS_CAT_ANALYSIS",_翻訳マスタ!$A$117:$A$247,0),MATCH(言語切替!$B$3,_翻訳マスタ!$B$1:$D$1,0)) -> Phân tích hiện trạng | J6: =INDEX(_翻訳マスタ!$D$2:$D$300,MATCH("WBS_TASK_2",_翻訳マスタ!$A$2:$A$300,0)) -> Rà soát nghiệp vụ hiện tại | K6: =IF(J6="","",_xlfn.TRANSLATE(J6,"","vi")) -> Rà soát nghiệp vụ hiện tại | L6: =IF(J6="","",_xlfn.TRANSLATE(J6,"","ja")) -> 現在の作戦のレビュー | M6: =IF(J6="","",_xlfn.TRANSLATE(J6,"","zh-Hans")) -> 当前行动回顾 | O6: 46294 | P6: 46311 | S6: =IF(OR(O6="",P6=""),"",IF(R6<>"",1,IF(Q6="",0,MAX(0,MIN(1,(TODAY()-O6)/(P6-O6+1)))))) -> 0 | T6: ='02_マスタ'!$E$5 -> Chưa bắt đầu | U6: =IF(P6="","",P6-TODAY()) -> 7 | V6: =INDEX(_翻訳マスタ!$D$2:$D$300,MATCH("COMMON_EXAMPLE",_翻訳マスタ!$A$2:$A$300,0)) -> Ví dụ nhập liệu | W6: =IF(V6="","",_xlfn.TRANSLATE(V6,"","vi")) -> Ví dụ nhập liệu | X6: =IF(V6="","",_xlfn.TRANSLATE(V6,"","ja")) -> データ入力の例 | Y6: =IF(V6="","",_xlfn.TRANSLATE(V6,"","zh-Hans")) -> 数据录入示例
A7: 3 | B7: WG-8 | C7: WG-8-001 | E7: ='02_マスタ'!$C$5 -> Chung | F7: =INDEX(_翻訳マスタ!$B$117:$D$247,MATCH("WBS_CAT_POLICY",_翻訳マスタ!$A$117:$A$247,0),MATCH(言語切替!$B$3,_翻訳マスタ!$B$1:$D$1,0)) -> Xây dựng định hướng | J7: =INDEX(_翻訳マスタ!$D$2:$D$300,MATCH("WBS_TASK_3",_翻訳マスタ!$A$2:$A$300,0)) -> Sắp xếp vai trò hệ thống hiện hữu | K7: =IF(J7="","",_xlfn.TRANSLATE(J7,"","vi")) -> Sắp xếp vai trò hệ thống hiện hữu | L7: =IF(J7="","",_xlfn.TRANSLATE(J7,"","ja")) -> 既存のシステム役割の組織化 | M7: =IF(J7="","",_xlfn.TRANSLATE(J7,"","zh-Hans")) -> 组织现有系统角色 | O7: 46296 | P7: 46325 | S7: =IF(OR(O7="",P7=""),"",IF(R7<>"",1,IF(Q7="",0,MAX(0,MIN(1,(TODAY()-O7)/(P7-O7+1)))))) -> 0 | T7: ='02_マスタ'!$E$5 -> Chưa bắt đầu | U7: =IF(P7="","",P7-TODAY()) -> 21 | V7: =INDEX(_翻訳マスタ!$D$2:$D$300,MATCH("COMMON_EXAMPLE",_翻訳マスタ!$A$2:$A$300,0)) -> Ví dụ nhập liệu | W7: =IF(V7="","",_xlfn.TRANSLATE(V7,"","vi")) -> Ví dụ nhập liệu | X7: =IF(V7="","",_xlfn.TRANSLATE(V7,"","ja")) -> データ入力の例 | Y7: =IF(V7="","",_xlfn.TRANSLATE(V7,"","zh-Hans")) -> 数据录入示例
A8: 4 | B8: WG-5 | C8: WG-5 | D8: 001 | E8: Chung | F8: Tự động hóa cấp phát | G8: =IF(F8="","",_xlfn.TRANSLATE(F8,"","vi")) -> Tự động hóa cấp phát | H8: =IF(F8="","",_xlfn.TRANSLATE(F8,"","ja")) -> プロビジョニング自動化 | I8: =IF(F8="","",_xlfn.TRANSLATE(F8,"","zh-Hans")) -> 配置自动化 | J8: Xem xét phương pháp AMM lấy thùng HAN-CON | K8: =IF(J8="","",_xlfn.TRANSLATE(J8,"","vi")) -> Xem xét phương pháp AMM lấy thùng HAN-CON | L8: =IF(J8="","",_xlfn.TRANSLATE(J8,"","ja")) -> HAN-CONバレル取得AMM法を考えてみましょう | M8: =IF(J8="","",_xlfn.TRANSLATE(J8,"","zh-Hans")) -> 考虑汉康枪管采集反导法 | S8: =IF(OR(O8="",P8=""),"",IF(R8<>"",1,IF(Q8="",0,MAX(0,MIN(1,(TODAY()-O8)/(P8-O8+1)))))) | U8: =IF(P8="","",P8-TODAY()) | W8: =IF(V8="","",_xlfn.TRANSLATE(V8,"","vi")) | X8: =IF(V8="","",_xlfn.TRANSLATE(V8,"","ja")) | Y8: =IF(V8="","",_xlfn.TRANSLATE(V8,"","zh-Hans"))
A9: 5 | B9: WG-5 | C9: WG-5 | D9: 002 | E9: Chung | F9: Tự động hóa cấp phát | G9: =IF(F9="","",_xlfn.TRANSLATE(F9,"","vi")) -> Tự động hóa cấp phát | H9: =IF(F9="","",_xlfn.TRANSLATE(F9,"","ja")) -> プロビジョニング自動化 | I9: =IF(F9="","",_xlfn.TRANSLATE(F9,"","zh-Hans")) -> 配置自动化 | J9: Xe xét đường vận chuyển | K9: =IF(J9="","",_xlfn.TRANSLATE(J9,"","vi")) -> Xe xét đường vận chuyển | L9: =IF(J9="","",_xlfn.TRANSLATE(J9,"","ja")) -> 交通道路車両 | M9: =IF(J9="","",_xlfn.TRANSLATE(J9,"","zh-Hans")) -> 交通道路车辆 | S9: =IF(OR(O9="",P9=""),"",IF(R9<>"",1,IF(Q9="",0,MAX(0,MIN(1,(TODAY()-O9)/(P9-O9+1)))))) | U9: =IF(P9="","",P9-TODAY()) | W9: =IF(V9="","",_xlfn.TRANSLATE(V9,"","vi")) | X9: =IF(V9="","",_xlfn.TRANSLATE(V9,"","ja")) | Y9: =IF(V9="","",_xlfn.TRANSLATE(V9,"","zh-Hans"))
A10: 6 | B10: WG-5 | C10: WG-5 | D10: 003 | F10: Cơ chế cấp phát | G10: =IF(F10="","",_xlfn.TRANSLATE(F10,"","vi")) -> Cơ chế cấp phát | H10: =IF(F10="","",_xlfn.TRANSLATE(F10,"","ja")) -> 配分メカニズム | I10: =IF(F10="","",_xlfn.TRANSLATE(F10,"","zh-Hans")) -> 分配机制 | J10: Xem xét cơ chế cấp phát theo phương thức Pull | K10: =IF(J10="","",_xlfn.TRANSLATE(J10,"","vi")) -> Xem xét cơ chế cấp phát theo phương thức Pull | L10: =IF(J10="","",_xlfn.TRANSLATE(J10,"","ja")) -> プル割り当てメカニズムを考えてみましょう | M10: =IF(J10="","",_xlfn.TRANSLATE(J10,"","zh-Hans")) -> 考虑拉动分配机制 | S10: =IF(OR(O10="",P10=""),"",IF(R10<>"",1,IF(Q10="",0,MAX(0,MIN(1,(TODAY()-O10)/(P10-O10+1)))))) | U10: =IF(P10="","",P10-TODAY()) | W10: =IF(V10="","",_xlfn.TRANSLATE(V10,"","vi")) | X10: =IF(V10="","",_xlfn.TRANSLATE(V10,"","ja")) | Y10: =IF(V10="","",_xlfn.TRANSLATE(V10,"","zh-Hans"))
A11: 7 | C11: 7 | J11: Phương pháp liên kết tín hiệu | K11: =IF(J11="","",_xlfn.TRANSLATE(J11,"","vi")) -> Phương pháp liên kết tín hiệu | L11: =IF(J11="","",_xlfn.TRANSLATE(J11,"","ja")) -> 信号ボンディング法 | M11: =IF(J11="","",_xlfn.TRANSLATE(J11,"","zh-Hans")) -> 信号绑定方法 | S11: =IF(OR(O11="",P11=""),"",IF(R11<>"",1,IF(Q11="",0,MAX(0,MIN(1,(TODAY()-O11)/(P11-O11+1)))))) | U11: =IF(P11="","",P11-TODAY()) | W11: =IF(V11="","",_xlfn.TRANSLATE(V11,"","vi")) | X11: =IF(V11="","",_xlfn.TRANSLATE(V11,"","ja")) | Y11: =IF(V11="","",_xlfn.TRANSLATE(V11,"","zh-Hans"))
A12: 8 | B12: WG-5 | C12: 8 | E12: Chung | F12: Tự động hóa cấp phát | J12: Xem xét lại diện tích layout line | K12: =IF(J12="","",_xlfn.TRANSLATE(J12,"","vi")) -> Xem xét lại diện tích layout line | L12: =IF(J12="","",_xlfn.TRANSLATE(J12,"","ja")) -> レイアウトラインのエリアを見直してください | M12: =IF(J12="","",_xlfn.TRANSLATE(J12,"","zh-Hans")) -> 检查布局线区域 | S12: =IF(OR(O12="",P12=""),"",IF(R12<>"",1,IF(Q12="",0,MAX(0,MIN(1,(TODAY()-O12)/(P12-O12+1)))))) | U12: =IF(P12="","",P12-TODAY()) | W12: =IF(V12="","",_xlfn.TRANSLATE(V12,"","vi")) | X12: =IF(V12="","",_xlfn.TRANSLATE(V12,"","ja")) | Y12: =IF(V12="","",_xlfn.TRANSLATE(V12,"","zh-Hans"))
K13: =IF(J13="","",_xlfn.TRANSLATE(J13,"","vi")) | L13: =IF(J13="","",_xlfn.TRANSLATE(J13,"","ja")) | M13: =IF(J13="","",_xlfn.TRANSLATE(J13,"","zh-Hans")) | S13: =IF(OR(O13="",P13=""),"",IF(R13<>"",1,IF(Q13="",0,MAX(0,MIN(1,(TODAY()-O13)/(P13-O13+1)))))) | U13: =IF(P13="","",P13-TODAY()) | W13: =IF(V13="","",_xlfn.TRANSLATE(V13,"","vi")) | X13: =IF(V13="","",_xlfn.TRANSLATE(V13,"","ja")) | Y13: =IF(V13="","",_xlfn.TRANSLATE(V13,"","zh-Hans"))
K14: =IF(J14="","",_xlfn.TRANSLATE(J14,"","vi")) | L14: =IF(J14="","",_xlfn.TRANSLATE(J14,"","ja")) | M14: =IF(J14="","",_xlfn.TRANSLATE(J14,"","zh-Hans")) | S14: =IF(OR(O14="",P14=""),"",IF(R14<>"",1,IF(Q14="",0,MAX(0,MIN(1,(TODAY()-O14)/(P14-O14+1)))))) | U14: =IF(P14="","",P14-TODAY()) | W14: =IF(V14="","",_xlfn.TRANSLATE(V14,"","vi")) | X14: =IF(V14="","",_xlfn.TRANSLATE(V14,"","ja")) | Y14: =IF(V14="","",_xlfn.TRANSLATE(V14,"","zh-Hans"))
K15: =IF(J15="","",_xlfn.TRANSLATE(J15,"","vi")) | L15: =IF(J15="","",_xlfn.TRANSLATE(J15,"","ja")) | M15: =IF(J15="","",_xlfn.TRANSLATE(J15,"","zh-Hans")) | S15: =IF(OR(O15="",P15=""),"",IF(R15<>"",1,IF(Q15="",0,MAX(0,MIN(1,(TODAY()-O15)/(P15-O15+1)))))) | U15: =IF(P15="","",P15-TODAY()) | W15: =IF(V15="","",_xlfn.TRANSLATE(V15,"","vi")) | X15: =IF(V15="","",_xlfn.TRANSLATE(V15,"","ja")) | Y15: =IF(V15="","",_xlfn.TRANSLATE(V15,"","zh-Hans"))
K16: =IF(J16="","",_xlfn.TRANSLATE(J16,"","vi")) | L16: =IF(J16="","",_xlfn.TRANSLATE(J16,"","ja")) | M16: =IF(J16="","",_xlfn.TRANSLATE(J16,"","zh-Hans")) | S16: =IF(OR(O16="",P16=""),"",IF(R16<>"",1,IF(Q16="",0,MAX(0,MIN(1,(TODAY()-O16)/(P16-O16+1)))))) | U16: =IF(P16="","",P16-TODAY()) | W16: =IF(V16="","",_xlfn.TRANSLATE(V16,"","vi")) | X16: =IF(V16="","",_xlfn.TRANSLATE(V16,"","ja")) | Y16: =IF(V16="","",_xlfn.TRANSLATE(V16,"","zh-Hans"))
K17: =IF(J17="","",_xlfn.TRANSLATE(J17,"","vi")) | L17: =IF(J17="","",_xlfn.TRANSLATE(J17,"","ja")) | M17: =IF(J17="","",_xlfn.TRANSLATE(J17,"","zh-Hans")) | S17: =IF(OR(O17="",P17=""),"",IF(R17<>"",1,IF(Q17="",0,MAX(0,MIN(1,(TODAY()-O17)/(P17-O17+1)))))) | U17: =IF(P17="","",P17-TODAY()) | W17: =IF(V17="","",_xlfn.TRANSLATE(V17,"","vi")) | X17: =IF(V17="","",_xlfn.TRANSLATE(V17,"","ja")) | Y17: =IF(V17="","",_xlfn.TRANSLATE(V17,"","zh-Hans"))
K18: =IF(J18="","",_xlfn.TRANSLATE(J18,"","vi")) | L18: =IF(J18="","",_xlfn.TRANSLATE(J18,"","ja")) | M18: =IF(J18="","",_xlfn.TRANSLATE(J18,"","zh-Hans")) | S18: =IF(OR(O18="",P18=""),"",IF(R18<>"",1,IF(Q18="",0,MAX(0,MIN(1,(TODAY()-O18)/(P18-O18+1)))))) | U18: =IF(P18="","",P18-TODAY()) | W18: =IF(V18="","",_xlfn.TRANSLATE(V18,"","vi")) | X18: =IF(V18="","",_xlfn.TRANSLATE(V18,"","ja")) | Y18: =IF(V18="","",_xlfn.TRANSLATE(V18,"","zh-Hans"))
K19: =IF(J19="","",_xlfn.TRANSLATE(J19,"","vi")) | L19: =IF(J19="","",_xlfn.TRANSLATE(J19,"","ja")) | M19: =IF(J19="","",_xlfn.TRANSLATE(J19,"","zh-Hans")) | S19: =IF(OR(O19="",P19=""),"",IF(R19<>"",1,IF(Q19="",0,MAX(0,MIN(1,(TODAY()-O19)/(P19-O19+1)))))) | U19: =IF(P19="","",P19-TODAY()) | W19: =IF(V19="","",_xlfn.TRANSLATE(V19,"","vi")) | X19: =IF(V19="","",_xlfn.TRANSLATE(V19,"","ja")) | Y19: =IF(V19="","",_xlfn.TRANSLATE(V19,"","zh-Hans"))
K20: =IF(J20="","",_xlfn.TRANSLATE(J20,"","vi")) | L20: =IF(J20="","",_xlfn.TRANSLATE(J20,"","ja")) | M20: =IF(J20="","",_xlfn.TRANSLATE(J20,"","zh-Hans")) | S20: =IF(OR(O20="",P20=""),"",IF(R20<>"",1,IF(Q20="",0,MAX(0,MIN(1,(TODAY()-O20)/(P20-O20+1)))))) | U20: =IF(P20="","",P20-TODAY()) | W20: =IF(V20="","",_xlfn.TRANSLATE(V20,"","vi")) | X20: =IF(V20="","",_xlfn.TRANSLATE(V20,"","ja")) | Y20: =IF(V20="","",_xlfn.TRANSLATE(V20,"","zh-Hans"))
K21: =IF(J21="","",_xlfn.TRANSLATE(J21,"","vi")) | L21: =IF(J21="","",_xlfn.TRANSLATE(J21,"","ja")) | M21: =IF(J21="","",_xlfn.TRANSLATE(J21,"","zh-Hans")) | S21: =IF(OR(O21="",P21=""),"",IF(R21<>"",1,IF(Q21="",0,MAX(0,MIN(1,(TODAY()-O21)/(P21-O21+1)))))) | U21: =IF(P21="","",P21-TODAY()) | W21: =IF(V21="","",_xlfn.TRANSLATE(V21,"","vi")) | X21: =IF(V21="","",_xlfn.TRANSLATE(V21,"","ja")) | Y21: =IF(V21="","",_xlfn.TRANSLATE(V21,"","zh-Hans"))
K22: =IF(J22="","",_xlfn.TRANSLATE(J22,"","vi")) | L22: =IF(J22="","",_xlfn.TRANSLATE(J22,"","ja")) | M22: =IF(J22="","",_xlfn.TRANSLATE(J22,"","zh-Hans")) | S22: =IF(OR(O22="",P22=""),"",IF(R22<>"",1,IF(Q22="",0,MAX(0,MIN(1,(TODAY()-O22)/(P22-O22+1)))))) | U22: =IF(P22="","",P22-TODAY()) | W22: =IF(V22="","",_xlfn.TRANSLATE(V22,"","vi")) | X22: =IF(V22="","",_xlfn.TRANSLATE(V22,"","ja")) | Y22: =IF(V22="","",_xlfn.TRANSLATE(V22,"","zh-Hans"))
K23: =IF(J23="","",_xlfn.TRANSLATE(J23,"","vi")) | L23: =IF(J23="","",_xlfn.TRANSLATE(J23,"","ja")) | M23: =IF(J23="","",_xlfn.TRANSLATE(J23,"","zh-Hans")) | S23: =IF(OR(O23="",P23=""),"",IF(R23<>"",1,IF(Q23="",0,MAX(0,MIN(1,(TODAY()-O23)/(P23-O23+1)))))) | U23: =IF(P23="","",P23-TODAY()) | W23: =IF(V23="","",_xlfn.TRANSLATE(V23,"","vi")) | X23: =IF(V23="","",_xlfn.TRANSLATE(V23,"","ja")) | Y23: =IF(V23="","",_xlfn.TRANSLATE(V23,"","zh-Hans"))
K24: =IF(J24="","",_xlfn.TRANSLATE(J24,"","vi")) | L24: =IF(J24="","",_xlfn.TRANSLATE(J24,"","ja")) | M24: =IF(J24="","",_xlfn.TRANSLATE(J24,"","zh-Hans")) | S24: =IF(OR(O24="",P24=""),"",IF(R24<>"",1,IF(Q24="",0,MAX(0,MIN(1,(TODAY()-O24)/(P24-O24+1)))))) | U24: =IF(P24="","",P24-TODAY()) | W24: =IF(V24="","",_xlfn.TRANSLATE(V24,"","vi")) | X24: =IF(V24="","",_xlfn.TRANSLATE(V24,"","ja")) | Y24: =IF(V24="","",_xlfn.TRANSLATE(V24,"","zh-Hans"))
... K31: =IF(J31="","",_xlfn.TRANSLATE(J31,"","vi")) | L31: =IF(J31="","",_xlfn.TRANSLATE(J31,"","ja")) | M31: =IF(J31="","",_xlfn.TRANSLATE(J31,"","zh-Hans")) | S31: =IF(OR(O31="",P31=""),"",IF(R31<>"",1,IF(Q31="",0,MAX(0,MIN(1,(TODAY()-O31)/(P31-O31+1)))))) | U31: =IF(P31="","",P31-TODAY()) | W31: =IF(V31="","",_xlfn.TRANSLATE(V31,"","vi")) | X31: =IF(V31="","",_xlfn.TRANSLATE(V31,"","ja")) | Y31: =IF(V31="","",_xlfn.TRANSLATE(V31,"","zh-Hans"))
L32: =IF(J32="","",_xlfn.TRANSLATE(J32,"vi","ja")) | M32: =IF(J32="","",_xlfn.TRANSLATE(J32,"vi","zh-Hans")) | S32: =IF(OR(O32="",P32=""),"",IF(R32<>"",1,IF(Q32="",0,MAX(0,MIN(1,(TODAY()-O32)/(P32-O32+1)))))) | U32: =IF(P32="","",P32-TODAY()) | X32: =IF(V32="","",_xlfn.TRANSLATE(V32,"vi","ja")) | Y32: =IF(V32="","",_xlfn.TRANSLATE(V32,"vi","zh-Hans"))
L33: =IF(J33="","",_xlfn.TRANSLATE(J33,"vi","ja")) | M33: =IF(J33="","",_xlfn.TRANSLATE(J33,"vi","zh-Hans")) | S33: =IF(OR(O33="",P33=""),"",IF(R33<>"",1,IF(Q33="",0,MAX(0,MIN(1,(TODAY()-O33)/(P33-O33+1)))))) | U33: =IF(P33="","",P33-TODAY()) | X33: =IF(V33="","",_xlfn.TRANSLATE(V33,"vi","ja")) | Y33: =IF(V33="","",_xlfn.TRANSLATE(V33,"vi","zh-Hans"))
L34: =IF(J34="","",_xlfn.TRANSLATE(J34,"vi","ja")) | M34: =IF(J34="","",_xlfn.TRANSLATE(J34,"vi","zh-Hans")) | S34: =IF(OR(O34="",P34=""),"",IF(R34<>"",1,IF(Q34="",0,MAX(0,MIN(1,(TODAY()-O34)/(P34-O34+1)))))) | U34: =IF(P34="","",P34-TODAY()) | X34: =IF(V34="","",_xlfn.TRANSLATE(V34,"vi","ja")) | Y34: =IF(V34="","",_xlfn.TRANSLATE(V34,"vi","zh-Hans"))
L35: =IF(J35="","",_xlfn.TRANSLATE(J35,"vi","ja")) | M35: =IF(J35="","",_xlfn.TRANSLATE(J35,"vi","zh-Hans")) | S35: =IF(OR(O35="",P35=""),"",IF(R35<>"",1,IF(Q35="",0,MAX(0,MIN(1,(TODAY()-O35)/(P35-O35+1)))))) | U35: =IF(P35="","",P35-TODAY()) | X35: =IF(V35="","",_xlfn.TRANSLATE(V35,"vi","ja")) | Y35: =IF(V35="","",_xlfn.TRANSLATE(V35,"vi","zh-Hans"))
L36: =IF(J36="","",_xlfn.TRANSLATE(J36,"vi","ja")) | M36: =IF(J36="","",_xlfn.TRANSLATE(J36,"vi","zh-Hans")) | S36: =IF(OR(O36="",P36=""),"",IF(R36<>"",1,IF(Q36="",0,MAX(0,MIN(1,(TODAY()-O36)/(P36-O36+1)))))) | U36: =IF(P36="","",P36-TODAY()) | X36: =IF(V36="","",_xlfn.TRANSLATE(V36,"vi","ja")) | Y36: =IF(V36="","",_xlfn.TRANSLATE(V36,"vi","zh-Hans"))
L37: =IF(J37="","",_xlfn.TRANSLATE(J37,"vi","ja")) | M37: =IF(J37="","",_xlfn.TRANSLATE(J37,"vi","zh-Hans")) | S37: =IF(OR(O37="",P37=""),"",IF(R37<>"",1,IF(Q37="",0,MAX(0,MIN(1,(TODAY()-O37)/(P37-O37+1)))))) | U37: =IF(P37="","",P37-TODAY()) | X37: =IF(V37="","",_xlfn.TRANSLATE(V37,"vi","ja")) | Y37: =IF(V37="","",_xlfn.TRANSLATE(V37,"vi","zh-Hans"))
L38: =IF(J38="","",_xlfn.TRANSLATE(J38,"vi","ja")) | M38: =IF(J38="","",_xlfn.TRANSLATE(J38,"vi","zh-Hans")) | S38: =IF(OR(O38="",P38=""),"",IF(R38<>"",1,IF(Q38="",0,MAX(0,MIN(1,(TODAY()-O38)/(P38-O38+1)))))) | U38: =IF(P38="","",P38-TODAY()) | X38: =IF(V38="","",_xlfn.TRANSLATE(V38,"vi","ja")) | Y38: =IF(V38="","",_xlfn.TRANSLATE(V38,"vi","zh-Hans"))
L39: =IF(J39="","",_xlfn.TRANSLATE(J39,"vi","ja")) | M39: =IF(J39="","",_xlfn.TRANSLATE(J39,"vi","zh-Hans")) | S39: =IF(OR(O39="",P39=""),"",IF(R39<>"",1,IF(Q39="",0,MAX(0,MIN(1,(TODAY()-O39)/(P39-O39+1)))))) | U39: =IF(P39="","",P39-TODAY()) | X39: =IF(V39="","",_xlfn.TRANSLATE(V39,"vi","ja")) | Y39: =IF(V39="","",_xlfn.TRANSLATE(V39,"vi","zh-Hans"))
L40: =IF(J40="","",_xlfn.TRANSLATE(J40,"vi","ja")) | M40: =IF(J40="","",_xlfn.TRANSLATE(J40,"vi","zh-Hans")) | S40: =IF(OR(O40="",P40=""),"",IF(R40<>"",1,IF(Q40="",0,MAX(0,MIN(1,(TODAY()-O40)/(P40-O40+1)))))) | U40: =IF(P40="","",P40-TODAY()) | X40: =IF(V40="","",_xlfn.TRANSLATE(V40,"vi","ja")) | Y40: =IF(V40="","",_xlfn.TRANSLATE(V40,"vi","zh-Hans"))
L41: =IF(J41="","",_xlfn.TRANSLATE(J41,"vi","ja")) | M41: =IF(J41="","",_xlfn.TRANSLATE(J41,"vi","zh-Hans")) | S41: =IF(OR(O41="",P41=""),"",IF(R41<>"",1,IF(Q41="",0,MAX(0,MIN(1,(TODAY()-O41)/(P41-O41+1)))))) | U41: =IF(P41="","",P41-TODAY()) | X41: =IF(V41="","",_xlfn.TRANSLATE(V41,"vi","ja")) | Y41: =IF(V41="","",_xlfn.TRANSLATE(V41,"vi","zh-Hans"))
L42: =IF(J42="","",_xlfn.TRANSLATE(J42,"vi","ja")) | M42: =IF(J42="","",_xlfn.TRANSLATE(J42,"vi","zh-Hans")) | S42: =IF(OR(O42="",P42=""),"",IF(R42<>"",1,IF(Q42="",0,MAX(0,MIN(1,(TODAY()-O42)/(P42-O42+1)))))) | U42: =IF(P42="","",P42-TODAY()) | X42: =IF(V42="","",_xlfn.TRANSLATE(V42,"vi","ja")) | Y42: =IF(V42="","",_xlfn.TRANSLATE(V42,"vi","zh-Hans"))
L43: =IF(J43="","",_xlfn.TRANSLATE(J43,"vi","ja")) | M43: =IF(J43="","",_xlfn.TRANSLATE(J43,"vi","zh-Hans")) | S43: =IF(OR(O43="",P43=""),"",IF(R43<>"",1,IF(Q43="",0,MAX(0,MIN(1,(TODAY()-O43)/(P43-O43+1)))))) | U43: =IF(P43="","",P43-TODAY()) | X43: =IF(V43="","",_xlfn.TRANSLATE(V43,"vi","ja")) | Y43: =IF(V43="","",_xlfn.TRANSLATE(V43,"vi","zh-Hans"))
... L205: =IF(J205="","",_xlfn.TRANSLATE(J205,"vi","ja")) | M205: =IF(J205="","",_xlfn.TRANSLATE(J205,"vi","zh-Hans")) | S205: =IF(OR(O205="",P205=""),"",IF(R205<>"",1,IF(Q205="",0,MAX(0,MIN(1,(TODAY()-O205)/(P205-O205+1)))))) | U205: =IF(P205="","",P205-TODAY()) | X205: =IF(V205="","",_xlfn.TRANSLATE(V205,"vi","ja")) | Y205: =IF(V205="","",_xlfn.TRANSLATE(V205,"vi","zh-Hans"))

Sheet 04_課題ToDo
A1: =INDEX(_翻訳マスタ!$B$117:$D$247,MATCH("ISSUE_TITLE",_翻訳マスタ!$A$117:$A$247,0),MATCH(言語切替!$B$3,_翻訳マスタ!$B$1:$D$1,0)) -> Quản lý Vấn đề & ToDo
A2: =INDEX(_翻訳マスタ!$B$117:$D$247,MATCH("ISSUE_DESC",_翻訳マスタ!$A$117:$A$247,0),MATCH(言語切替!$B$3,_翻訳マスタ!$B$1:$D$1,0)) -> Quản lý tập trung vấn đề, ToDo, quyết định và rủi ro. Số ngày còn lại và cảnh báo được tính tự động. 4 dòng là ví dụ nhập liệu.
A3: =INDEX(_翻訳マスタ!$B$2:$D$300,MATCH("PARA_HOWTO",_翻訳マスタ!$A$2:$A$300,0),MATCH(言語切替!$B$3,_翻訳マスタ!$B$1:$D$1,0)) -> Quy tắc nhập: 【Tiêu đề VÀNG】= Được phép nhập / chọn dữ liệu (Gõ bất kỳ tiếng Việt/Nhật/Trung vào ô [Nhập]) 【Tiêu đề XANH DƯƠNG】= Cấm nhập (Tự động tính toán & dịch tự động 3 thứ tiếng).
A4: =INDEX(_翻訳マスタ!$B$117:$D$247,MATCH("ISSUE_COL_ID",_翻訳マスタ!$A$117:$A$247,0),MATCH(言語切替!$B$3,_翻訳マスタ!$B$1:$D$1,0)) -> ID | B4: =INDEX(_翻訳マスタ!$B$117:$D$247,MATCH("ISSUE_COL_TYPE",_翻訳マスタ!$A$117:$A$247,0),MATCH(言語切替!$B$3,_翻訳マスタ!$B$1:$D$1,0)) -> Phân loại | C4: =INDEX(_翻訳マスタ!$B$117:$D$247,MATCH("ISSUE_COL_WG",_翻訳マスタ!$A$117:$A$247,0),MATCH(言語切替!$B$3,_翻訳マスタ!$B$1:$D$1,0)) -> WG | D4: =INDEX(_翻訳マスタ!$B$117:$D$247,MATCH("ISSUE_COL_SITE",_翻訳マスタ!$A$117:$A$247,0),MATCH(言語切替!$B$3,_翻訳マスタ!$B$1:$D$1,0)) -> Đơn vị | E4: =INDEX(_翻訳マスタ!$B$2:$D$300,MATCH("WBS_TASK",_翻訳マスタ!$A$2:$A$300,0),MATCH(言語切替!$B$3,_翻訳マスタ!$B$1:$D$1,0))&INDEX(_翻訳マスタ!$B$2:$D$300,MATCH("NEW_INPUT_SUFFIX",_翻訳マスタ!$A$2:$A$300,0),MATCH(言語切替!$B$3,_翻訳マスタ!$B$1:$D$1,0)) -> Nhiệm vụ / Mục tiêu [Nhập: VI/JP/CN] | F4: =INDEX(_翻訳マスタ!$B$2:$D$300,MATCH("ISSUE_COL_TITLE",_翻訳マスタ!$A$2:$A$300,0),MATCH(言語切替!$B$3,_翻訳マスタ!$B$1:$D$1,0))&INDEX(_翻訳マスタ!$B$2:$D$300,MATCH("NEW_INPUT_SUFFIX",_翻訳マスタ!$A$2:$A$300,0),MATCH(言語切替!$B$3,_翻訳マスタ!$B$1:$D$1,0)) -> Tiêu đề [Nhập: VI/JP/CN] | G4: =INDEX(_翻訳マスタ!$B$2:$D$300,MATCH("ISSUE_COL_TITLE",_翻訳マスタ!$A$2:$A$300,0),MATCH(言語切替!$B$3,_翻訳マスタ!$B$1:$D$1,0))&INDEX(_翻訳マスタ!$B$2:$D$300,MATCH("NEW_VI_SUFFIX",_翻訳マスタ!$A$2:$A$300,0),MATCH(言語切替!$B$3,_翻訳マスタ!$B$1:$D$1,0)) -> Tiêu đề (VI) | H4: =INDEX(_翻訳マスタ!$B$2:$D$300,MATCH("ISSUE_COL_TITLE",_翻訳マスタ!$A$2:$A$300,0),MATCH(言語切替!$B$3,_翻訳マスタ!$B$1:$D$1,0))&INDEX(_翻訳マスタ!$B$2:$D$300,MATCH("NEW_JP_SUFFIX",_翻訳マスタ!$A$2:$A$300,0),MATCH(言語切替!$B$3,_翻訳マスタ!$B$1:$D$1,0)) -> Tiêu đề (JP) | I4: =INDEX(_翻訳マスタ!$B$2:$D$300,MATCH("ISSUE_COL_TITLE",_翻訳マスタ!$A$2:$A$300,0),MATCH(言語切替!$B$3,_翻訳マスタ!$B$1:$D$1,0))&INDEX(_翻訳マスタ!$B$2:$D$300,MATCH("NEW_CN_SUFFIX",_翻訳マスタ!$A$2:$A$300,0),MATCH(言語切替!$B$3,_翻訳マスタ!$B$1:$D$1,0)) -> Tiêu đề (CN) | J4: =INDEX(_翻訳マスタ!$B$2:$D$300,MATCH("ISSUE_COL_BG",_翻訳マスタ!$A$2:$A$300,0),MATCH(言語切替!$B$3,_翻訳マスタ!$B$1:$D$1,0))&INDEX(_翻訳マスタ!$B$2:$D$300,MATCH("NEW_INPUT_SUFFIX",_翻訳マスタ!$A$2:$A$300,0),MATCH(言語切替!$B$3,_翻訳マスタ!$B$1:$D$1,0)) -> Bối cảnh / Vấn đề [Nhập: VI/JP/CN] | K4: =INDEX(_翻訳マスタ!$B$2:$D$300,MATCH("ISSUE_COL_BG",_翻訳マスタ!$A$2:$A$300,0),MATCH(言語切替!$B$3,_翻訳マスタ!$B$1:$D$1,0))&INDEX(_翻訳マスタ!$B$2:$D$300,MATCH("NEW_VI_SUFFIX",_翻訳マスタ!$A$2:$A$300,0),MATCH(言語切替!$B$3,_翻訳マスタ!$B$1:$D$1,0)) -> Bối cảnh / Vấn đề (VI) | L4: =INDEX(_翻訳マスタ!$B$2:$D$300,MATCH("ISSUE_COL_BG",_翻訳マスタ!$A$2:$A$300,0),MATCH(言語切替!$B$3,_翻訳マスタ!$B$1:$D$1,0))&INDEX(_翻訳マスタ!$B$2:$D$300,MATCH("NEW_JP_SUFFIX",_翻訳マスタ!$A$2:$A$300,0),MATCH(言語切替!$B$3,_翻訳マスタ!$B$1:$D$1,0)) -> Bối cảnh / Vấn đề (JP) | M4: =INDEX(_翻訳マスタ!$B$2:$D$300,MATCH("ISSUE_COL_BG",_翻訳マスタ!$A$2:$A$300,0),MATCH(言語切替!$B$3,_翻訳マスタ!$B$1:$D$1,0))&INDEX(_翻訳マスタ!$B$2:$D$300,MATCH("NEW_CN_SUFFIX",_翻訳マスタ!$A$2:$A$300,0),MATCH(言語切替!$B$3,_翻訳マスタ!$B$1:$D$1,0)) -> Bối cảnh / Vấn đề (CN) | N4: =INDEX(_翻訳マスタ!$B$2:$D$300,MATCH("ISSUE_COL_ACTION",_翻訳マスタ!$A$2:$A$300,0),MATCH(言語切替!$B$3,_翻訳マスタ!$B$1:$D$1,0))&INDEX(_翻訳マスタ!$B$2:$D$300,MATCH("NEW_INPUT_SUFFIX",_翻訳マスタ!$A$2:$A$300,0),MATCH(言語切替!$B$3,_翻訳マスタ!$B$1:$D$1,0)) -> Hành động tiếp theo [Nhập: VI/JP/CN] | O4: =INDEX(_翻訳マスタ!$B$2:$D$300,MATCH("ISSUE_COL_ACTION",_翻訳マスタ!$A$2:$A$300,0),MATCH(言語切替!$B$3,_翻訳マスタ!$B$1:$D$1,0))&INDEX(_翻訳マスタ!$B$2:$D$300,MATCH("NEW_VI_SUFFIX",_翻訳マスタ!$A$2:$A$300,0),MATCH(言語切替!$B$3,_翻訳マスタ!$B$1:$D$1,0)) -> Hành động tiếp theo (VI) | P4: =INDEX(_翻訳マスタ!$B$2:$D$300,MATCH("ISSUE_COL_ACTION",_翻訳マスタ!$A$2:$A$300,0),MATCH(言語切替!$B$3,_翻訳マスタ!$B$1:$D$1,0))&INDEX(_翻訳マスタ!$B$2:$D$300,MATCH("NEW_JP_SUFFIX",_翻訳マスタ!$A$2:$A$300,0),MATCH(言語切替!$B$3,_翻訳マスタ!$B$1:$D$1,0)) -> Hành động tiếp theo (JP) | Q4: =INDEX(_翻訳マスタ!$B$2:$D$300,MATCH("ISSUE_COL_ACTION",_翻訳マスタ!$A$2:$A$300,0),MATCH(言語切替!$B$3,_翻訳マスタ!$B$1:$D$1,0))&INDEX(_翻訳マスタ!$B$2:$D$300,MATCH("NEW_CN_SUFFIX",_翻訳マスタ!$A$2:$A$300,0),MATCH(言語切替!$B$3,_翻訳マスタ!$B$1:$D$1,0)) -> Hành động tiếp theo (CN) | R4: =INDEX(_翻訳マスタ!$B$117:$D$247,MATCH("ISSUE_COL_OWNER",_翻訳マスタ!$A$117:$A$247,0),MATCH(言語切替!$B$3,_翻訳マスタ!$B$1:$D$1,0)) -> Người phụ trách | S4: =INDEX(_翻訳マスタ!$B$117:$D$247,MATCH("ISSUE_COL_COOP",_翻訳マスタ!$A$117:$A$247,0),MATCH(言語切替!$B$3,_翻訳マスタ!$B$1:$D$1,0)) -> Người phối hợp | T4: =INDEX(_翻訳マスタ!$B$117:$D$247,MATCH("ISSUE_COL_START",_翻訳マスタ!$A$117:$A$247,0),MATCH(言語切替!$B$3,_翻訳マスタ!$B$1:$D$1,0)) -> Ngày tạo | U4: =INDEX(_翻訳マスタ!$B$117:$D$247,MATCH("ISSUE_COL_DUE",_翻訳マスタ!$A$117:$A$247,0),MATCH(言語切替!$B$3,_翻訳マスタ!$B$1:$D$1,0)) -> Thời hạn | V4: =INDEX(_翻訳マスタ!$B$117:$D$247,MATCH("ISSUE_COL_PRIORITY",_翻訳マスタ!$A$117:$A$247,0),MATCH(言語切替!$B$3,_翻訳マスタ!$B$1:$D$1,0)) -> Mức ưu tiên | W4: =INDEX(_翻訳マスタ!$B$117:$D$247,MATCH("ISSUE_COL_STATUS",_翻訳マスタ!$A$117:$A$247,0),MATCH(言語切替!$B$3,_翻訳マスタ!$B$1:$D$1,0)) -> Trạng thái | X4: =INDEX(_翻訳マスタ!$B$117:$D$247,MATCH("ISSUE_COL_DEP",_翻訳マスタ!$A$117:$A$247,0),MATCH(言語切替!$B$3,_翻訳マスタ!$B$1:$D$1,0)) -> WG liên quan / Phụ thuộc | Y4: =INDEX(_翻訳マスタ!$B$2:$D$300,MATCH("ISSUE_COL_COND",_翻訳マスタ!$A$2:$A$300,0),MATCH(言語切替!$B$3,_翻訳マスタ!$B$1:$D$1,0))&INDEX(_翻訳マスタ!$B$2:$D$300,MATCH("NEW_INPUT_SUFFIX",_翻訳マスタ!$A$2:$A$300,0),MATCH(言語切替!$B$3,_翻訳マスタ!$B$1:$D$1,0)) -> Điều kiện hoàn thành [Nhập: VI/JP/CN] | Z4: =INDEX(_翻訳マスタ!$B$2:$D$300,MATCH("ISSUE_COL_COND",_翻訳マスタ!$A$2:$A$300,0),MATCH(言語切替!$B$3,_翻訳マスタ!$B$1:$D$1,0))&INDEX(_翻訳マスタ!$B$2:$D$300,MATCH("NEW_VI_SUFFIX",_翻訳マスタ!$A$2:$A$300,0),MATCH(言語切替!$B$3,_翻訳マスタ!$B$1:$D$1,0)) -> Điều kiện hoàn thành (VI) | AA4: =INDEX(_翻訳マスタ!$B$2:$D$300,MATCH("ISSUE_COL_COND",_翻訳マスタ!$A$2:$A$300,0),MATCH(言語切替!$B$3,_翻訳マスタ!$B$1:$D$1,0))&INDEX(_翻訳マスタ!$B$2:$D$300,MATCH("NEW_JP_SUFFIX",_翻訳マスタ!$A$2:$A$300,0),MATCH(言語切替!$B$3,_翻訳マスタ!$B$1:$D$1,0)) -> Điều kiện hoàn thành (JP) | AB4: =INDEX(_翻訳マスタ!$B$2:$D$300,MATCH("ISSUE_COL_COND",_翻訳マスタ!$A$2:$A$300,0),MATCH(言語切替!$B$3,_翻訳マスタ!$B$1:$D$1,0))&INDEX(_翻訳マスタ!$B$2:$D$300,MATCH("NEW_CN_SUFFIX",_翻訳マスタ!$A$2:$A$300,0),MATCH(言語切替!$B$3,_翻訳マスタ!$B$1:$D$1,0)) -> Điều kiện hoàn thành (CN) | AC4: =INDEX(_翻訳マスタ!$B$2:$D$300,MATCH("ISSUE_COL_RESULT",_翻訳マスタ!$A$2:$A$300,0),MATCH(言語切替!$B$3,_翻訳マスタ!$B$1:$D$1,0))&INDEX(_翻訳マスタ!$B$2:$D$300,MATCH("NEW_INPUT_SUFFIX",_翻訳マスタ!$A$2:$A$300,0),MATCH(言語切替!$B$3,_翻訳マスタ!$B$1:$D$1,0)) -> Tình trạng xử lý / Kết luận [Nhập: VI/JP/CN] | AD4: =INDEX(_翻訳マスタ!$B$2:$D$300,MATCH("ISSUE_COL_RESULT",_翻訳マスタ!$A$2:$A$300,0),MATCH(言語切替!$B$3,_翻訳マスタ!$B$1:$D$1,0))&INDEX(_翻訳マスタ!$B$2:$D$300,MATCH("NEW_VI_SUFFIX",_翻訳マスタ!$A$2:$A$300,0),MATCH(言語切替!$B$3,_翻訳マスタ!$B$1:$D$1,0)) -> Tình trạng xử lý / Kết luận (VI) | AE4: =INDEX(_翻訳マスタ!$B$2:$D$300,MATCH("ISSUE_COL_RESULT",_翻訳マスタ!$A$2:$A$300,0),MATCH(言語切替!$B$3,_翻訳マスタ!$B$1:$D$1,0))&INDEX(_翻訳マスタ!$B$2:$D$300,MATCH("NEW_JP_SUFFIX",_翻訳マスタ!$A$2:$A$300,0),MATCH(言語切替!$B$3,_翻訳マスタ!$B$1:$D$1,0)) -> Tình trạng xử lý / Kết luận (JP) | AF4: =INDEX(_翻訳マスタ!$B$2:$D$300,MATCH("ISSUE_COL_RESULT",_翻訳マスタ!$A$2:$A$300,0),MATCH(言語切替!$B$3,_翻訳マスタ!$B$1:$D$1,0))&INDEX(_翻訳マスタ!$B$2:$D$300,MATCH("NEW_CN_SUFFIX",_翻訳マスタ!$A$2:$A$300,0),MATCH(言語切替!$B$3,_翻訳マスタ!$B$1:$D$1,0)) -> Tình trạng xử lý / Kết luận (CN) | AG4: =INDEX(_翻訳マスタ!$B$117:$D$247,MATCH("ISSUE_COL_LINK",_翻訳マスタ!$A$117:$A$247,0),MATCH(言語切替!$B$3,_翻訳マスタ!$B$1:$D$1,0)) -> Liên kết liên quan | AH4: =INDEX(_翻訳マスタ!$B$117:$D$247,MATCH("ISSUE_COL_DAYS",_翻訳マスタ!$A$117:$A$247,0),MATCH(言語切替!$B$3,_翻訳マスタ!$B$1:$D$1,0)) -> Số ngày còn lại | AI4: =INDEX(_翻訳マスタ!$B$117:$D$247,MATCH("ISSUE_COL_ALERT",_翻訳マスタ!$A$117:$A$247,0),MATCH(言語切替!$B$3,_翻訳マスタ!$B$1:$D$1,0)) -> Cảnh báo | AJ4: =INDEX(_翻訳マスタ!$B$117:$D$247,MATCH("ISSUE_COL_UPDATED",_翻訳マスタ!$A$117:$A$247,0),MATCH(言語切替!$B$3,_翻訳マスタ!$B$1:$D$1,0)) -> Ngày cập nhật cuối
